Workbook
Name LMH_KEY: 'Backend Data'!$A$7:$A$9
Name LMH_PTS: 'Backend Data'!$C$7:$C$9
Name LMH_STEP: 'Backend Data'!$D$7:$D$9
Name B_LVL: 'Backend Data'!$A$14:$A$30
Name B_VAL: 'Backend Data'!$B$14:$B$30
Name B_RANK: 'Backend Data'!$D$14:$D$30
Name LAD_STD: 'Backend Data'!$E$14:$E$25
Name LAD_PC: 'Backend Data'!$F$14:$F$27
Name LIST_LEVELS: 'Backend Data'!$A$14:$A$30
Name RBD_KEY: 'Backend Data'!$A$34:$A$432
Name RBD_C: 'Backend Data'!$E$34:$E$432
Name RBD_Au: 'Backend Data'!$F$34:$F$432
Name RBD_Ac: 'Backend Data'!$G$34:$G$432
Name RBD_L: 'Backend Data'!$H$34:$H$432
Name RBD_BI: 'Backend Data'!$I$34:$I$432
Name RBD_Exp: 'Backend Data'!$J$34:$J$432
Name RBD_Edu: 'Backend Data'!$K$34:$K$432
Name LIST_LMH: 'Backend Data'!$A$435:$A$437
Name DL_KEY: '5. Department Ladder'!$Y$7:$Y$297
Name DL_C: '5. Department Ladder'!$J$7:$J$297
Name DL_Au: '5. Department Ladder'!$K$7:$K$297
Name DL_Ac: '5. Department Ladder'!$L$7:$L$297
Name DL_L: '5. Department Ladder'!$M$7:$M$297
Name DL_BI: '5. Department Ladder'!$N$7:$N$297
Name DL_Exp: '5. Department Ladder'!$O$7:$O$297
Name DL_Edu: '5. Department Ladder'!$P$7:$P$297

Sheet 1. How to use
A1: Business-Head Workbook — how to use it
A2: Read this first · five minutes.
A3: IRIS · Job Architecture & Job Design · Final v1.15 · October 2026 · Internal — Confidential · HR only
A5: What this is | B5: Every person at IRIS, top down from the CEO, with the band HR proposes and the evidence behind it. You review it, weigh what matters for each role, assess each person, and the final proposed band updates itself.
A6: 1 · Read the row | B6: Core details, then what the employee and their manager told us. 'All their data ▸' opens everything we hold on the person in 3. Raw Data; '◂ Back' returns.
A7: 2 · Weightage · L / M / H | B7: How much each of the seven parameters counts for the role: Complexity & Expertise, Autonomy & Decision, Accountability & Impact, Leadership & Strategy, Business Impact, Experience, Education. It comes from 5. Department Ladder, which starts from the family's RB sheet. Change it there for a whole role, or type L, M or H on a person's row for that person only.
A8: 3 · Your assessment · L / M / H | B8: Against what the RB sheet describes for the HR proposed band: Medium = meets it, Low = works at the level below on that parameter, High = already works at the level above. Everything starts at Medium, so the final band equals HR's until you change something. 'What the data shows' gives our reading of the evidence to start from.
A9: 4 · The band moves live | B9: Weighted net = Σ weightage × assessment ÷ Σ weightage, from −1 to +1. At +0.5 or more the person moves one level up; at −0.5 or less one level down. Use the override for any other band, and say why in your comment.
A10: 5 · The manager check | B10: Shown live on every row: under a head at C1 or above a reportee sits in a lower band; below C1 a reportee sits at least one level below the manager; CEO with CXOs is the agreed exception. A ⚠ means your change breaks it — adjust the person or their manager.
A11: Market benchmark | B11: Each row shows the market weight of each parameter for the role group, the market experience range, the education and span norms and the market codes — sheet 4 has every source.
A12: HR proposed band | B12: From the model · six ratings × market-derived weights and rules R1–R13 · then the top-down manager rule HR agreed on 12 October 2026: 68 people move down, pay and title protected for one cycle, 8 move up. Band E sits in its own job family, Enterprise Leadership · E2 Chief Executive · E1 Chief Officers · CXO; department and function heads at C1–D2 sit in Executive Leadership · Business Head.
A13: Input from benchmarking | B13: The same six ratings on the plain market-average weights, without IRIS's adjustments, rounded to a level, with the person's experience against the market range for it.
A14: Colours | B14: Yellow = yours to edit · red = something missing · band colours on levels.
A15: Privacy | B15: HR and business heads only. Survey content is shown against names by HR's decision. Pay is not in this file.
A17: Sheets
A18: 1. How to use
A19: 2. Talent Mapping
A20: 3. Raw Data
A21: 4. Market Benchmark
A22: 5. Department Ladder
A23: RB · Administration, Legal & Se
A24: RB · Business Analysis
A25: RB · Consulting & Professional
A26: RB · Customer Success & Support
A27: RB · Data & Analytics
A28: RB · Data Operations & Digitiza
... A44: Backend Data

Sheet 2. Talent Mapping
A1: Talent Mapping — business heads: review, weigh and propose the band | Q1: ◂ Start
A2: Sheet 2 · One row per person, top down from the CEO. Read left to right: who → what they and their manager told us, with a link to all their data → how much each parameter counts · L/M/H → your assessment against the band · L/M/H → the market benchmark → HR's proposed band → what benchmarking says → the final proposed band, which updates the moment you change any L, M or H. Yellow = yours to edit.
A3: IRIS · Job Architecture & Job Design · Final v1.15 · October 2026 · Internal — Confidential · HR only
A4: Section colours: each column group has its own header colour and a matching light tint | E4: Changed vs current | G4: Level up | H4: Level down · pay & title protected | J4: Newly mapped | K4: Player-Coach · B+ · C+ | M4: RED = critical input needed · says what and who | P4: YELLOW = to complete or edit | R4: GREY = pay · set later
A5: CORE EMPLOYEE DETAILS | S5: SUMMARY OF RESPONSES RECEIVED — full detail in 3. Raw Data | Y5: WEIGHTAGE · L / M / H — from 5. Department Ladder; overwrite for this person | AF5: YOUR ASSESSMENT · L / M / H against the band — Medium = meets it | AM5: MARKET BENCHMARK — this role group at the HR proposed level | AY5: PROPOSAL | BM5: ENGINE — points and steps, live
A6: Business | B6: Department | C6: Layer from the CEO | D6: Emp ID | E6: Employee name | F6: Current designation | G6: Proposed designation | H6: Job family | I6: Sub-family | J6: Track | K6: Role ID | L6: Reporting manager | M6: Manager Emp ID | N6: Total exp. · yrs | O6: Exp. at IRIS · yrs | P6: Qualification | Q6: Current level · as is | R6: Model level · v1.13 | S6: Survey · questions answered | T6: What they shared · summary | U6: KRAs received · summary | V6: Manager talent mapping · rating · potential · 9-box · readiness | W6: What the data shows · vs HR proposed band | X6: All their data ▸ | Y6: Complexity & Expertise · weightage | Z6: Autonomy & Decision · weightage | AA6: Accountability & Impact · weightage | AB6: Leadership & Strategy · weightage | AC6: Business Impact · weightage | AD6: Experience · weightage | AE6: Education · weightage | AF6: Complexity & Expertise · assessment | AG6: Autonomy & Decision · assessment | AH6: Accountability & Impact · assessment | AI6: Leadership & Strategy · assessment | AJ6: Business Impact · assessment | AK6: Experience · assessment | AL6: Education · assessment | AM6: Market weight · Complexity & Expertise % | AN6: Market weight · Autonomy & Decision % | AO6: Market weight · Accountability & Impact % | AP6: Market weight · Leadership & Strategy % | AQ6: Market weight · Business Impact % | AR6: Market weight · Experience % | AS6: Market weight · Education % | AT6: Market experience · yrs | AU6: Education norm | AV6: Span norm | AW6: Radford / Mercer · SFIA 9 | AX6: References | AY6: HR proposed band · market benchmark and people inputs | AZ6: HR proposed · band and title | BA6: How HR set it | BB6: Input from benchmarking | BC6: Benchmarking · how | BD6: Weighted net · −1 to +1, live | BE6: Final proposed band · business inputs, live | BF6: Business head override · optional | BG6: FINAL PROPOSED BAND | BH6: Band | BI6: Move vs HR proposed | BJ6: Manager's final proposed band | BK6: Manager rule check · live | BL6: Business head comment | BM6: C points | BN6: Au points | BO6: Ac points | BP6: L points | BQ6: BI points | BR6: Exp points | BS6: Edu points | BT6: C step | BU6: Au step | BV6: Ac step | BW6: L step | BX6: BI step | BY6: Exp step | BZ6: Edu step | CA6: Ladder key
A7: Corporate | B7: Management | C7: 0 | D7: IRIS0001 | E7: Balachandran K | F7: CEO | G7: Chief Executive Officer | H7: Enterprise Leadership | I7: Chief Executive | J7: People Manager | K7: RC-EN-CE-E2 | L7: — · top of the organisation | M7: Not in this file | N7: 32.1 | O7: 22.1 | P7: MBA | Q7: Not in current mapping files | R7: E2 | S7: 0 of 20 | T7: Complexity: Evidence: no survey answers or KRAs on file → rating stays at the start Autonomy: Evidence: no survey answers or KRAs on file → rating stays at the start Accountability: Evidence: no survey answers or KRAs on file → rating stays at the start Leadership: Evidence: no survey answers or KRAs on file → rating stays at the start Business Impact: No … | U7: KRAs not received · manager to supply | V7: Latest rating: Not rated · manager · 9-box: Not placed · manager · Readiness: No rating data | W7: C M · Au M · Ac M · L M · BI M · Exp M · 32.1 yrs vs 20+ yrs · Edu M · MBA | X7: Open ▸ | Y7: =IFERROR(INDEX(DL_C,MATCH($CA7,DL_KEY,0)),"M") -> H | Z7: =IFERROR(INDEX(DL_Au,MATCH($CA7,DL_KEY,0)),"M") -> M | AA7: =IFERROR(INDEX(DL_Ac,MATCH($CA7,DL_KEY,0)),"M") -> M | AB7: =IFERROR(INDEX(DL_L,MATCH($CA7,DL_KEY,0)),"M") -> M | AC7: =IFERROR(INDEX(DL_BI,MATCH($CA7,DL_KEY,0)),"M") -> L | AD7: =IFERROR(INDEX(DL_Exp,MATCH($CA7,DL_KEY,0)),"M") -> L | AE7: =IFERROR(INDEX(DL_Edu,MATCH($CA7,DL_KEY,0)),"M") -> L | AF7: M | AG7: M | AH7: M | AI7: M | AJ7: M | AK7: M | AL7: M | AM7: 0.363 | AN7: 0.19 | AO7: 0.113 | AP7: 0.2 | AQ7: 0.087 | AR7: 0.04 | AS7: 0.01 | AT7: 20+ yrs | AU7: Postgraduate / professional qualification; proven business leadership | AV7: Executive team | AW7: E6 · SFIA 7 | AX7: S46–S51 Korn Ferry Hay evaluations · S04, S52 Mercer IPE · S53–S57 NHS, UK NJC/PSC, GLPC, SJC, US OPM point-factor plans · S58 McKinsey skills-based hiring · S60 WEF skills-first · S61 EY India 2026 · the Experience / Education split is an IRIS rule · S32 Google, Microsoft, Amazon · S33 Infosys · S35 Accenture India · IRIS experience guide · S01 Aon Radford · S02 Pave · S08 SFIA 9 · S03 Mercer career levels | AY7: E2 | AZ7: Band E · Enterprise leadership · Chief Executive Officer | BA7: Model E2 from the six ratings, the market-derived weights and rules R1–R13 · then Top of the reporting line | BB7: E2 | BC7: The six ratings on the market-average weights of Bands D–E · Leadership score 12.00 → E2 · Hay, Mercer IPE and public plans · experience 32.1 yrs vs the E2 market range 20+ yrs | BD7: =IF(SUM(BM7,BN7,BO7,BP7,BQ7,BR7,BS7)=0,0,(BM7*BT7+BN7*BU7+BO7*BV7+BP7*BW7+BQ7*BX7+BR7*BY7+BS7*BZ7)/SUM(BM7,BN7,BO7,BP7,BQ7,BR7,BS7)) -> 0 | BE7: =IF(LEFT(AY7,1)="X",AY7,IF(OR(AY7="B+",AY7="C+"),INDEX(LAD_PC,MAX(1,MIN(14,MATCH(AY7,LAD_PC,0)+IF(BD7>=0.5,1,IF(BD7<=-0.5,-1,0))))),INDEX(LAD_STD,MAX(1,MIN(12,MATCH(AY7,LAD_STD,0)+IF(BD7>=0.5,1,IF(BD7<=-0.5,-1,0))))))) -> E2 | BG7: =IF(BF7<>"",BF7,BE7) -> E2 | BH7: =IFERROR(CHOOSE(INDEX(B_RANK,MATCH(BG7,B_LVL,0)),"Band A","Band B","B+ · Player-Coach","Band C","C+ · Player-Coach","Band D","Band E"),"Band X · Consultant") -> Band E | BI7: =IF(BG7=AY7,"• Same",IF(INDEX(B_VAL,MATCH(BG7,B_LVL,0))>INDEX(B_VAL,MATCH(AY7,B_LVL,0)),"▲ Up","▼ Down")) -> • Same | BJ7: =IF(OR($M7="",$M7="—",$M7="Not in this file"),"",IFERROR(INDEX($BG$7:$BG$592,MATCH($M7,$D$7:$D$592,0)),"")) | BK7: =IFERROR(IF(BJ7="","—",IF(OR(LEFT(BG7,1)="X",LEFT(BJ7,1)="X"),"—",IF(AND(LEFT(BG7,1)="E",LEFT(BJ7,1)="E"),"Exception · Band E",IF(AND(INDEX(B_VAL,MATCH(BJ7,B_LVL,0))>=7,INDEX(B_RANK,MATCH(BG7,B_LVL,0))>=INDEX(B_RANK,MATCH(BJ7,B_LVL,0))),"⚠ Same band as a head manager",IF(INDEX(B_VAL,MATCH(BG7,B_LVL,0))>=INDEX(B_VAL,MATCH(BJ7,B_LVL,0)),"⚠ At or above the manager's level","OK"))))),"—") -> — | BM7: =IFERROR(INDEX(LMH_PTS,MATCH(Y7,LMH_KEY,0)),0) -> 9 | BN7: =IFERROR(INDEX(LMH_PTS,MATCH(Z7,LMH_KEY,0)),0) -> 3 | BO7: =IFERROR(INDEX(LMH_PTS,MATCH(AA7,LMH_KEY,0)),0) -> 3 | BP7: =IFERROR(INDEX(LMH_PTS,MATCH(AB7,LMH_KEY,0)),0) -> 3 | BQ7: =IFERROR(INDEX(LMH_PTS,MATCH(AC7,LMH_KEY,0)),0) -> 1 | BR7: =IFERROR(INDEX(LMH_PTS,MATCH(AD7,LMH_KEY,0)),0) -> 1 | BS7: =IFERROR(INDEX(LMH_PTS,MATCH(AE7,LMH_KEY,0)),0) -> 1 | BT7: =IFERROR(INDEX(LMH_STEP,MATCH(AF7,LMH_KEY,0)),0) -> 0 | BU7: =IFERROR(INDEX(LMH_STEP,MATCH(AG7,LMH_KEY,0)),0) -> 0 | BV7: =IFERROR(INDEX(LMH_STEP,MATCH(AH7,LMH_KEY,0)),0) -> 0 | BW7: =IFERROR(INDEX(LMH_STEP,MATCH(AI7,LMH_KEY,0)),0) -> 0 | BX7: =IFERROR(INDEX(LMH_STEP,MATCH(AJ7,LMH_KEY,0)),0) -> 0 | BY7: =IFERROR(INDEX(LMH_STEP,MATCH(AK7,LMH_KEY,0)),0) -> 0 | BZ7: =IFERROR(INDEX(LMH_STEP,MATCH(AL7,LMH_KEY,0)),0) -> 0 | CA7: Corporate|Management|Chief Executive Officer|E2|DE
A8: CARBON | B8: CRO - Carbon | C8: 1 | D8: IRIS2478 | E8: Dixit Jasani | F8: Chief Revenue Officer- Enterprise Division | G8: Chief Revenue Officer | H8: Enterprise Leadership | I8: Chief Officers · CXO | J8: People Manager | K8: RC-EN-CO-E1 | L8: Balachandran K | M8: IRIS0001 | N8: 27.9 | O8: 0.6 | P8: PGDM | Q8: Not in current mapping files | R8: E1 | S8: 0 of 20 | T8: Complexity: Evidence: no survey answers or KRAs on file → rating stays at the start Autonomy: Evidence: no survey answers or KRAs on file → rating stays at the start Accountability: Evidence: no survey answers or KRAs on file → rating stays at the start Leadership: Evidence: no survey answers or KRAs on file → rating stays at the start Business Impact: No … | U8: KRAs not received · manager to supply | V8: Latest rating: Not rated · manager · 9-box: Not placed · manager · Readiness: No rating data | W8: C M · Au M · Ac M · L M · BI M · Exp M · 27.9 yrs vs 20+ yrs · Edu M · PGDM | X8: Open ▸ | Y8: =IFERROR(INDEX(DL_C,MATCH($CA8,DL_KEY,0)),"M") -> H | Z8: =IFERROR(INDEX(DL_Au,MATCH($CA8,DL_KEY,0)),"M") -> M | AA8: =IFERROR(INDEX(DL_Ac,MATCH($CA8,DL_KEY,0)),"M") -> M | AB8: =IFERROR(INDEX(DL_L,MATCH($CA8,DL_KEY,0)),"M") -> M | AC8: =IFERROR(INDEX(DL_BI,MATCH($CA8,DL_KEY,0)),"M") -> L | AD8: =IFERROR(INDEX(DL_Exp,MATCH($CA8,DL_KEY,0)),"M") -> L | AE8: =IFERROR(INDEX(DL_Edu,MATCH($CA8,DL_KEY,0)),"M") -> L | AF8: M | AG8: M | AH8: M | AI8: M | AJ8: M | AK8: M | AL8: M | AM8: 0.363 | AN8: 0.19 | AO8: 0.113 | AP8: 0.2 | AQ8: 0.087 | AR8: 0.04 | AS8: 0.01 | AT8: 20+ yrs | AU8: Postgraduate / professional qualification; business leadership record | AV8: 5–8 function heads | AW8: E5 · SFIA 7 | AX8: S46–S51 Korn Ferry Hay evaluations · S04, S52 Mercer IPE · S53–S57 NHS, UK NJC/PSC, GLPC, SJC, US OPM point-factor plans · S58 McKinsey skills-based hiring · S60 WEF skills-first · S61 EY India 2026 · the Experience / Education split is an IRIS rule · S32 Google, Microsoft, Amazon · S33 Infosys · S35 Accenture India · IRIS experience guide · S01 Aon Radford · S02 Pave · S08 SFIA 9 · S03 Mercer career levels | AY8: E1 | AZ8: Band E · Enterprise leadership · CXO / President | BA8: Model E1 from the six ratings, the market-derived weights and rules R1–R13 · then Band E with Band E · agreed exception · manager E2 | BB8: E1 | BC8: The six ratings on the market-average weights of Bands D–E · Leadership score 11.05 → E1 · Hay, Mercer IPE and public plans · experience 27.9 yrs vs the E1 market range 20+ yrs | BD8: =IF(SUM(BM8,BN8,BO8,BP8,BQ8,BR8,BS8)=0,0,(BM8*BT8+BN8*BU8+BO8*BV8+BP8*BW8+BQ8*BX8+BR8*BY8+BS8*BZ8)/SUM(BM8,BN8,BO8,BP8,BQ8,BR8,BS8)) -> 0 | BE8: =IF(LEFT(AY8,1)="X",AY8,IF(OR(AY8="B+",AY8="C+"),INDEX(LAD_PC,MAX(1,MIN(14,MATCH(AY8,LAD_PC,0)+IF(BD8>=0.5,1,IF(BD8<=-0.5,-1,0))))),INDEX(LAD_STD,MAX(1,MIN(12,MATCH(AY8,LAD_STD,0)+IF(BD8>=0.5,1,IF(BD8<=-0.5,-1,0))))))) -> E1 | BG8: =IF(BF8<>"",BF8,BE8) -> E1 | BH8: =IFERROR(CHOOSE(INDEX(B_RANK,MATCH(BG8,B_LVL,0)),"Band A","Band B","B+ · Player-Coach","Band C","C+ · Player-Coach","Band D","Band E"),"Band X · Consultant") -> Band E | BI8: =IF(BG8=AY8,"• Same",IF(INDEX(B_VAL,MATCH(BG8,B_LVL,0))>INDEX(B_VAL,MATCH(AY8,B_LVL,0)),"▲ Up","▼ Down")) -> • Same | BJ8: =IF(OR($M8="",$M8="—",$M8="Not in this file"),"",IFERROR(INDEX($BG$7:$BG$592,MATCH($M8,$D$7:$D$592,0)),"")) -> E2 | BK8: =IFERROR(IF(BJ8="","—",IF(OR(LEFT(BG8,1)="X",LEFT(BJ8,1)="X"),"—",IF(AND(LEFT(BG8,1)="E",LEFT(BJ8,1)="E"),"Exception · Band E",IF(AND(INDEX(B_VAL,MATCH(BJ8,B_LVL,0))>=7,INDEX(B_RANK,MATCH(BG8,B_LVL,0))>=INDEX(B_RANK,MATCH(BJ8,B_LVL,0))),"⚠ Same band as a head manager",IF(INDEX(B_VAL,MATCH(BG8,B_LVL,0))>=INDEX(B_VAL,MATCH(BJ8,B_LVL,0)),"⚠ At or above the manager's level","OK"))))),"—") -> Exception · Band E | BM8: =IFERROR(INDEX(LMH_PTS,MATCH(Y8,LMH_KEY,0)),0) -> 9 | BN8: =IFERROR(INDEX(LMH_PTS,MATCH(Z8,LMH_KEY,0)),0) -> 3 | BO8: =IFERROR(INDEX(LMH_PTS,MATCH(AA8,LMH_KEY,0)),0) -> 3 | BP8: =IFERROR(INDEX(LMH_PTS,MATCH(AB8,LMH_KEY,0)),0) -> 3 | BQ8: =IFERROR(INDEX(LMH_PTS,MATCH(AC8,LMH_KEY,0)),0) -> 1 | BR8: =IFERROR(INDEX(LMH_PTS,MATCH(AD8,LMH_KEY,0)),0) -> 1 | BS8: =IFERROR(INDEX(LMH_PTS,MATCH(AE8,LMH_KEY,0)),0) -> 1 | BT8: =IFERROR(INDEX(LMH_STEP,MATCH(AF8,LMH_KEY,0)),0) -> 0 | BU8: =IFERROR(INDEX(LMH_STEP,MATCH(AG8,LMH_KEY,0)),0) -> 0 | BV8: =IFERROR(INDEX(LMH_STEP,MATCH(AH8,LMH_KEY,0)),0) -> 0 | BW8: =IFERROR(INDEX(LMH_STEP,MATCH(AI8,LMH_KEY,0)),0) -> 0 | BX8: =IFERROR(INDEX(LMH_STEP,MATCH(AJ8,LMH_KEY,0)),0) -> 0 | BY8: =IFERROR(INDEX(LMH_STEP,MATCH(AK8,LMH_KEY,0)),0) -> 0 | BZ8: =IFERROR(INDEX(LMH_STEP,MATCH(AL8,LMH_KEY,0)),0) -> 0 | CA8: CARBON|CRO - Carbon|Chief Revenue Officer|E1|DE
A9: CARBON | B9: CARBON Business Head | C9: 2 | D9: IRIS0391 | E9: Anuradha RK | F9: Business Head | G9: Business Head | H9: Executive Leadership | I9: Business Head | J9: People Manager | K9: RC-EL-BH-D2 | L9: Dixit Jasani | M9: IRIS2478 | N9: 17.1 | O9: 16.4 | P9: MBA | Q9: Not in current mapping files | R9: D2 | S9: 0 of 20 | T9: Complexity: Evidence: no survey answers or KRAs on file → rating stays at the start Autonomy: Evidence: no survey answers or KRAs on file → rating stays at the start Accountability: Evidence: no survey answers or KRAs on file → rating stays at the start Leadership: Evidence: no survey answers or KRAs on file → rating stays at the start Business Impact: No … | U9: KRAs not received · manager to supply | V9: Latest rating: Not rated · manager · 9-box: Not placed · manager · Readiness: No rating data | W9: C L · Au L · Ac L · L L · BI L · Exp L · 17.1 yrs vs 18–24 yrs · Edu M · MBA | X9: Open ▸ | Y9: =IFERROR(INDEX(DL_C,MATCH($CA9,DL_KEY,0)),"M") -> H | Z9: =IFERROR(INDEX(DL_Au,MATCH($CA9,DL_KEY,0)),"M") -> M | AA9: =IFERROR(INDEX(DL_Ac,MATCH($CA9,DL_KEY,0)),"M") -> M | AB9: =IFERROR(INDEX(DL_L,MATCH($CA9,DL_KEY,0)),"M") -> M | AC9: =IFERROR(INDEX(DL_BI,MATCH($CA9,DL_KEY,0)),"M") -> L | AD9: =IFERROR(INDEX(DL_Exp,MATCH($CA9,DL_KEY,0)),"M") -> L | AE9: =IFERROR(INDEX(DL_Edu,MATCH($CA9,DL_KEY,0)),"M") -> L | AF9: M | AG9: M | AH9: M | AI9: M | AJ9: M | AK9: M | AL9: M | AM9: 0.363 | AN9: 0.19 | AO9: 0.113 | AP9: 0.2 | AQ9: 0.087 | AR9: 0.04 | AS9: 0.01 | AT9: 18–24 yrs | AU9: Postgraduate / professional qualification preferred | AV9: 5–8 AVPs / heads | AW9: E3–E4 · SFIA 7 Set strategy | AX9: S46–S51 Korn Ferry Hay evaluations · S04, S52 Mercer IPE · S53–S57 NHS, UK NJC/PSC, GLPC, SJC, US OPM point-factor plans · S58 McKinsey skills-based hiring · S60 WEF skills-first · S61 EY India 2026 · the Experience / Education split is an IRIS rule · S32 Google, Microsoft, Amazon · S33 Infosys · S35 Accenture India · IRIS experience guide · S01 Aon Radford · S02 Pave · S08 SFIA 9 · S03 Mercer career levels | AY9: D2 | AZ9: Band D · Business leadership · Senior Vice President / Business Head | BA9: Model D2 from the six ratings, the market-derived weights and rules R1–R13 · then No change · already below the manager | BB9: D1 | BC9: The six ratings on the market-average weights of Bands D–E · Leadership score 9.02 → D1 · Hay, Mercer IPE and public plans · experience 17.1 yrs vs the D1 market range 15–20 yrs | BD9: =IF(SUM(BM9,BN9,BO9,BP9,BQ9,BR9,BS9)=0,0,(BM9*BT9+BN9*BU9+BO9*BV9+BP9*BW9+BQ9*BX9+BR9*BY9+BS9*BZ9)/SUM(BM9,BN9,BO9,BP9,BQ9,BR9,BS9)) -> 0 | BE9: =IF(LEFT(AY9,1)="X",AY9,IF(OR(AY9="B+",AY9="C+"),INDEX(LAD_PC,MAX(1,MIN(14,MATCH(AY9,LAD_PC,0)+IF(BD9>=0.5,1,IF(BD9<=-0.5,-1,0))))),INDEX(LAD_STD,MAX(1,MIN(12,MATCH(AY9,LAD_STD,0)+IF(BD9>=0.5,1,IF(BD9<=-0.5,-1,0))))))) -> D2 | BG9: =IF(BF9<>"",BF9,BE9) -> D2 | BH9: =IFERROR(CHOOSE(INDEX(B_RANK,MATCH(BG9,B_LVL,0)),"Band A","Band B","B+ · Player-Coach","Band C","C+ · Player-Coach","Band D","Band E"),"Band X · Consultant") -> Band D | BI9: =IF(BG9=AY9,"• Same",IF(INDEX(B_VAL,MATCH(BG9,B_LVL,0))>INDEX(B_VAL,MATCH(AY9,B_LVL,0)),"▲ Up","▼ Down")) -> • Same | BJ9: =IF(OR($M9="",$M9="—",$M9="Not in this file"),"",IFERROR(INDEX($BG$7:$BG$592,MATCH($M9,$D$7:$D$592,0)),"")) -> E1 | BK9: =IFERROR(IF(BJ9="","—",IF(OR(LEFT(BG9,1)="X",LEFT(BJ9,1)="X"),"—",IF(AND(LEFT(BG9,1)="E",LEFT(BJ9,1)="E"),"Exception · Band E",IF(AND(INDEX(B_VAL,MATCH(BJ9,B_LVL,0))>=7,INDEX(B_RANK,MATCH(BG9,B_LVL,0))>=INDEX(B_RANK,MATCH(BJ9,B_LVL,0))),"⚠ Same band as a head manager",IF(INDEX(B_VAL,MATCH(BG9,B_LVL,0))>=INDEX(B_VAL,MATCH(BJ9,B_LVL,0)),"⚠ At or above the manager's level","OK"))))),"—") -> OK | BM9: =IFERROR(INDEX(LMH_PTS,MATCH(Y9,LMH_KEY,0)),0) -> 9 | BN9: =IFERROR(INDEX(LMH_PTS,MATCH(Z9,LMH_KEY,0)),0) -> 3 | BO9: =IFERROR(INDEX(LMH_PTS,MATCH(AA9,LMH_KEY,0)),0) -> 3 | BP9: =IFERROR(INDEX(LMH_PTS,MATCH(AB9,LMH_KEY,0)),0) -> 3 | BQ9: =IFERROR(INDEX(LMH_PTS,MATCH(AC9,LMH_KEY,0)),0) -> 1 | BR9: =IFERROR(INDEX(LMH_PTS,MATCH(AD9,LMH_KEY,0)),0) -> 1 | BS9: =IFERROR(INDEX(LMH_PTS,MATCH(AE9,LMH_KEY,0)),0) -> 1 | BT9: =IFERROR(INDEX(LMH_STEP,MATCH(AF9,LMH_KEY,0)),0) -> 0 | BU9: =IFERROR(INDEX(LMH_STEP,MATCH(AG9,LMH_KEY,0)),0) -> 0 | BV9: =IFERROR(INDEX(LMH_STEP,MATCH(AH9,LMH_KEY,0)),0) -> 0 | BW9: =IFERROR(INDEX(LMH_STEP,MATCH(AI9,LMH_KEY,0)),0) -> 0 | BX9: =IFERROR(INDEX(LMH_STEP,MATCH(AJ9,LMH_KEY,0)),0) -> 0 | BY9: =IFERROR(INDEX(LMH_STEP,MATCH(AK9,LMH_KEY,0)),0) -> 0 | BZ9: =IFERROR(INDEX(LMH_STEP,MATCH(AL9,LMH_KEY,0)),0) -> 0 | CA9: CARBON|CARBON Business Head|Business Head|D2|DE
A10: CARBON | B10: Customer Experience | C10: 3 | D10: IRIS2359 | E10: Suman Adhikary | F10: Senior Vice President - Customer Experience | G10: Senior Vice President – Customer Experience | H10: Executive Leadership | I10: Business Head | J10: People Manager | K10: RC-EL-BH-D1 | L10: Anuradha RK | M10: IRIS0391 | N10: 28.7 | O10: 1.5 | P10: B.E | Q10: Not in current mapping files | R10: D1 | S10: 0 of 20 | T10: Complexity: Evidence: no survey answers or KRAs on file → rating stays at the start Autonomy: Evidence: no survey answers or KRAs on file → rating stays at the start Accountability: Evidence: no survey answers or KRAs on file → rating stays at the start Leadership: Evidence: no survey answers or KRAs on file → rating stays at the start Business Impact: No … | U10: KRAs not received · manager to supply | V10: Latest rating: Not rated · manager · 9-box: Underperformer / Exit Risk · Readiness: No rating data | W10: C H · Au H · Ac H · L H · BI H · Exp H · 28.7 yrs vs 12–17 yrs · Edu L · B.E | X10: Open ▸ | Y10: =IFERROR(INDEX(DL_C,MATCH($CA10,DL_KEY,0)),"M") -> H | Z10: =IFERROR(INDEX(DL_Au,MATCH($CA10,DL_KEY,0)),"M") -> M | AA10: =IFERROR(INDEX(DL_Ac,MATCH($CA10,DL_KEY,0)),"M") -> M | AB10: =IFERROR(INDEX(DL_L,MATCH($CA10,DL_KEY,0)),"M") -> M | AC10: =IFERROR(INDEX(DL_BI,MATCH($CA10,DL_KEY,0)),"M") -> L | AD10: =IFERROR(INDEX(DL_Exp,MATCH($CA10,DL_KEY,0)),"M") -> L | AE10: =IFERROR(INDEX(DL_Edu,MATCH($CA10,DL_KEY,0)),"M") -> L | AF10: M | AG10: M | AH10: M | AI10: M | AJ10: M | AK10: M | AL10: M | AM10: 0.433 | AN10: 0.18 | AO10: 0.107 | AP10: 0.15 | AQ10: 0.08 | AR10: 0.04 | AS10: 0.01 | AT10: 12–17 yrs | AU10: Postgraduate / professional qualification preferred | AV10: 5–8 managers / associate heads | AW10: P7 / M6 · SFIA 6 Initiate, influence | AX10: S46–S51 Korn Ferry Hay evaluations · S04, S52 Mercer IPE · S53–S57 NHS, UK NJC/PSC, GLPC, SJC, US OPM point-factor plans · S58 McKinsey skills-based hiring · S60 WEF skills-first · S61 EY India 2026 · the Experience / Education split is an IRIS rule · S32 Google, Microsoft, Amazon · S33 Infosys · S35 Accenture India · IRIS experience guide · S01 Aon Radford · S02 Pave · S08 SFIA 9 · S03 Mercer career levels | AY10: C2 | AZ10: Band C · Principal / Head · Head of Function | BA10: Model D1 from the six ratings, the market-derived weights and rules R1–R13 · then Band rule: manager D2 is a head in Band D · Business leadership; a reportee sits in a lower band · D1 → C2 · move down · pay and title protected for one cycle | BB10: D2 | BC10: The six ratings on the market-average weights of Band C · Head / manager score 10.10 → D2 · Hay, Mercer IPE and public plans · experience 28.7 yrs vs the D2 market range 18–24 yrs | BD10: =IF(SUM(BM10,BN10,BO10,BP10,BQ10,BR10,BS10)=0,0,(BM10*BT10+BN10*BU10+BO10*BV10+BP10*BW10+BQ10*BX10+BR10*BY10+BS10*BZ10)/SUM(BM10,BN10,BO10,BP10,BQ10,BR10,BS10)) -> 0 | BE10: =IF(LEFT(AY10,1)="X",AY10,IF(OR(AY10="B+",AY10="C+"),INDEX(LAD_PC,MAX(1,MIN(14,MATCH(AY10,LAD_PC,0)+IF(BD10>=0.5,1,IF(BD10<=-0.5,-1,0))))),INDEX(LAD_STD,MAX(1,MIN(12,MATCH(AY10,LAD_STD,0)+IF(BD10>=0.5,1,IF(BD10<=-0.5,-1,0))))))) -> C2 | BG10: =IF(BF10<>"",BF10,BE10) -> C2 | BH10: =IFERROR(CHOOSE(INDEX(B_RANK,MATCH(BG10,B_LVL,0)),"Band A","Band B","B+ · Player-Coach","Band C","C+ · Player-Coach","Band D","Band E"),"Band X · Consultant") -> Band C | BI10: =IF(BG10=AY10,"• Same",IF(INDEX(B_VAL,MATCH(BG10,B_LVL,0))>INDEX(B_VAL,MATCH(AY10,B_LVL,0)),"▲ Up","▼ Down")) -> • Same | BJ10: =IF(OR($M10="",$M10="—",$M10="Not in this file"),"",IFERROR(INDEX($BG$7:$BG$592,MATCH($M10,$D$7:$D$592,0)),"")) -> D2 | BK10: =IFERROR(IF(BJ10="","—",IF(OR(LEFT(BG10,1)="X",LEFT(BJ10,1)="X"),"—",IF(AND(LEFT(BG10,1)="E",LEFT(BJ10,1)="E"),"Exception · Band E",IF(AND(INDEX(B_VAL,MATCH(BJ10,B_LVL,0))>=7,INDEX(B_RANK,MATCH(BG10,B_LVL,0))>=INDEX(B_RANK,MATCH(BJ10,B_LVL,0))),"⚠ Same band as a head manager",IF(INDEX(B_VAL,MATCH(BG10,B_LVL,0))>=INDEX(B_VAL,MATCH(BJ10,B_LVL,0)),"⚠ At or above the manager's level","OK"))))),"—") -> OK | BM10: =IFERROR(INDEX(LMH_PTS,MATCH(Y10,LMH_KEY,0)),0) -> 9 | BN10: =IFERROR(INDEX(LMH_PTS,MATCH(Z10,LMH_KEY,0)),0) -> 3 | BO10: =IFERROR(INDEX(LMH_PTS,MATCH(AA10,LMH_KEY,0)),0) -> 3 | BP10: =IFERROR(INDEX(LMH_PTS,MATCH(AB10,LMH_KEY,0)),0) -> 3 | BQ10: =IFERROR(INDEX(LMH_PTS,MATCH(AC10,LMH_KEY,0)),0) -> 1 | BR10: =IFERROR(INDEX(LMH_PTS,MATCH(AD10,LMH_KEY,0)),0) -> 1 | BS10: =IFERROR(INDEX(LMH_PTS,MATCH(AE10,LMH_KEY,0)),0) -> 1 | BT10: =IFERROR(INDEX(LMH_STEP,MATCH(AF10,LMH_KEY,0)),0) -> 0 | BU10: =IFERROR(INDEX(LMH_STEP,MATCH(AG10,LMH_KEY,0)),0) -> 0 | BV10: =IFERROR(INDEX(LMH_STEP,MATCH(AH10,LMH_KEY,0)),0) -> 0 | BW10: =IFERROR(INDEX(LMH_STEP,MATCH(AI10,LMH_KEY,0)),0) -> 0 | BX10: =IFERROR(INDEX(LMH_STEP,MATCH(AJ10,LMH_KEY,0)),0) -> 0 | BY10: =IFERROR(INDEX(LMH_STEP,MATCH(AK10,LMH_KEY,0)),0) -> 0 | BZ10: =IFERROR(INDEX(LMH_STEP,MATCH(AL10,LMH_KEY,0)),0) -> 0 | CA10: CARBON|Customer Experience|Senior Vice President – Customer Experience|C2|C-M
A11: CARBON | B11: Support | C11: 4 | D11: IRIS1335 | E11: Anushree Aparajit | F11: Global Customer Success Head | G11: Associate Head – Customer Success | H11: Executive Leadership | I11: Business Head | J11: People Manager | K11: RC-EL-BH-C1 | L11: Suman Adhikary | M11: IRIS2359 | N11: 14.6 | O11: 13.3 | P11: CA | Q11: L7 – Head / Sr Director | R11: C1 | S11: 0 of 20 | T11: Complexity: Evidence: no survey answers or KRAs on file → rating stays at the start Autonomy: Evidence: no survey answers or KRAs on file → rating stays at the start Accountability: Evidence: no survey answers or KRAs on file → rating stays at the start Leadership: Evidence: no survey answers or KRAs on file → rating stays at the start Business Impact: … | U11: Received · manager annual · Net Revenue Retention ≥100–105% Target ARR - to be achieved - INR 2.35 CR 90% reach value milestone in 90 days Develop advocates · Promoter per CEM Produce case studies annually CSAT ≥90% NPS ≥30 100% QBR coverage for accounts 100% CRM hygiene maintained Renewal forecast accuracy ≥95% Outstanding receivables ≤45 … | V11: Latest rating: 4 · Potential: Medium · 9-box: High Impact / Growth Talent · Readiness: Ready in 6–12 months | W11: C H · Au H · Ac M · L H · BI H · Exp H · 14.6 yrs vs 8–12 yrs · Edu H · CA | X11: Open ▸ | Y11: =IFERROR(INDEX(DL_C,MATCH($CA11,DL_KEY,0)),"M") -> H | Z11: =IFERROR(INDEX(DL_Au,MATCH($CA11,DL_KEY,0)),"M") -> M | AA11: =IFERROR(INDEX(DL_Ac,MATCH($CA11,DL_KEY,0)),"M") -> M | AB11: =IFERROR(INDEX(DL_L,MATCH($CA11,DL_KEY,0)),"M") -> M | AC11: =IFERROR(INDEX(DL_BI,MATCH($CA11,DL_KEY,0)),"M") -> L | AD11: =IFERROR(INDEX(DL_Exp,MATCH($CA11,DL_KEY,0)),"M") -> L | AE11: =IFERROR(INDEX(DL_Edu,MATCH($CA11,DL_KEY,0)),"M") -> L | AF11: M | AG11: M | AH11: M | AI11: M | AJ11: M | AK11: M | AL11: M | AM11: 0.37 | AN11: 0.183 | AO11: 0.113 | AP11: 0.15 | AQ11: 0.087 | AR11: 0.06 | AS11: 0.04 | AT11: 8–13 | AU11: Postgraduate or professional qualification preferred | AV11: IC: none · People: 5–8 incl. team leads | AW11: P5 / M4 · SFIA 5 Ensure, advise | AX11: S46–S51 Korn Ferry Hay evaluations · S04, S52 Mercer IPE · S53–S57 NHS, UK NJC/PSC, GLPC, SJC, US OPM point-factor plans · S58 McKinsey skills-based hiring · S60 WEF skills-first · S61 EY India 2026 · the Experience / Education split is an IRIS rule · S32 Google, Microsoft, Amazon · S33 Infosys · S35 Accenture India · IRIS experience guide · S01 Aon Radford · S02 Pave · S08 SFIA 9 · S03 Mercer career levels | AY11: B3 | AZ11: Band B · Specialist / Manager · Senior Manager | BA11: Model C1 from the six ratings, the market-derived weights and rules R1–R13 · then Band rule: manager C2 is a head in Band C · Principal / Head; a reportee sits in a lower band · C1 → B3 · move down · pay and title protected for one cycle | BB11: C2 | BC11: The six ratings on the market-average weights of Band B · People Manager score 7.69 → C2 · Hay, Mercer IPE and public plans · experience 14.6 yrs vs the C2 market range 12–17 yrs | BD11: =IF(SUM(BM11,BN11,BO11,BP11,BQ11,BR11,BS11)=0,0,(BM11*BT11+BN11*BU11+BO11*BV11+BP11*BW11+BQ11*BX11+BR11*BY11+BS11*BZ11)/SUM(BM11,BN11,BO11,BP11,BQ11,BR11,BS11)) -> 0 | BE11: =IF(LEFT(AY11,1)="X",AY11,IF(OR(AY11="B+",AY11="C+"),INDEX(LAD_PC,MAX(1,MIN(14,MATCH(AY11,LAD_PC,0)+IF(BD11>=0.5,1,IF(BD11<=-0.5,-1,0))))),INDEX(LAD_STD,MAX(1,MIN(12,MATCH(AY11,LAD_STD,0)+IF(BD11>=0.5,1,IF(BD11<=-0.5,-1,0))))))) -> B3 | BG11: =IF(BF11<>"",BF11,BE11) -> B3 | BH11: =IFERROR(CHOOSE(INDEX(B_RANK,MATCH(BG11,B_LVL,0)),"Band A","Band B","B+ · Player-Coach","Band C","C+ · Player-Coach","Band D","Band E"),"Band X · Consultant") -> Band B | BI11: =IF(BG11=AY11,"• Same",IF(INDEX(B_VAL,MATCH(BG11,B_LVL,0))>INDEX(B_VAL,MATCH(AY11,B_LVL,0)),"▲ Up","▼ Down")) -> • Same | BJ11: =IF(OR($M11="",$M11="—",$M11="Not in this file"),"",IFERROR(INDEX($BG$7:$BG$592,MATCH($M11,$D$7:$D$592,0)),"")) -> C2 | BK11: =IFERROR(IF(BJ11="","—",IF(OR(LEFT(BG11,1)="X",LEFT(BJ11,1)="X"),"—",IF(AND(LEFT(BG11,1)="E",LEFT(BJ11,1)="E"),"Exception · Band E",IF(AND(INDEX(B_VAL,MATCH(BJ11,B_LVL,0))>=7,INDEX(B_RANK,MATCH(BG11,B_LVL,0))>=INDEX(B_RANK,MATCH(BJ11,B_LVL,0))),"⚠ Same band as a head manager",IF(INDEX(B_VAL,MATCH(BG11,B_LVL,0))>=INDEX(B_VAL,MATCH(BJ11,B_LVL,0)),"⚠ At or above the manager's level","OK"))))),"—") -> OK | BM11: =IFERROR(INDEX(LMH_PTS,MATCH(Y11,LMH_KEY,0)),0) -> 9 | BN11: =IFERROR(INDEX(LMH_PTS,MATCH(Z11,LMH_KEY,0)),0) -> 3 | BO11: =IFERROR(INDEX(LMH_PTS,MATCH(AA11,LMH_KEY,0)),0) -> 3 | BP11: =IFERROR(INDEX(LMH_PTS,MATCH(AB11,LMH_KEY,0)),0) -> 3 | BQ11: =IFERROR(INDEX(LMH_PTS,MATCH(AC11,LMH_KEY,0)),0) -> 1 | BR11: =IFERROR(INDEX(LMH_PTS,MATCH(AD11,LMH_KEY,0)),0) -> 1 | BS11: =IFERROR(INDEX(LMH_PTS,MATCH(AE11,LMH_KEY,0)),0) -> 1 | BT11: =IFERROR(INDEX(LMH_STEP,MATCH(AF11,LMH_KEY,0)),0) -> 0 | BU11: =IFERROR(INDEX(LMH_STEP,MATCH(AG11,LMH_KEY,0)),0) -> 0 | BV11: =IFERROR(INDEX(LMH_STEP,MATCH(AH11,LMH_KEY,0)),0) -> 0 | BW11: =IFERROR(INDEX(LMH_STEP,MATCH(AI11,LMH_KEY,0)),0) -> 0 | BX11: =IFERROR(INDEX(LMH_STEP,MATCH(AJ11,LMH_KEY,0)),0) -> 0 | BY11: =IFERROR(INDEX(LMH_STEP,MATCH(AK11,LMH_KEY,0)),0) -> 0 | BZ11: =IFERROR(INDEX(LMH_STEP,MATCH(AL11,LMH_KEY,0)),0) -> 0 | CA11: CARBON|Support|Associate Head – Customer Success|B3|B-M
A12: CARBON | B12: Support | C12: 5 | D12: IRIS1935 | E12: Chinmayi Patil | F12: Customer Success Manager | G12: Customer Success Specialist | H12: Customer Success & Support | I12: Customer Success & Account Management | J12: IC | K12: RC-036 | L12: Anushree Aparajit | M12: IRIS1335 | N12: 5.2 | O12: 5.2 | P12: MMS | Q12: L5 – Manager | R12: B2 | S12: 20 of 20 | T12: • Role / sub-team: Support — Customer Success Manager. • Core purpose: Post sales customer journey, retention and renewal, up sell and cross sell of other products for account expansion and revenue growth. • Decision-making autonomy: Can independently product training material. • Is this something only they do: Most of us. • What's different about this … | U12: Received · manager annual · Net Revenue Retention ≥100–105% Target ARR - to be achieved: INR 3000000 90% reach value milestone in 90 days Develop advocates · Promoter per CEM Produce case studies annually CSAT ≥90% NPS ≥30 100% QBR coverage for accounts 100% CRM hygiene maintained Renewal forecast accuracy ≥95% Outstanding receivables ≤45 … | V12: Latest rating: 4 · Potential: High · 9-box: Future Leader · Readiness: Ready now | W12: C M · Au M · Ac M · L L · BI M · Exp L · 5.2 yrs vs 6–9 yrs · Edu H · MMS | X12: Open ▸ | Y12: =IFERROR(INDEX(DL_C,MATCH($CA12,DL_KEY,0)),"M") -> H | Z12: =IFERROR(INDEX(DL_Au,MATCH($CA12,DL_KEY,0)),"M") -> M | AA12: =IFERROR(INDEX(DL_Ac,MATCH($CA12,DL_KEY,0)),"M") -> M | AB12: =IFERROR(INDEX(DL_L,MATCH($CA12,DL_KEY,0)),"M") -> L | AC12: =IFERROR(INDEX(DL_BI,MATCH($CA12,DL_KEY,0)),"M") -> M | AD12: =IFERROR(INDEX(DL_Exp,MATCH($CA12,DL_KEY,0)),"M") -> L | AE12: =IFERROR(INDEX(DL_Edu,MATCH($CA12,DL_KEY,0)),"M") -> L | AF12: M | AG12: M | AH12: M | AI12: M | AJ12: M | AK12: M | AL12: M | AM12: 0.513 | AN12: 0.173 | AO12: 0.097 | AP12: 0.05 | AQ12: 0.07 | AR12: 0.06 | AS12: 0.04 | AT12: 6–10 | AU12: Graduate or postgraduate; professional qualification preferred | AV12: IC: none · People: 6–8 knowledge work, 8–12 standardised delivery | AW12: P4 / M3 · SFIA 4–5 | AX12: S46–S51 Korn Ferry Hay evaluations · S04, S52 Mercer IPE · S53–S57 NHS, UK NJC/PSC, GLPC, SJC, US OPM point-factor plans · S58 McKinsey skills-based hiring · S60 WEF skills-first · S61 EY India 2026 · the Experience / Education split is an IRIS rule · S32 Google, Microsoft, Amazon · S33 Infosys · S35 Accenture India · IRIS experience guide · S01 Aon Radford · S02 Pave · S08 SFIA 9 · S03 Mercer career levels | AY12: B2 | AZ12: Band B · Specialist / Manager · Senior Specialist | BA12: Model B2 from the six ratings, the market-derived weights and rules R1–R13 · then No change · already below the manager | BB12: B1 | BC12: The six ratings on the market-average weights of Band B · Specialist / POD Lead score 4.49 → B1 · Hay, Mercer IPE and public plans · experience 5.2 yrs vs the B1 market range 4–8 | BD12: =IF(SUM(BM12,BN12,BO12,BP12,BQ12,BR12,BS12)=0,0,(BM12*BT12+BN12*BU12+BO12*BV12+BP12*BW12+BQ12*BX12+BR12*BY12+BS12*BZ12)/SUM(BM12,BN12,BO12,BP12,BQ12,BR12,BS12)) -> 0 | BE12: =IF(LEFT(AY12,1)="X",AY12,IF(OR(AY12="B+",AY12="C+"),INDEX(LAD_PC,MAX(1,MIN(14,MATCH(AY12,LAD_PC,0)+IF(BD12>=0.5,1,IF(BD12<=-0.5,-1,0))))),INDEX(LAD_STD,MAX(1,MIN(12,MATCH(AY12,LAD_STD,0)+IF(BD12>=0.5,1,IF(BD12<=-0.5,-1,0))))))) -> B2 | BG12: =IF(BF12<>"",BF12,BE12) -> B2 | BH12: =IFERROR(CHOOSE(INDEX(B_RANK,MATCH(BG12,B_LVL,0)),"Band A","Band B","B+ · Player-Coach","Band C","C+ · Player-Coach","Band D","Band E"),"Band X · Consultant") -> Band B | BI12: =IF(BG12=AY12,"• Same",IF(INDEX(B_VAL,MATCH(BG12,B_LVL,0))>INDEX(B_VAL,MATCH(AY12,B_LVL,0)),"▲ Up","▼ Down")) -> • Same | BJ12: =IF(OR($M12="",$M12="—",$M12="Not in this file"),"",IFERROR(INDEX($BG$7:$BG$592,MATCH($M12,$D$7:$D$592,0)),"")) -> B3 | BK12: =IFERROR(IF(BJ12="","—",IF(OR(LEFT(BG12,1)="X",LEFT(BJ12,1)="X"),"—",IF(AND(LEFT(BG12,1)="E",LEFT(BJ12,1)="E"),"Exception · Band E",IF(AND(INDEX(B_VAL,MATCH(BJ12,B_LVL,0))>=7,INDEX(B_RANK,MATCH(BG12,B_LVL,0))>=INDEX(B_RANK,MATCH(BJ12,B_LVL,0))),"⚠ Same band as a head manager",IF(INDEX(B_VAL,MATCH(BG12,B_LVL,0))>=INDEX(B_VAL,MATCH(BJ12,B_LVL,0)),"⚠ At or above the manager's level","OK"))))),"—") -> OK | BM12: =IFERROR(INDEX(LMH_PTS,MATCH(Y12,LMH_KEY,0)),0) -> 9 | BN12: =IFERROR(INDEX(LMH_PTS,MATCH(Z12,LMH_KEY,0)),0) -> 3 | BO12: =IFERROR(INDEX(LMH_PTS,MATCH(AA12,LMH_KEY,0)),0) -> 3 | BP12: =IFERROR(INDEX(LMH_PTS,MATCH(AB12,LMH_KEY,0)),0) -> 1 | BQ12: =IFERROR(INDEX(LMH_PTS,MATCH(AC12,LMH_KEY,0)),0) -> 3 | BR12: =IFERROR(INDEX(LMH_PTS,MATCH(AD12,LMH_KEY,0)),0) -> 1 | BS12: =IFERROR(INDEX(LMH_PTS,MATCH(AE12,LMH_KEY,0)),0) -> 1 | BT12: =IFERROR(INDEX(LMH_STEP,MATCH(AF12,LMH_KEY,0)),0) -> 0 | BU12: =IFERROR(INDEX(LMH_STEP,MATCH(AG12,LMH_KEY,0)),0) -> 0 | BV12: =IFERROR(INDEX(LMH_STEP,MATCH(AH12,LMH_KEY,0)),0) -> 0 | BW12: =IFERROR(INDEX(LMH_STEP,MATCH(AI12,LMH_KEY,0)),0) -> 0 | BX12: =IFERROR(INDEX(LMH_STEP,MATCH(AJ12,LMH_KEY,0)),0) -> 0 | BY12: =IFERROR(INDEX(LMH_STEP,MATCH(AK12,LMH_KEY,0)),0) -> 0 | BZ12: =IFERROR(INDEX(LMH_STEP,MATCH(AL12,LMH_KEY,0)),0) -> 0 | CA12: CARBON|Support|Customer Success Specialist|B2|B-IC
A13: CARBON | B13: Support | C13: 5 | D13: IRIS1963 | E13: Neha Gajbhiye | F13: Manager- Customer Engagement | G13: Senior Customer Success Specialist – POD Lead | H13: Customer Success & Support | I13: Customer Success & Account Management | J13: POD Lead | K13: RC-036 | L13: Anushree Aparajit | M13: IRIS1335 | N13: 16.2 | O13: 4.9 | P13: MBA | Q13: L5 – Manager | R13: B2 | S13: 20 of 20 | T13: • Role / sub-team: Support — Manager- Customer Engagement. • Core purpose: Client interaction, Domain expertise, Go live, platform enablement, training and end to end hypercare. • Decision-making autonomy: Can independently trainings only. • Is this something only they do: Everyone does the same but in different geos. • What's different about this role: … | U13: Received · manager annual · Net Revenue Retention ≥100–105% Target ARR - to be achieved: INR 1700000 90% reach value milestone in 90 days Develop advocates · Promoter per CEM Produce case studies annually CSAT ≥90% NPS ≥30 100% QBR coverage for accounts 100% CRM hygiene maintained Renewal forecast accuracy ≥95% Outstanding receivables ≤45 … | V13: Latest rating: 4 · Potential: High · 9-box: High Impact / Growth Talent · Readiness: Ready now | W13: C L · Au L · Ac M · L L · BI M · Exp H · 16.2 yrs vs 6–9 yrs · Edu H · MBA | X13: Open ▸ | Y13: =IFERROR(INDEX(DL_C,MATCH($CA13,DL_KEY,0)),"M") -> H | Z13: =IFERROR(INDEX(DL_Au,MATCH($CA13,DL_KEY,0)),"M") -> M | AA13: =IFERROR(INDEX(DL_Ac,MATCH($CA13,DL_KEY,0)),"M") -> M | AB13: =IFERROR(INDEX(DL_L,MATCH($CA13,DL_KEY,0)),"M") -> L | AC13: =IFERROR(INDEX(DL_BI,MATCH($CA13,DL_KEY,0)),"M") -> M | AD13: =IFERROR(INDEX(DL_Exp,MATCH($CA13,DL_KEY,0)),"M") -> L | AE13: =IFERROR(INDEX(DL_Edu,MATCH($CA13,DL_KEY,0)),"M") -> L | AF13: M | AG13: M | AH13: M | AI13: M | AJ13: M | AK13: M | AL13: M | AM13: 0.513 | AN13: 0.173 | AO13: 0.097 | AP13: 0.05 | AQ13: 0.07 | AR13: 0.06 | AS13: 0.04 | AT13: 6–10 | AU13: Graduate or postgraduate; professional qualification preferred | AV13: IC: none · People: 6–8 knowledge work, 8–12 standardised delivery | AW13: P4 / M3 · SFIA 4–5 | AX13: S46–S51 Korn Ferry Hay evaluations · S04, S52 Mercer IPE · S53–S57 NHS, UK NJC/PSC, GLPC, SJC, US OPM point-factor plans · S58 McKinsey skills-based hiring · S60 WEF skills-first · S61 EY India 2026 · the Experience / Education split is an IRIS rule · S32 Google, Microsoft, Amazon · S33 Infosys · S35 Accenture India · IRIS experience guide · S01 Aon Radford · S02 Pave · S08 SFIA 9 · S03 Mercer career levels | AY13: B2 | AZ13: Band B · Specialist / Manager · Manager | BA13: Model B2 from the six ratings, the market-derived weights and rules R1–R13 · then No change · already below the manager | BB13: B2 | BC13: The six ratings on the market-average weights of Band B · Specialist / POD Lead score 4.57 → B2 · Hay, Mercer IPE and public plans · experience 16.2 yrs vs the B2 market range 6–10 | BD13: =IF(SUM(BM13,BN13,BO13,BP13,BQ13,BR13,BS13)=0,0,(BM13*BT13+BN13*BU13+BO13*BV13+BP13*BW13+BQ13*BX13+BR13*BY13+BS13*BZ13)/SUM(BM13,BN13,BO13,BP13,BQ13,BR13,BS13)) -> 0 | BE13: =IF(LEFT(AY13,1)="X",AY13,IF(OR(AY13="B+",AY13="C+"),INDEX(LAD_PC,MAX(1,MIN(14,MATCH(AY13,LAD_PC,0)+IF(BD13>=0.5,1,IF(BD13<=-0.5,-1,0))))),INDEX(LAD_STD,MAX(1,MIN(12,MATCH(AY13,LAD_STD,0)+IF(BD13>=0.5,1,IF(BD13<=-0.5,-1,0))))))) -> B2 | BG13: =IF(BF13<>"",BF13,BE13) -> B2 | BH13: =IFERROR(CHOOSE(INDEX(B_RANK,MATCH(BG13,B_LVL,0)),"Band A","Band B","B+ · Player-Coach","Band C","C+ · Player-Coach","Band D","Band E"),"Band X · Consultant") -> Band B | BI13: =IF(BG13=AY13,"• Same",IF(INDEX(B_VAL,MATCH(BG13,B_LVL,0))>INDEX(B_VAL,MATCH(AY13,B_LVL,0)),"▲ Up","▼ Down")) -> • Same | BJ13: =IF(OR($M13="",$M13="—",$M13="Not in this file"),"",IFERROR(INDEX($BG$7:$BG$592,MATCH($M13,$D$7:$D$592,0)),"")) -> B3 | BK13: =IFERROR(IF(BJ13="","—",IF(OR(LEFT(BG13,1)="X",LEFT(BJ13,1)="X"),"—",IF(AND(LEFT(BG13,1)="E",LEFT(BJ13,1)="E"),"Exception · Band E",IF(AND(INDEX(B_VAL,MATCH(BJ13,B_LVL,0))>=7,INDEX(B_RANK,MATCH(BG13,B_LVL,0))>=INDEX(B_RANK,MATCH(BJ13,B_LVL,0))),"⚠ Same band as a head manager",IF(INDEX(B_VAL,MATCH(BG13,B_LVL,0))>=INDEX(B_VAL,MATCH(BJ13,B_LVL,0)),"⚠ At or above the manager's level","OK"))))),"—") -> OK | BM13: =IFERROR(INDEX(LMH_PTS,MATCH(Y13,LMH_KEY,0)),0) -> 9 | BN13: =IFERROR(INDEX(LMH_PTS,MATCH(Z13,LMH_KEY,0)),0) -> 3 | BO13: =IFERROR(INDEX(LMH_PTS,MATCH(AA13,LMH_KEY,0)),0) -> 3 | BP13: =IFERROR(INDEX(LMH_PTS,MATCH(AB13,LMH_KEY,0)),0) -> 1 | BQ13: =IFERROR(INDEX(LMH_PTS,MATCH(AC13,LMH_KEY,0)),0) -> 3 | BR13: =IFERROR(INDEX(LMH_PTS,MATCH(AD13,LMH_KEY,0)),0) -> 1 | BS13: =IFERROR(INDEX(LMH_PTS,MATCH(AE13,LMH_KEY,0)),0) -> 1 | BT13: =IFERROR(INDEX(LMH_STEP,MATCH(AF13,LMH_KEY,0)),0) -> 0 | BU13: =IFERROR(INDEX(LMH_STEP,MATCH(AG13,LMH_KEY,0)),0) -> 0 | BV13: =IFERROR(INDEX(LMH_STEP,MATCH(AH13,LMH_KEY,0)),0) -> 0 | BW13: =IFERROR(INDEX(LMH_STEP,MATCH(AI13,LMH_KEY,0)),0) -> 0 | BX13: =IFERROR(INDEX(LMH_STEP,MATCH(AJ13,LMH_KEY,0)),0) -> 0 | BY13: =IFERROR(INDEX(LMH_STEP,MATCH(AK13,LMH_KEY,0)),0) -> 0 | BZ13: =IFERROR(INDEX(LMH_STEP,MATCH(AL13,LMH_KEY,0)),0) -> 0 | CA13: CARBON|Support|Senior Customer Success Specialist – POD Lead|B2|B-IC
A14: CARBON | B14: Support | C14: 6 | D14: IRISC184 | E14: Tanya Dhere | F14: Consultant | G14: Senior Customer Success Executive | H14: Customer Success & Support | I14: Customer Success & Account Management | J14: IC | K14: RC-034 | L14: Neha Gajbhiye | M14: IRIS1963 | N14: 13 | O14: 6 | P14: B.Com | Q14: L3 – Professional / Associate | R14: A3 | S14: 19 of 20 | T14: • Role / sub-team: PMO Activity, AI Testing. | U14: KRAs not received · manager to supply | V14: Latest rating: 3 · Potential: Low · 9-box: Reliable Specialist · Readiness: Develop in role | W14: C M · Au L · Ac M · L L · BI M · Exp H · 13 yrs vs 2–4 yrs · Edu M · B.Com | X14: Open ▸ | Y14: =IFERROR(INDEX(DL_C,MATCH($CA14,DL_KEY,0)),"M") -> H | Z14: =IFERROR(INDEX(DL_Au,MATCH($CA14,DL_KEY,0)),"M") -> M | AA14: =IFERROR(INDEX(DL_Ac,MATCH($CA14,DL_KEY,0)),"M") -> M | AB14: =IFERROR(INDEX(DL_L,MATCH($CA14,DL_KEY,0)),"M") -> L | AC14: =IFERROR(INDEX(DL_BI,MATCH($CA14,DL_KEY,0)),"M") -> M | AD14: =IFERROR(INDEX(DL_Exp,MATCH($CA14,DL_KEY,0)),"M") -> L | AE14: =IFERROR(INDEX(DL_Edu,MATCH($CA14,DL_KEY,0)),"M") -> L | AF14: M | AG14: M | AH14: M | AI14: M | AJ14: M | AK14: M | AL14: M | AM14: 0.583 | AN14: 0.16 | AO14: 0.09 | AP14: 0 | AQ14: 0.063 | AR14: 0.06 | AS14: 0.04 | AT14: 2–5 | AU14: Graduate; relevant certification preferred | AV14: None · guides 1–3 juniors informally | AW14: P2 · SFIA 3 Apply | AX14: S46–S51 Korn Ferry Hay evaluations · S04, S52 Mercer IPE · S53–S57 NHS, UK NJC/PSC, GLPC, SJC, US OPM point-factor plans · S58 McKinsey skills-based hiring · S60 WEF skills-first · S61 EY India 2026 · the Experience / Education split is an IRIS rule · S32 Google, Microsoft, Amazon · S33 Infosys · S35 Accenture India · IRIS experience guide · S01 Aon Radford · S02 Pave · S08 SFIA 9 · S03 Mercer career levels | AY14: A3 | AZ14: Band A · Practitioner · Senior Associate | BA14: Model A3 from the six ratings, the market-derived weights and rules R1–R13 · then No change · already below the manager | BB14: A3 | BC14: The six ratings on the market-average weights of Band A · all tracks score 2.92 → A3 · Hay, Mercer IPE and public plans · experience 13 yrs vs the A3 market range 2–5 | BD14: =IF(SUM(BM14,BN14,BO14,BP14,BQ14,BR14,BS14)=0,0,(BM14*BT14+BN14*BU14+BO14*BV14+BP14*BW14+BQ14*BX14+BR14*BY14+BS14*BZ14)/SUM(BM14,BN14,BO14,BP14,BQ14,BR14,BS14)) -> 0 | BE14: =IF(LEFT(AY14,1)="X",AY14,IF(OR(AY14="B+",AY14="C+"),INDEX(LAD_PC,MAX(1,MIN(14,MATCH(AY14,LAD_PC,0)+IF(BD14>=0.5,1,IF(BD14<=-0.5,-1,0))))),INDEX(LAD_STD,MAX(1,MIN(12,MATCH(AY14,LAD_STD,0)+IF(BD14>=0.5,1,IF(BD14<=-0.5,-1,0))))))) -> A3 | BG14: =IF(BF14<>"",BF14,BE14) -> A3 | BH14: =IFERROR(CHOOSE(INDEX(B_RANK,MATCH(BG14,B_LVL,0)),"Band A","Band B","B+ · Player-Coach","Band C","C+ · Player-Coach","Band D","Band E"),"Band X · Consultant") -> Band A | BI14: =IF(BG14=AY14,"• Same",IF(INDEX(B_VAL,MATCH(BG14,B_LVL,0))>INDEX(B_VAL,MATCH(AY14,B_LVL,0)),"▲ Up","▼ Down")) -> • Same | BJ14: =IF(OR($M14="",$M14="—",$M14="Not in this file"),"",IFERROR(INDEX($BG$7:$BG$592,MATCH($M14,$D$7:$D$592,0)),"")) -> B2 | BK14: =IFERROR(IF(BJ14="","—",IF(OR(LEFT(BG14,1)="X",LEFT(BJ14,1)="X"),"—",IF(AND(LEFT(BG14,1)="E",LEFT(BJ14,1)="E"),"Exception · Band E",IF(AND(INDEX(B_VAL,MATCH(BJ14,B_LVL,0))>=7,INDEX(B_RANK,MATCH(BG14,B_LVL,0))>=INDEX(B_RANK,MATCH(BJ14,B_LVL,0))),"⚠ Same band as a head manager",IF(INDEX(B_VAL,MATCH(BG14,B_LVL,0))>=INDEX(B_VAL,MATCH(BJ14,B_LVL,0)),"⚠ At or above the manager's level","OK"))))),"—") -> OK | BM14: =IFERROR(INDEX(LMH_PTS,MATCH(Y14,LMH_KEY,0)),0) -> 9 | BN14: =IFERROR(INDEX(LMH_PTS,MATCH(Z14,LMH_KEY,0)),0) -> 3 | BO14: =IFERROR(INDEX(LMH_PTS,MATCH(AA14,LMH_KEY,0)),0) -> 3 | BP14: =IFERROR(INDEX(LMH_PTS,MATCH(AB14,LMH_KEY,0)),0) -> 1 | BQ14: =IFERROR(INDEX(LMH_PTS,MATCH(AC14,LMH_KEY,0)),0) -> 3 | BR14: =IFERROR(INDEX(LMH_PTS,MATCH(AD14,LMH_KEY,0)),0) -> 1 | BS14: =IFERROR(INDEX(LMH_PTS,MATCH(AE14,LMH_KEY,0)),0) -> 1 | BT14: =IFERROR(INDEX(LMH_STEP,MATCH(AF14,LMH_KEY,0)),0) -> 0 | BU14: =IFERROR(INDEX(LMH_STEP,MATCH(AG14,LMH_KEY,0)),0) -> 0 | BV14: =IFERROR(INDEX(LMH_STEP,MATCH(AH14,LMH_KEY,0)),0) -> 0 | BW14: =IFERROR(INDEX(LMH_STEP,MATCH(AI14,LMH_KEY,0)),0) -> 0 | BX14: =IFERROR(INDEX(LMH_STEP,MATCH(AJ14,LMH_KEY,0)),0) -> 0 | BY14: =IFERROR(INDEX(LMH_STEP,MATCH(AK14,LMH_KEY,0)),0) -> 0 | BZ14: =IFERROR(INDEX(LMH_STEP,MATCH(AL14,LMH_KEY,0)),0) -> 0 | CA14: CARBON|Support|Senior Customer Success Executive|A3|A
A15: CARBON | B15: Support | C15: 5 | D15: IRIS1959 | E15: Praveen Kumar Rajpurohit | F15: Manager- Customer Engagement | G15: Senior Customer Success Specialist | H15: Customer Success & Support | I15: Customer Success & Account Management | J15: IC | K15: RC-036 | L15: Anushree Aparajit | M15: IRIS1335 | N15: 14.6 | O15: 5 | P15: MBA | Q15: L5 – Manager | R15: B2 | S15: 20 of 20 | T15: • Role / sub-team: Support — Manager- Customer Engagement. • Core purpose: Managing EU client portfolios to ensure timely ESEF filings, effective use of the Disclosure Management Platform, client retention and renewals, while supporting prospect demos and product feedback. • Decision-making autonomy: Can independently clients query handling. • Is this … | U15: Received · manager annual · Net Revenue Retention ≥100–105% Target ARR - to be achieved: INR 50,00,000 90% reach value milestone in 90 days Develop advocates · Promoter per CEM Produce case studies annually CSAT ≥90% NPS ≥30 100% QBR coverage for accounts 100% CRM hygiene maintained Renewal forecast accuracy ≥95% Outstanding receivables ≤45 … | V15: Latest rating: 3 · Potential: Medium · 9-box: Core Contributor · Readiness: Develop in role | W15: C L · Au L · Ac M · L L · BI M · Exp H · 14.6 yrs vs 6–9 yrs · Edu H · MBA | X15: Open ▸ | Y15: =IFERROR(INDEX(DL_C,MATCH($CA15,DL_KEY,0)),"M") -> H | Z15: =IFERROR(INDEX(DL_Au,MATCH($CA15,DL_KEY,0)),"M") -> M | AA15: =IFERROR(INDEX(DL_Ac,MATCH($CA15,DL_KEY,0)),"M") -> M | AB15: =IFERROR(INDEX(DL_L,MATCH($CA15,DL_KEY,0)),"M") -> L | AC15: =IFERROR(INDEX(DL_BI,MATCH($CA15,DL_KEY,0)),"M") -> M | AD15: =IFERROR(INDEX(DL_Exp,MATCH($CA15,DL_KEY,0)),"M") -> L | AE15: =IFERROR(INDEX(DL_Edu,MATCH($CA15,DL_KEY,0)),"M") -> L | AF15: M | AG15: M | AH15: M | AI15: M | AJ15: M | AK15: M | AL15: M | AM15: 0.513 | AN15: 0.173 | AO15: 0.097 | AP15: 0.05 | AQ15: 0.07 | AR15: 0.06 | AS15: 0.04 | AT15: 6–10 | AU15: Graduate or postgraduate; professional qualification preferred | AV15: IC: none · People: 6–8 knowledge work, 8–12 standardised delivery | AW15: P4 / M3 · SFIA 4–5 | AX15: S46–S51 Korn Ferry Hay evaluations · S04, S52 Mercer IPE · S53–S57 NHS, UK NJC/PSC, GLPC, SJC, US OPM point-factor plans · S58 McKinsey skills-based hiring · S60 WEF skills-first · S61 EY India 2026 · the Experience / Education split is an IRIS rule · S32 Google, Microsoft, Amazon · S33 Infosys · S35 Accenture India · IRIS experience guide · S01 Aon Radford · S02 Pave · S08 SFIA 9 · S03 Mercer career levels | AY15: B2 | AZ15: Band B · Specialist / Manager · Senior Specialist | BA15: Model B2 from the six ratings, the market-derived weights and rules R1–R13 · then No change · already below the manager | BB15: B2 | BC15: The six ratings on the market-average weights of Band B · Specialist / POD Lead score 4.60 → B2 · Hay, Mercer IPE and public plans · experience 14.6 yrs vs the B2 market range 6–10 | BD15: =IF(SUM(BM15,BN15,BO15,BP15,BQ15,BR15,BS15)=0,0,(BM15*BT15+BN15*BU15+BO15*BV15+BP15*BW15+BQ15*BX15+BR15*BY15+BS15*BZ15)/SUM(BM15,BN15,BO15,BP15,BQ15,BR15,BS15)) -> 0 | BE15: =IF(LEFT(AY15,1)="X",AY15,IF(OR(AY15="B+",AY15="C+"),INDEX(LAD_PC,MAX(1,MIN(14,MATCH(AY15,LAD_PC,0)+IF(BD15>=0.5,1,IF(BD15<=-0.5,-1,0))))),INDEX(LAD_STD,MAX(1,MIN(12,MATCH(AY15,LAD_STD,0)+IF(BD15>=0.5,1,IF(BD15<=-0.5,-1,0))))))) -> B2 | BG15: =IF(BF15<>"",BF15,BE15) -> B2 | BH15: =IFERROR(CHOOSE(INDEX(B_RANK,MATCH(BG15,B_LVL,0)),"Band A","Band B","B+ · Player-Coach","Band C","C+ · Player-Coach","Band D","Band E"),"Band X · Consultant") -> Band B | BI15: =IF(BG15=AY15,"• Same",IF(INDEX(B_VAL,MATCH(BG15,B_LVL,0))>INDEX(B_VAL,MATCH(AY15,B_LVL,0)),"▲ Up","▼ Down")) -> • Same | BJ15: =IF(OR($M15="",$M15="—",$M15="Not in this file"),"",IFERROR(INDEX($BG$7:$BG$592,MATCH($M15,$D$7:$D$592,0)),"")) -> B3 | BK15: =IFERROR(IF(BJ15="","—",IF(OR(LEFT(BG15,1)="X",LEFT(BJ15,1)="X"),"—",IF(AND(LEFT(BG15,1)="E",LEFT(BJ15,1)="E"),"Exception · Band E",IF(AND(INDEX(B_VAL,MATCH(BJ15,B_LVL,0))>=7,INDEX(B_RANK,MATCH(BG15,B_LVL,0))>=INDEX(B_RANK,MATCH(BJ15,B_LVL,0))),"⚠ Same band as a head manager",IF(INDEX(B_VAL,MATCH(BG15,B_LVL,0))>=INDEX(B_VAL,MATCH(BJ15,B_LVL,0)),"⚠ At or above the manager's level","OK"))))),"—") -> OK | BM15: =IFERROR(INDEX(LMH_PTS,MATCH(Y15,LMH_KEY,0)),0) -> 9 | BN15: =IFERROR(INDEX(LMH_PTS,MATCH(Z15,LMH_KEY,0)),0) -> 3 | BO15: =IFERROR(INDEX(LMH_PTS,MATCH(AA15,LMH_KEY,0)),0) -> 3 | BP15: =IFERROR(INDEX(LMH_PTS,MATCH(AB15,LMH_KEY,0)),0) -> 1 | BQ15: =IFERROR(INDEX(LMH_PTS,MATCH(AC15,LMH_KEY,0)),0) -> 3 | BR15: =IFERROR(INDEX(LMH_PTS,MATCH(AD15,LMH_KEY,0)),0) -> 1 | BS15: =IFERROR(INDEX(LMH_PTS,MATCH(AE15,LMH_KEY,0)),0) -> 1 | BT15: =IFERROR(INDEX(LMH_STEP,MATCH(AF15,LMH_KEY,0)),0) -> 0 | BU15: =IFERROR(INDEX(LMH_STEP,MATCH(AG15,LMH_KEY,0)),0) -> 0 | BV15: =IFERROR(INDEX(LMH_STEP,MATCH(AH15,LMH_KEY,0)),0) -> 0 | BW15: =IFERROR(INDEX(LMH_STEP,MATCH(AI15,LMH_KEY,0)),0) -> 0 | BX15: =IFERROR(INDEX(LMH_STEP,MATCH(AJ15,LMH_KEY,0)),0) -> 0 | BY15: =IFERROR(INDEX(LMH_STEP,MATCH(AK15,LMH_KEY,0)),0) -> 0 | BZ15: =IFERROR(INDEX(LMH_STEP,MATCH(AL15,LMH_KEY,0)),0) -> 0 | CA15: CARBON|Support|Senior Customer Success Specialist|B2|B-IC
A16: CARBON | B16: Support | C16: 5 | D16: IRIS1967 | E16: Pritam Agarwal | F16: Manager- Customer Engagement | G16: Senior Customer Success Specialist | H16: Customer Success & Support | I16: Customer Success & Account Management | J16: IC | K16: RC-036 | L16: Anushree Aparajit | M16: IRIS1335 | N16: 20.1 | O16: 4.8 | P16: PGDM | Q16: L5 – Manager | R16: B2 | S16: 20 of 20 | T16: • Role / sub-team: Support — Manager- Customer Engagement. • Core purpose: Client communication and Nurturing the client with training and enablement process to work independently. • Decision-making autonomy: Can independently none of the activity. • Is this something only they do: Most of us. • What's different about this role: Geo specific reporting; … | U16: Received · manager annual · "Net Revenue Retention ≥100–105% Target ARR - to be achieved: INR 30,00,000 90% reach value milestone in 90 days Develop advocates · Promoter per CEM Produce case studies annually CSAT ≥90% NPS ≥30 100% QBR coverage for accounts 100% CRM hygiene maintained Renewal forecast accuracy ≥95% Outstanding receivables ≤45 … | V16: Latest rating: 2 · Potential: Medium · 9-box: Core Contributor · Readiness: Performance first | W16: C M · Au M · Ac M · L L · BI M · Exp H · 20.1 yrs vs 6–9 yrs · Edu H · PGDM | X16: Open ▸ | Y16: =IFERROR(INDEX(DL_C,MATCH($CA16,DL_KEY,0)),"M") -> H | Z16: =IFERROR(INDEX(DL_Au,MATCH($CA16,DL_KEY,0)),"M") -> M | AA16: =IFERROR(INDEX(DL_Ac,MATCH($CA16,DL_KEY,0)),"M") -> M | AB16: =IFERROR(INDEX(DL_L,MATCH($CA16,DL_KEY,0)),"M") -> L | AC16: =IFERROR(INDEX(DL_BI,MATCH($CA16,DL_KEY,0)),"M") -> M | AD16: =IFERROR(INDEX(DL_Exp,MATCH($CA16,DL_KEY,0)),"M") -> L | AE16: =IFERROR(INDEX(DL_Edu,MATCH($CA16,DL_KEY,0)),"M") -> L | AF16: M | AG16: M | AH16: M | AI16: M | AJ16: M | AK16: M | AL16: M | AM16: 0.513 | AN16: 0.173 | AO16: 0.097 | AP16: 0.05 | AQ16: 0.07 | AR16: 0.06 | AS16: 0.04 | AT16: 6–10 | AU16: Graduate or postgraduate; professional qualification preferred | AV16: IC: none · People: 6–8 knowledge work, 8–12 standardised delivery | AW16: P4 / M3 · SFIA 4–5 | AX16: S46–S51 Korn Ferry Hay evaluations · S04, S52 Mercer IPE · S53–S57 NHS, UK NJC/PSC, GLPC, SJC, US OPM point-factor plans · S58 McKinsey skills-based hiring · S60 WEF skills-first · S61 EY India 2026 · the Experience / Education split is an IRIS rule · S32 Google, Microsoft, Amazon · S33 Infosys · S35 Accenture India · IRIS experience guide · S01 Aon Radford · S02 Pave · S08 SFIA 9 · S03 Mercer career levels | AY16: B2 | AZ16: Band B · Specialist / Manager · Senior Specialist | BA16: Model B2 from the six ratings, the market-derived weights and rules R1–R13 · then No change · already below the manager | BB16: B2 | BC16: The six ratings on the market-average weights of Band B · Specialist / POD Lead score 5.03 → B2 · Hay, Mercer IPE and public plans · experience 20.1 yrs vs the B2 market range 6–10 | BD16: =IF(SUM(BM16,BN16,BO16,BP16,BQ16,BR16,BS16)=0,0,(BM16*BT16+BN16*BU16+BO16*BV16+BP16*BW16+BQ16*BX16+BR16*BY16+BS16*BZ16)/SUM(BM16,BN16,BO16,BP16,BQ16,BR16,BS16)) -> 0 | BE16: =IF(LEFT(AY16,1)="X",AY16,IF(OR(AY16="B+",AY16="C+"),INDEX(LAD_PC,MAX(1,MIN(14,MATCH(AY16,LAD_PC,0)+IF(BD16>=0.5,1,IF(BD16<=-0.5,-1,0))))),INDEX(LAD_STD,MAX(1,MIN(12,MATCH(AY16,LAD_STD,0)+IF(BD16>=0.5,1,IF(BD16<=-0.5,-1,0))))))) -> B2 | BG16: =IF(BF16<>"",BF16,BE16) -> B2 | BH16: =IFERROR(CHOOSE(INDEX(B_RANK,MATCH(BG16,B_LVL,0)),"Band A","Band B","B+ · Player-Coach","Band C","C+ · Player-Coach","Band D","Band E"),"Band X · Consultant") -> Band B | BI16: =IF(BG16=AY16,"• Same",IF(INDEX(B_VAL,MATCH(BG16,B_LVL,0))>INDEX(B_VAL,MATCH(AY16,B_LVL,0)),"▲ Up","▼ Down")) -> • Same | BJ16: =IF(OR($M16="",$M16="—",$M16="Not in this file"),"",IFERROR(INDEX($BG$7:$BG$592,MATCH($M16,$D$7:$D$592,0)),"")) -> B3 | BK16: =IFERROR(IF(BJ16="","—",IF(OR(LEFT(BG16,1)="X",LEFT(BJ16,1)="X"),"—",IF(AND(LEFT(BG16,1)="E",LEFT(BJ16,1)="E"),"Exception · Band E",IF(AND(INDEX(B_VAL,MATCH(BJ16,B_LVL,0))>=7,INDEX(B_RANK,MATCH(BG16,B_LVL,0))>=INDEX(B_RANK,MATCH(BJ16,B_LVL,0))),"⚠ Same band as a head manager",IF(INDEX(B_VAL,MATCH(BG16,B_LVL,0))>=INDEX(B_VAL,MATCH(BJ16,B_LVL,0)),"⚠ At or above the manager's level","OK"))))),"—") -> OK | BM16: =IFERROR(INDEX(LMH_PTS,MATCH(Y16,LMH_KEY,0)),0) -> 9 | BN16: =IFERROR(INDEX(LMH_PTS,MATCH(Z16,LMH_KEY,0)),0) -> 3 | BO16: =IFERROR(INDEX(LMH_PTS,MATCH(AA16,LMH_KEY,0)),0) -> 3 | BP16: =IFERROR(INDEX(LMH_PTS,MATCH(AB16,LMH_KEY,0)),0) -> 1 | BQ16: =IFERROR(INDEX(LMH_PTS,MATCH(AC16,LMH_KEY,0)),0) -> 3 | BR16: =IFERROR(INDEX(LMH_PTS,MATCH(AD16,LMH_KEY,0)),0) -> 1 | BS16: =IFERROR(INDEX(LMH_PTS,MATCH(AE16,LMH_KEY,0)),0) -> 1 | BT16: =IFERROR(INDEX(LMH_STEP,MATCH(AF16,LMH_KEY,0)),0) -> 0 | BU16: =IFERROR(INDEX(LMH_STEP,MATCH(AG16,LMH_KEY,0)),0) -> 0 | BV16: =IFERROR(INDEX(LMH_STEP,MATCH(AH16,LMH_KEY,0)),0) -> 0 | BW16: =IFERROR(INDEX(LMH_STEP,MATCH(AI16,LMH_KEY,0)),0) -> 0 | BX16: =IFERROR(INDEX(LMH_STEP,MATCH(AJ16,LMH_KEY,0)),0) -> 0 | BY16: =IFERROR(INDEX(LMH_STEP,MATCH(AK16,LMH_KEY,0)),0) -> 0 | BZ16: =IFERROR(INDEX(LMH_STEP,MATCH(AL16,LMH_KEY,0)),0) -> 0 | CA16: CARBON|Support|Senior Customer Success Specialist|B2|B-IC
