Workbook
Name PC_Products: 'Card Lists'!$A$1:$A$1
Name PC_D_1: 'Card Lists'!$B$1:$B$11
Name PC_N_1: 'Card Lists'!$D$1:$D$1
Name PC_I_1: 'Card Lists'!$E$1:$E$1
Name PC_N_2: 'Card Lists'!$D$2:$D$2
Name PC_I_2: 'Card Lists'!$E$2:$E$2
Name PC_N_3: 'Card Lists'!$D$3:$D$3
Name PC_I_3: 'Card Lists'!$E$3:$E$3
Name PC_N_4: 'Card Lists'!$D$4:$D$27
Name PC_I_4: 'Card Lists'!$E$4:$E$27
Name PC_N_5: 'Card Lists'!$D$28:$D$41
Name PC_I_5: 'Card Lists'!$E$28:$E$41
Name PC_N_6: 'Card Lists'!$D$42:$D$72
Name PC_I_6: 'Card Lists'!$E$42:$E$72
Name PC_N_7: 'Card Lists'!$D$73:$D$80
Name PC_I_7: 'Card Lists'!$E$73:$E$80
Name PC_N_8: 'Card Lists'!$D$81:$D$86
Name PC_I_8: 'Card Lists'!$E$81:$E$86
Name PC_N_9: 'Card Lists'!$D$87:$D$146
Name PC_I_9: 'Card Lists'!$E$87:$E$146
Name PC_N_10: 'Card Lists'!$D$147:$D$168
Name PC_I_10: 'Card Lists'!$E$147:$E$168
Name PC_N_11: 'Card Lists'!$D$169:$D$215
Name PC_I_11: 'Card Lists'!$E$169:$E$215
Name PC_Keys: 'Card Lists'!$F$1:$F$11
Name PC_NK: 'Card Lists'!$H$1:$H$215
Name PC_NKIds: 'Card Lists'!$I$1:$I$215
Name PC_NKRow: 'Card Lists'!$J$1:$J$215
Name PC_ProdF: OFFSET('Card Lists'!$M$1,0,0,MAX(1,'Card Lists'!$L$1),1)
Name PC_DeptF: OFFSET('Card Lists'!$O$1,0,0,MAX(1,'Card Lists'!$N$11),1)
Name PC_NameF: OFFSET('Card Lists'!$Q$1,0,0,MAX(1,'Card Lists'!$P$215),1)
Name WM_EXP_AB: '1d. Weightage Matrix'!$B$6
Name WM_EXP_CE: '1d. Weightage Matrix'!$B$7
Name WM_C: '1d. Weightage Matrix'!$N$17:$N$46
Name WM_AU: '1d. Weightage Matrix'!$O$17:$O$46
Name WM_AC: '1d. Weightage Matrix'!$P$17:$P$46
Name WM_L: '1d. Weightage Matrix'!$Q$17:$Q$46
Name WM_E: '1d. Weightage Matrix'!$R$17:$R$46
Name WM_BI: '1d. Weightage Matrix'!$S$17:$S$46
Name WM_KEY: '1d. Weightage Matrix'!$A$17:$A$46

Sheet Start — How It Works
A1: How this exercise works — from a base framework to the final job architecture | E1: ◂ Contents
A2: Read this first: what we did step by step, what is happening now, how the model works, what it produced, the impact — then our framework, the Job Architecture process and the Job Design process. The same page opens every file. The full master for one product: every person, the reasoning, the role catalogue, insights and the career ladder.
A3: IRIS · Job Architecture & Job Design · Final v1.12 · October 2026 · Internal — Confidential
A5: 1. What we did — step by step
A6: # | B6: Step | C6: What we did | D6: What came out of it
A7: 1 | B7: Created a base framework | C7: Built IRIS's job architecture from established market methods — Aon Radford / Mercer career levels, Korn Ferry Hay factors, WTW banding and SFIA — with job families anchored to the ILO occupation standard. | D7: 19 job families, 61 sub-families, a 12-level ladder plus two Player-Coach steps · B+, C+, six factors, individual-contributor and manager tracks
A8: 2 | B8: Designed a survey around it | C8: The 'How We Grow' survey: 20 questions, each tied to the framework's factors — purpose of the role, what it delivers, what it is accountable for, what it can decide, the skills and tools it needs, and learning needs. | D8: One evidence form for every role, so each rating can be traced to an answer
A9: 3 | B9: Conducted 60–65 workshops | C9: Ran 60–65 workshops with teams across the six products and Corporate: explained the framework, walked through the questions and collected answers in the room. | D9: Survey responses from 520 people
A10: 4 | B10: Gathered the data | C10: Combined the survey with the HRIS employee master, KRAs · self and manager-set, the managers' talent mapping · rating, potential, 9-box and the reporting lines. | D10: One record per person — 586 people; KRAs on file for 453
A11: 5 | B11: Cleaned and protected it | C11: Matched responses to people · with consent where needed, removed personal data, and showed survey content only where three or more role-holders answered — never one person's words against a name. | D11: Privacy-safe evidence
A12: 6 | B12: Mapped every role | C12: Placed each person in a job family, a sub-family · the work they actually do and a track. | D12: 267 distinct employee roles; one IRIS-wide role catalogue
A13: 7 | B13: Rated and scored | C13: Rated six factors — Complexity, Autonomy, Accountability, Leadership, Experience & Qualification, Business Impact — on the ladder scale from the evidence; rating × weight = points; points add up to a score; the score points to a level. | D13: A score and an indicated level for 540 employees
A14: 8 | B14: Applied the rules | C14: Gates, limits and Player-Coach steps where the evidence calls for them, and leadership decisions for the top bands — each one written down with its numbers. | D14: A final level and designation for everyone, every move explained
A15: 9 | B15: Benchmarked to the market | C15: Matched every level to Aon Radford / Mercer codes and SFIA, and to competitor, regtech and SaaS ladders; every source re-read and corrected. | D15: A market code and a typical market title for every level
A16: 10 | B16: Built the file set | C16: One build produces every file from the same data, so they always agree: the HR Super Master, product masters and simplified editions, the framework & model master, the calibration panel pack, the ladder master and draft letters. | D16: Files by audience, rebuilt and re-checked in minutes
A17: 11 | B17: Reviewed and corrected | C17: Business-head review, independent reviews, and 100+ automated checks on every build · placements, privacy, formulas, links, counts. | D17: Corrections fed back as validated inputs, never as hand edits
A19: 2. What we are doing now
A20: Now | C20: What happens | D20: Who
A21: Calibration | C21: The panel rates anchor roles blind and compares them with the model; close calls and moves down are decided. | D21: Calibration panel
A22: Decisions and data | C22: Open decisions and critical data requests are worked in the HR Super Master's tracker. | D22: HR, managers, business heads
A23: Business-head review | C23: Each business head marks Agree / Change / Discuss in their simplified edition; responses are imported and tracked. | D23: Business heads
A24: Sign-off | C24: The executive sponsor approves the structure; then the draft letters are issued. | D24: Executive sponsor, HR
A25: Pay · later | C25: Buy one India pay survey and price each level; pay columns stay blank until then. | D25: HR, Finance
A27: 3. How it works — in one minute
A28: Step | C28: In plain words
A29: 1 · A building with 12 floors | C29: IRIS is a building: floor 1 = first job, floor 12 = CEO; two half floors · B+, C+ for player-coaches. Every job lives on one floor.
A30: 2 · Six judges | C30: Six judges look at the job — How hard? Decides alone? Answers for? Leads? Experience? Business impact? — and each holds up a floor number · the rating, using the evidence: survey, KRAs, HRIS, reporting line.
A31: 3 · Some count more | C31: Starting out, the quality of the work counts most; for leaders, results, leading and business impact count most. Experience counts little. All six add to 100%, and leaders can edit them on the Weightage Matrix.
A32: 4 · Add up = the floor | C32: Card × how much it counts = points; add the points = the score; round it = the floor · 5.05 → 5 → B2. Fair-play checks can hold it — each one written down.
A34: The HR Super Master's sheet '1c. Scoring Made Simple' and the Process Explainer tell this story in full, with three worked examples.
A35: 4. What it produced — the output
A36: Output | D36: Count
A37: People mapped · employees + consultants | D37: 586
A38: Job families · sub-families | D38: 19 · 61
A39: Ladder steps in use · employees | D39: 13
A40: Designations on the new ladder · employees | D40: 184
A41: Distinct employee roles | D41: 267
A42: Products and Corporate | D42: 6
A43: People in leadership bands D–E | D43: 11
A45: 5. The impact
...

Sheet Contents
A1: IRIS Job Architecture — CARBON Product Master — contents
A2: Click a sheet name to go there; every sheet has a '◂ Contents' link at the top right to come back.
A3: IRIS · Job Architecture & Job Design · Final v1.12 · October 2026 · Internal — Confidential
A5: # | B5: Sheet | C5: What it holds
A6: 1 | B6: Start — How It Works | C6: Read this first: what we did step by step, what is happening now, how the model works, what it produced, the impact — then our framework, the Job Architecture process and the Job Design process.
A7: 2 | B7: 1. Overview | C7: The whole picture on one page: how many people, families, sub-families and roles; what changed from the old structure; where everyone sits by band, track and department; the Player-Coach transition steps; what each sheet in this workbook is for; and, at the end, how a role's level is worked out.
A8: 3 | B8: 1a. Placements | C8: Who sits where, before → after, the score as built, the six ratings · bars, what set the level and any flag; after a leader edits the Weightage Matrix, the live score is on sheet 2. The full reasoning for one person is on sheet 1b · choose the Emp ID; every column for everyone is on sheet 2. Filter by business, department, family or level with the header arrows.
A9: 4 | B9: 1b. Person Card | C9: Find a person: paste or type an Emp ID, or pick Department → Name from the yellow drop-downs — type part of a word in the Search box beside a drop-down to shorten its list.
A10: 5 | B10: 1d. Weightage Matrix | C10: 1d · Leaders: change the yellow weights. Sheet 2 recalculates points, score and 'Level the score indicates' at once.
A11: 6 | B11: 1e. Weight Benchmark | C11: 1e · The published point-factor plans, how weights shift with seniority, the evidence on experience and on business impact, and IRIS's defaults set against them.
A12: 7 | B12: 2. Talent Mapping | C12: Read left to right: the person → their role before and after → what the role does · responsibilities and competencies required → six ratings × weights = points → the score and the level it points to → any rule that changed the level → why each rating was given · starting point, evidence, market standard → the data used.
A13: 8 | B13: 3. Raw Data & Market Standards | C13: Left: the person and their final role. Middle: the market standard for that role and level.
A14: 9 | B14: 4. Role Competency Framework | C14: For every role · designation × level × track and the sub-family it sits in: the proficiency required in each cluster and exactly what that proficiency looks like — the six core and four future-ready competencies, the leadership expected, the family's must-have and other functional competencies, the department's technical competencies, how to assess them, the credentials, and where today's role-holders stand.
A15: 10 | B15: 5. Capability Framework | C15: The level sizes the role; the capability framework defines what a person in it must be able to do, and how well · proficiency 1–5, aligned to SFIA 9.
A16: 11 | B16: 6. Role Catalogue | C16: One row per catalogue role · job family × sub-family × level × track that someone here holds.
A17: 12 | B17: 7. Role Requirements | C17: One row per role · designation × level × track inside each department, lowest level first.
... A29: 24 | B29: 18. Career Ladder | C29: 215 people in 11 departments. One row per designation at a level in a department, ordered department → band → level · bottom to top: earlier rows are lower levels. 'Same work' = same job family, sub-family and level; overlap within the product is shaded orange, overlap across IRIS blue.

Sheet 1. Overview
A1: Overview — CARBON | O1: ◂ Contents
A2: Sheet 1 · The whole picture on one page: how many people, families, sub-families and roles; what changed from the old structure; where everyone sits by band, track and department; the Player-Coach transition steps; what each sheet in this workbook is for; and, at the end, how a role's level is worked out.
A3: IRIS · Job Architecture & Job Design · Final v1.12 · October 2026 · Internal — Confidential
A5: 1. Headline numbers
A6: People | C6: Departments | E6: Job families | G6: Sub-families | I6: Roles | K6: Ladder steps in use | M6: Player-Coaches
A7: 215 | C7: 11 | E7: 14 | G7: 38 | I7: 92 | K7: 11 | M7: 0
A8: Level up vs current | C8: Level down · protected | E8: Same level | G8: Newly mapped | I8: Close calls / near a gate | K8: Consultants
A9: 131 | C9: 14 | E9: 53 | G9: 17 | I9: 17 / 8 | K9: 2
A10: Job families and sub-families exclude 'Unassigned' · consultants with no role on record. Career levels: 12 levels A1–E2 plus 2 Player-Coach Player-Coach transition steps · B+, C+ = 14; consultants sit outside the ladder at X1–X3. Departments are counted per business line.
A12: 2. What changed — old structure → new structure
A13: Measure | D13: Old · count | F13: New · count | H13: People whose value changed | J13: People unchanged | L13: What it means
A14: Job families | D14: 13 | F14: 14 | H14: 108 | J14: 107 | L14: Families are now disciplines, the same across businesses
A15: Sub-families | D15: 39 | F15: 38 | H15: 208 | J15: 7 | L15: Sub-families now name the actual work done
A16: Designations | D16: 70 | F16: 85 | H16: 189 | J16: 26 | L16: Title = level marker + role noun
A17: Career levels | D17: 9 | F17: 11 | H17: 162 | J17: 53 | L17: New ladder: 12 levels + 2 Player-Coach transition steps; consultants counted separately
A19: 2a. Job families — old → new
A20: Old job family | F20: New job family | K20: People | L20: What happened
A21: Professional Services | F21: Consulting & Professional Services | K21: 57 | L21: Split into several
A22: Engineering & Development | F22: Engineering & Development | K22: 42 | L22: Unchanged; others joined it
A23: Professional Services | F23: Data Operations & Digitization | K23: 23 | L23: Split into several
A24: Sales & Business Development | F24: Sales & Business Development | K24: 21 | L24: Unchanged; part of it moved elsewhere
A25: Customer Success & Support | F25: Customer Success & Support | K25: 17 | L25: Unchanged; others joined it
A26: Marketing & Communications | F26: Marketing & Communications | K26: 13 | L26: Unchanged; part of it moved elsewhere; others joined it
A27: Quality Assurance | F27: Quality Assurance | K27: 8 | L27: Unchanged; part of it moved elsewhere; others joined it
A28: Consulting | F28: Solution Consulting & Implementation | K28: 6 | L28: Split and regrouped
A29: Consulting | F29: Product Management | K29: 5 | L29: Split into several
A30: Business Analysis | F30: Business Analysis | K30: 3 | L30: Unchanged
A31: Executive Leadership | F31: Executive Leadership | K31: 3 | L31: Unchanged
A32: Consulting | F32: Customer Success & Support | K32: 2 | L32: Split and regrouped
... A44: Sales & Business Development | F44: Data & Analytics | K44: 1 | L44: Split into several
A46: 2b. Sub-families — old → new · the 30 largest moves; sheet 10 §2 lists every sub-family
A47: Old sub-family | F47: New sub-family | K47: People | L47: What happened
A48: XBRL / Regulatory Reporting | F48: XBRL Tagging, Conversion & Filing | K48: 52 | L48: Split into several
A49: Digitization & Image Processing | F49: Document Conversion, Formatting & Web Publishing | K49: 22 | L49: Split into several
A50: Sales Development · SDR | F50: Sales Development & Prospecting | K50: 15 | L50: Renamed
A51: Full-Stack Engineering | F51: Backend Development | K51: 9 | L51: Split and regrouped
A52: Customer Success | F52: Customer Success & Account Management | K52: 8 | L52: Split and regrouped
A53: AI / ML Engineering | F53: AI / ML & GenAI Engineering | K53: 7 | L53: Split into several
A54: Customer Success | F54: Application & Product Support | K54: 7 | L54: Split and regrouped
A55: Full-Stack Engineering | F55: Full-Stack Development | K55: 6 | L55: Split and regrouped
...

Sheet 1a. Placements
A1: Placements — one line per person · the slim view | W1: ◂ Contents
A2: Sheet 1a · Who sits where, before → after, the score as built, the six ratings · bars, what set the level and any flag; after a leader edits the Weightage Matrix, the live score is on sheet 2. The full reasoning for one person is on sheet 1b · choose the Emp ID; every column for everyone is on sheet 2. Filter by business, department, family or level with the header arrows.
A3: IRIS · Job Architecture & Job Design · Final v1.12 · October 2026 · Internal — Confidential
A6: Emp ID | B6: Employee name | C6: Business | D6: Department | E6: Job family | F6: Sub-family | G6: Current designation | H6: Final designation | I6: Current level | J6: FINAL LEVEL | K6: Track | L6: Change | M6: Score | N6: Complexity | O6: Autonomy | P6: Accountability | Q6: Leadership | R6: Exp & Qual | S6: Bus. Impact | T6: What set the level | U6: Flags | V6: Confidence
A7: IRIS0391 | B7: Anuradha RK | C7: CARBON | D7: CARBON Business Head | E7: Executive Leadership | F7: Business & Functional Leadership | G7: Business Head | H7: Business Head | I7: Not mapped | J7: D2 | K7: People Manager | L7: Newly mapped | M7: 9.03 | N7: 9 | O7: 9 | P7: 9 | Q7: 9 | R7: 9.5 | S7: 9 | T7: Rule: R11 leadership decision | U7: Input needed | V7: Low
A8: IRIS2478 | B8: Dixit Jasani | C8: CARBON | D8: CRO - Carbon | E8: Executive Leadership | F8: Enterprise Leadership | G8: Chief Revenue Officer- Enterprise Division | H8: Chief Revenue Officer | I8: Not mapped | J8: E1 | K8: People Manager | L8: Newly mapped | M8: 11.05 | N8: 11 | O8: 11 | P8: 11 | Q8: 11 | R8: 12 | S8: 11 | T8: The score decided the level | U8: Input needed | V8: Low
A9: IRIS2359 | B9: Suman Adhikary | C9: CARBON | D9: Customer Experience | E9: Executive Leadership | F9: Business & Functional Leadership | G9: Senior Vice President - Customer Experience | H9: Senior Vice President – Customer Experience | I9: Not mapped | J9: D1 | K9: People Manager | L9: Newly mapped | M9: 10.1 | N9: 10 | O9: 10 | P9: 10 | Q9: 10 | R9: 12 | S9: 10 | T9: Rule: R11 leadership decision | U9: Input needed | V9: Low
A10: IRIS0055 | B10: Vijay Parulekar | C10: CARBON | D10: Digitizing | E10: Data Operations & Digitization | F10: Digitization Leadership | G10: Head Image Processing | H10: Associate Head – Digitization | I10: L7 | J10: C1 | K10: People Manager | L10: Down | M10: 7 | N10: 7 | O10: 7 | P10: 6.5 | Q10: 6 | R10: 11.5 | S10: 7 | T10: The score decided the level | U10: Down — protected | V10: High
A11: IRIS0470 | B11: Janardan Bale | C11: CARBON | D11: Digitizing | E11: Data Operations & Digitization | F11: Document Conversion, Formatting & Web Publishing | G11: Image Processing Specialist | H11: Digitization Manager | I11: L3 | J11: B2 | K11: People Manager | L11: Up | M11: 4.95 | N11: 3.5 | O11: 4.5 | P11: 5 | Q11: 5.5 | R11: 9 | S11: 5.5 | T11: The score decided the level | U11: Input needed | V11: Medium
A12: IRIS1005 | B12: Datta Hatagale | C12: CARBON | D12: Digitizing | E12: Customer Success & Support | F12: Customer Training & Enablement | G12: Image Processing Specialist | H12: Customer Enablement Specialist – POD Lead | I12: L3 | J12: B1 | K12: POD Lead | L12: Up | M12: 3.67 | N12: 3 | O12: 3 | P12: 3.5 | Q12: 3.5 | R12: 8 | S12: 4 | T12: The score decided the level | U12: — | V12: Low
A13: IRIS1204 | B13: Dinesh Sharma | C13: CARBON | D13: Digitizing | E13: Data Operations & Digitization | F13: Document Conversion, Formatting & Web Publishing | G13: Image Processing Specialist | H13: Team Lead – Digitization | I13: L3 | J13: B1 | K13: People Manager | L13: Up | M13: 4.01 | N13: 3 | O13: 3.5 | P13: 3.5 | Q13: 4 | R13: 9 | S13: 4 | T13: The score decided the level | U13: — | V13: Medium
A14: IRIS0117 | B14: Prajakta Mokal | C14: CARBON | D14: Digitizing | E14: Data Operations & Digitization | F14: Document Conversion, Formatting & Web Publishing | G14: Image Processing Specialist | H14: Digitization Specialist – POD Lead | I14: L3 | J14: B1 | K14: POD Lead | L14: Up | M14: 3.69 | N14: 3 | O14: 3 | P14: 3 | Q14: 3 | R14: 9.5 | S14: 3.5 | T14: The score decided the level | U14: — | V14: High
A15: IRIS0171 | B15: Ritesh Yeram | C15: CARBON | D15: Digitizing | E15: Data Operations & Digitization | F15: Document Conversion, Formatting & Web Publishing | G15: Image Processing Specialist | H15: Digitization Specialist – POD Lead | I15: L3 | J15: B1 | K15: POD Lead | L15: Up | M15: 3.74 | N15: 3 | O15: 2.5 | P15: 3.5 | Q15: 3.5 | R15: 9.5 | S15: 4 | T15: The score decided the level | U15: — | V15: Medium
A16: IRIS1210 | B16: Tejas Kat | C16: CARBON | D16: Digitizing | E16: Data Operations & Digitization | F16: Document Conversion, Formatting & Web Publishing | G16: Image Processing Specialist | H16: Digitization Specialist – POD Lead | I16: L3 | J16: B1 | K16: POD Lead | L16: Up | M16: 3.72 | N16: 3 | O16: 3 | P16: 3.5 | Q16: 3.5 | R16: 8.5 | S16: 4 | T16: The score decided the level | U16: — | V16: High
A17: IRISC238 | B17: Aishwarya Chaulkar | C17: CARBON | D17: Digitizing | E17: Data Operations & Digitization | F17: Document Conversion, Formatting & Web Publishing | G17: Consultant | H17: Senior Digitization Associate | I17: L3 | J17: A3 | K17: IC | L17: Up | M17: 2.53 | N17: 2.5 | O17: 2.5 | P17: 2 | Q17: 2 | R17: 3.5 | S17: 2.5 | T17: The score decided the level | U17: Close call · Input needed | V17: Medium
A18: IRISC286 | B18: Bhavesh Gusain | C18: CARBON | D18: Digitizing | E18: Data Operations & Digitization | F18: Document Conversion, Formatting & Web Publishing | G18: Consultant | H18: Senior Digitization Associate | I18: L3 | J18: A3 | K18: IC | L18: Up | M18: 2.13 | N18: 2 | O18: 2 | P18: 2 | Q18: 1 | R18: 3 | S18: 2.5 | T18: Rule: R7 Band A experience | U18: — | V18: Medium
... A75: IRIS2534 | B75: Vishal | C75: CARBON | D75: Marketing | E75: Marketing & Communications | F75: Marketing Operations & Automation | G75: Associate- MarkOps | H75: Marketing Operations Associate | I75: L1 | J75: A2 | K75: IC | L75: Up | M75: 1.95 | N75: 2 | O75: 2 | P75: 2 | Q75: 1 | R75: 1.5 | S75: 2 | T75: The score decided the level | U75: — | V75: High
A76: INTN0287 | B76: Anika Mariam | C76: CARBON | D76: Marketing | E76: Sales & Business Development | F76: Sales Development & Prospecting | G76: Intern | H76: Intern – Sales Development & Prospecting | I76: L1 | J76: A1 | K76: IC | L76: Same level | T76: Placed by rule | U76: — | V76: Medium
A77: INTN0285 | B77: Deblina Chatterjee | C77: CARBON | D77: Marketing | E77: Sales & Business Development | F77: Sales Development & Prospecting | G77: Intern | H77: Intern – Sales Development & Prospecting | I77: L1 | J77: A1 | K77: IC | L77: Same level | T77: Placed by rule | U77: — | V77: Medium
A78: INTN0286 | B78: Samriddhi Kundu | C78: CARBON | D78: Marketing | E78: Sales & Business Development | F78: Sales Development & Prospecting | G78: Intern | H78: Intern – Sales Development & Prospecting | I78: L1 | J78: A1 | K78: IC | L78: Same level | T78: Placed by rule | U78: — | V78: Medium
A79: IRIS0591 | B79: Vinod Katekar | C79: CARBON | D79: Quality Assurance | E79: Quality Assurance | F79: Test Management & QA Leadership | G79: QA-Lead | H79: QA Manager | I79: L5 | J79: B2 | K79: People Manager | L79: Down | M79: 4.84 | N79: 4 | O79: 4.5 | P79: 5 | Q79: 5 | R79: 8.5 | S79: 5 | T79: The score decided the level | U79: Input needed · Down — protected | V79: Medium
A80: IRIS1672 | B80: Brehmjit Gopalkrishnan | C80: CARBON | D80: Quality Assurance | E80: Quality Assurance | F80: Functional & Domain Testing | G80: Client Solutions Executive | H80: Senior QA Engineer | I80: L3 | J80: A3 | K80: IC | L80: Up | M80: 2.75 | N80: 2 | O80: 2 | P80: 2.5 | Q80: 1 | R80: 9 | S80: 2.5 | T80: The score decided the level | U80: — | V80: High
A81: IRIS2388 | B81: Hrishikesh Thombare | C81: CARBON | D81: Quality Assurance | E81: Quality Assurance | F81: Functional & Domain Testing | G81: QA Engineer | H81: Senior QA Engineer | I81: L3 | J81: A3 | K81: IC | L81: Up | M81: 2.15 | N81: 2 | O81: 2 | P81: 2 | Q81: 1 | R81: 3.5 | S81: 2 | T81: Rule: R7 Band A experience | U81: — | V81: Medium
A82: IRIS0625 | B82: Pooja Gawas | C82: CARBON | D82: Quality Assurance | E82: Quality Assurance | F82: Functional & Domain Testing | G82: QA Engineer | H82: Senior QA Engineer | I82: L3 | J82: A3 | K82: IC | L82: Up | M82: 2.78 | N82: 2 | O82: 2 | P82: 3 | Q82: 3 | R82: 8.5 | S82: 3.5 | T82: The score decided the level | U82: Input needed | V82: Medium
A83: IRIS2107 | B83: Pratikkumar Mistry | C83: CARBON | D83: Quality Assurance | E83: Quality Assurance | F83: Functional & Domain Testing | G83: QA Engineer | H83: Senior QA Engineer | I83: L3 | J83: A3 | K83: IC | L83: Up | M83: 2.25 | N83: 2 | O83: 2 | P83: 2 | Q83: 1 | R83: 4.5 | S83: 2 | T83: Rule: R7 Band A experience | U83: — | V83: Medium
A84: IRIS2405 | B84: Tasmiyah Patni | C84: CARBON | D84: Quality Assurance | E84: Quality Assurance | F84: Functional & Domain Testing | G84: QA Engineer | H84: Senior QA Engineer | I84: L3 | J84: A3 | K84: IC | L84: Up | M84: 2.15 | N84: 2 | O84: 2 | P84: 2 | Q84: 1 | R84: 3.5 | S84: 2 | T84: Rule: R7 Band A experience | U84: — | V84: Medium
A85: IRIS2014 | B85: Vishal Panchal | C85: CARBON | D85: Quality Assurance | E85: Quality Assurance | F85: Functional & Domain Testing | G85: QA Engineer | H85: Senior QA Engineer | I85: L3 | J85: A3 | K85: IC | L85: Up | M85: 2.9 | N85: 2.5 | O85: 2.5 | P85: 3.5 | Q85: 3.5 | R85: 5.5 | S85: 3.5 | T85: The score decided the level | U85: Input needed | V85: Low
A86: IRIS2112 | B86: Vitiksha Gamit | C86: CARBON | D86: Quality Assurance | E86: Quality Assurance | F86: Test Automation | G86: QA Automation Engineer | H86: Senior QA Automation Engineer | I86: L3 | J86: A3 | K86: IC | L86: Up | M86: 2.6 | N86: 2.5 | O86: 2.5 | P86: 2.5 | Q86: 1.5 | R86: 3.5 | S86: 2.5 | T86: The score decided the level | U86: — | V86: Medium
A87: IRIS2489 | B87: Sreyash Duragkar | C87: CARBON | D87: Sales | E87: Sales & Business Development | F87: Sales Leadership | G87: Director- Enterprise Sales | H87: Principal – Enterprise Sales | I87: Not mapped | J87: C1 | K87: IC | L87: Newly mapped | M87: 8.72 | N87: 9 | O87: 9 | P87: 9 | Q87: 9 | R87: 3.5 | S87: 9 | T87: Rule: R5 structural gate | U87: Input needed | V87: Low
A88: IRIS1783 | B88: Swapnil Trikane | C88: CARBON | D88: Sales | E88: Sales & Business Development | F88: Sales Leadership | G88: Senior Manager Sales | H88: Lead Account Executive | I88: Not mapped | J88: B3 | K88: IC | L88: Newly mapped | M88: 5.8 | N88: 5.5 | O88: 5.5 | P88: 5.5 | Q88: 4.5 | R88: 9 | S88: 5.5 | T88: The score decided the level | U88: — | V88: Medium
A89: IRIS1734 | B89: Rohit Bansal | C89: CARBON | D89: Sales | E89: Sales & Business Development | F89: Sales Leadership | G89: Senior Manager Sales | H89: Lead Account Executive | I89: Not mapped | J89: B2 | K89: IC | L89: Newly mapped | M89: 5.44 | N89: 5 | O89: 5 | P89: 5.5 | Q89: 4 | R89: 9 | S89: 5.5 | T89: The score decided the level | U89: — | V89: High
A90: IRIS2351 | B90: Aniket Das | C90: CARBON | D90: Sales | E90: Sales & Business Development | F90: Bids, RFP & Sales Operations | G90: Senior Analyst, Strategy and Operations | H90: Sales Operations Specialist – POD Lead | I90: Not mapped | J90: B1 | K90: POD Lead | L90: Newly mapped | M90: 3.55 | N90: 3.5 | O90: 3 | P90: 4 | Q90: 3 | R90: 4.5 | S90: 4 | T90: The score decided the level | U90: — | V90: High
A91: IRIS2308 | B91: Smriti Priya | C91: CARBON | D91: Sales | E91: Sales & Business Development | F91: Bids, RFP & Sales Operations | G91: Senior Analyst, Strategy and Operations | H91: Senior Sales Operations Analyst | I91: L4 | J91: A3 | K91: IC | L91: Same level | M91: 3.1 | N91: 3 | O91: 3 | P91: 3 | Q91: 1.5 | R91: 4 | S91: 3 | T91: The score decided the level | U91: — | V91: High
A92: IRISC345 | B92: Andrea Messiga | C92: CARBON | D92: Sales | E92: Sales & Business Development | F92: Enterprise Sales & Account Management | G92: Regional Manager- Business Development | H92: Senior Consultant – Enterprise Sales & Account Management | I92: Not mapped | J92: X3 | K92: Consultant | L92: Same level | T92: Placed by rule | U92: — | V92: —
A93: IRIS0018 | B93: K Ashok Kumar | C93: CARBON | D93: Services | E93: Consulting & Professional Services | F93: Professional Services Leadership | G93: Manager Financial Analyst | H93: Associate Head – Assisted Services | I93: L5 | J93: C1 | K93: People Manager | L93: Up | M93: 6.81 | N93: 5.5 | O93: 6.5 | P93: 7.5 | Q93: 7.5 | R93: 11 | S93: 8.5 | T93: The score decided the level | U93: Input needed | V93: Medium
A94: IRIS0786 | B94: Shashikant Mudaliar | C94: CARBON | D94: Services | E94: Consulting & Professional Services | F94: Professional Services Leadership | G94: Head - XBRL Assisted Services | H94: Associate Head – XBRL Assisted Services | I94: L7 | J94: C1 | K94: People Manager | L94: Down | M94: 7.14 | N94: 7 | O94: 7 | P94: 7 | Q94: 7 | R94: 9 | S94: 7.5 | T94: The score decided the level | U94: Down — protected | V94: High
A95: IRIS0511 | B95: Jinesh Kumar S | C95: CARBON | D95: Services | E95: Consulting & Professional Services | F95: XBRL Tagging, Conversion & Filing | G95: Lead - Assisted Services | H95: Manager – Assisted Services | I95: L5 | J95: B2 | K95: People Manager | L95: Down | M95: 5.04 | N95: 4 | O95: 4.5 | P95: 5 | Q95: 5 | R95: 9 | S95: 5.5 | T95: The score decided the level | U95: Down — protected | V95: Medium
A96: IRIS0393 | B96: Mayur Zope | C96: CARBON | D96: Services | E96: Consulting & Professional Services | F96: XBRL Tagging, Conversion & Filing | G96: Lead Financial Analyst | H96: Senior Manager – Assisted Services | I96: L5 | J96: B2 | K96: People Manager | L96: Same level | M96: 5.28 | N96: 4 | O96: 5 | P96: 5 | Q96: 5 | R96: 10.5 | S96: 5.5 | T96: The score decided the level | U96: Input needed | V96: High
A97: IRIS0977 | B97: Mohammed Dholkawala | C97: CARBON | D97: Services | E97: Consulting & Professional Services | F97: XBRL Tagging, Conversion & Filing | G97: Lead - Assisted Services | H97: Manager – Assisted Services | I97: L5 | J97: B2 | K97: People Manager | L97: Down | M97: 4.54 | N97: 4 | O97: 4.5 | P97: 4 | Q97: 4 | R97: 8 | S97: 4.5 | T97: The score decided the level | U97: Close call · Down — protected | V97: High
A98: IRIS0589 | B98: Mohammed Sameer Shamsudin | C98: CARBON | D98: Services | E98: Quality Assurance | F98: Functional & Domain Testing | G98: Lead - Assisted Services | H98: Senior QA Specialist – POD Lead | I98: L5 | J98: B2 | K98: POD Lead | L98: Down | M98: 4.57 | N98: 4 | O98: 4.5 | P98: 4 | Q98: 4 | R98: 8.5 | S98: 4.5 | T98: The score decided the level | U98: Down — protected | V98: Low
...

Sheet 1b. Person Card
A1: Person card — one person's placement on one page | I1: ◂ Contents
A2: Sheet 1b · Find a person: paste or type an Emp ID, or pick Department → Name from the yellow drop-downs — type part of a word in the Search box beside a drop-down to shorten its list. Everything below fills in from sheet 2: the role before and after, the six ratings as bars with weights and points, the score and the level, the rules applied, the justification for each rating and the evidence.
A3: IRIS · Job Architecture & Job Design · Final v1.12 · October 2026 · Internal — Confidential
A5: Department | B5: CARBON Business Head | E5: Search ▸ | G5: Showing ▸ | H5: =IFERROR(INDEX('2. Talent Mapping'!$B$7:$B$221,$J$7),"") -> Anuradha RK | J5: CARBON
A6: Name | B6: Anuradha RK | E6: Search ▸ | H6: =IF($J$7="","No match — check the Emp ID" & IF(COUNTA(PC_Products)=1," · this file holds one product only","") & ", or clear it and pick a name",IF(LEFT($J$6,3)="No ",$J$6,"Emp ID "&$J$6)&IF($B$7<>""," · by Emp ID"," · by name")) -> Emp ID IRIS0391 · by name | J6: =IF(TRIM($B$7)<>"",TRIM($B$7),IFERROR(INDEX(PC_NKIds,MATCH($J$5&"|"&$B$5&"|"&$B$6,PC_NK,0)),"")) -> IRIS0391
A7: Emp ID — paste or type | J7: =IFERROR(INDEX(PC_NKRow,MATCH($J$6,PC_NKIds,0)),"") -> 1
A8: Paste or type an Emp ID — any person, any product, upper or lower case — or leave it blank and pick Department → Name. To shorten a drop-down, type part of a word in its Search box first. A typed Emp ID wins — clear it to pick by name.
A10: WHO
A11: Business | C11: CARBON | E11: Department | G11: =IFERROR(INDEX('2. Talent Mapping'!$C$7:$C$221,$J$7),"") -> CARBON Business Head
A12: Reporting manager | C12: =IFERROR(INDEX('2. Talent Mapping'!$D$7:$D$221,$J$7),"") -> Dixit Jasani | E12: Qualification | G12: =IFERROR(INDEX('2. Talent Mapping'!$G$7:$G$221,$J$7),"") -> MBA
A13: Total experience · yrs | C13: =IFERROR(INDEX('2. Talent Mapping'!$E$7:$E$221,$J$7),"") -> 17.1 | E13: Experience at IRIS · yrs | G13: =IFERROR(INDEX('2. Talent Mapping'!$F$7:$F$221,$J$7),"") -> 16.4
A15: ROLE — BEFORE → AFTER
A16: Current designation | C16: =IFERROR(INDEX('2. Talent Mapping'!$H$7:$H$221,$J$7),"") -> Business Head | E16: Final designation | G16: =IFERROR(INDEX('2. Talent Mapping'!$I$7:$I$221,$J$7),"") -> Business Head
A17: Current level | C17: =IFERROR(INDEX('2. Talent Mapping'!$L$7:$L$221,$J$7),"") -> Not in current mapping files | E17: FINAL LEVEL | G17: =IFERROR(INDEX('2. Talent Mapping'!$M$7:$M$221,$J$7),"") -> D2
A18: Level title | C18: =IFERROR(INDEX('2. Talent Mapping'!$N$7:$N$221,$J$7),"") -> Vice President | E18: Band | G18: =IFERROR(INDEX('2. Talent Mapping'!$O$7:$O$221,$J$7),"") -> D
A19: Job family | C19: =IFERROR(INDEX('2. Talent Mapping'!$J$7:$J$221,$J$7),"") -> Executive Leadership | E19: Sub-family | G19: =IFERROR(INDEX('2. Talent Mapping'!$K$7:$K$221,$J$7),"") -> Business & Functional Leadership
A20: Track | C20: =IFERROR(INDEX('2. Talent Mapping'!$P$7:$P$221,$J$7),"") -> People Manager | E20: Change vs current | G20: =IFERROR(INDEX('2. Talent Mapping'!$Q$7:$Q$221,$J$7),"") -> ● Newly mapped
A22: WHAT THEY DO — role, responsibilities & competencies required | B22: =IFERROR(IF(INDEX('2. Talent Mapping'!$R$7:$R$221,$J$7)="","—",INDEX('2. Talent Mapping'!$R$7:$R$221,$J$7)),"") -> WHAT THE ROLE DOES: Owns a business line or enterprise function end to end. At D2: several business lines or an executive-scope enterprise function. KEY RESPONSIBILITIES: Owns a business line or enterprise function end to end; Portfolio-level strategic, financial and regulatory trade-offs; Multi-business results DELIVERS: Multi-business results DECIDES ALONE: Sets direction across business lines SKILLS & KNOWLEDGE · role-holders: Product Management COMPETENCIES REQUIRED — must-have ★: Strategic Thinking & Business Acumen · People Leadership & Mentoring OTHER FUNCTIONAL COMPETENCIES: Stakeholder & Client Management · Product, Platform & Domain Knowledge · Regulatory & BFSI Domain · Communication & Presentation PROFICIENCY NEEDED AT THIS LEVEL: Core 5 · Future-ready 4 · Functional 4 · Leadership 5 CREDENTIALS: MBA / PGDM · preferred at C+ SOURCE: Framework only · fewer than 3 answered — 3 holders, 0 answered the survey; sub-family 0 answered; catalogue RC-091
A23: BUSINESS IMPACT — from survey and data | B23: =IFERROR(IF(INDEX('2. Talent Mapping'!$S$7:$S$221,$J$7)="","—",INDEX('2. Talent Mapping'!$S$7:$S$221,$J$7)),"") -> What the role answers for: Multi-business results. Accountability & Impact rating: 9 of 12 · D1-level impact. Leads 9 direct reports. Manager talent mapping — Latest rating: Not rated · manager · 9-Box Grid placement: Not placed · manager.
A24: BUSINESS IMPACT — from manager / head | B24: =IFERROR(IF(INDEX('2. Talent Mapping'!$T$7:$T$221,$J$7)="","—",INDEX('2. Talent Mapping'!$T$7:$T$221,$J$7)),"") -> —
A25: RECRUITMENT — FIND A REPLACEMENT FOR THIS ROLE
A26: What they do · simple | B26: =IFERROR(IF(INDEX('2. Talent Mapping'!$U$7:$U$221,$J$7)="","—",INDEX('2. Talent Mapping'!$U$7:$U$221,$J$7)),"") -> Business Head in CARBON Business Head · CARBON, D2 — People Manager. The work: Owns a business line or enterprise function end to end. At this level the role owns several business lines or an executive-scope enterprise function. Key responsibilities: Owns a business line or enterprise function end to end; Portfolio-level strategic, financial and regulatory trade-offs; Multi-business results. Leads 9 direct reports.
A27: Hire equivalent · external market | B27: =IFERROR(IF(INDEX('2. Talent Mapping'!$V$7:$V$221,$J$7)="","—",INDEX('2. Talent Mapping'!$V$7:$V$221,$J$7)),"") -> Hire as: Associate Vice President / Business Head — IRIS D2 Vice President · People Manager Market level: E3–E4 · SFIA 7 Set strategy Experience: 18–24 yrs · Education: Postgraduate / professional qualification Team size at this level: 5–8 AVPs / heads Equivalent titles at peers: IRIS Vs Market Benchmark — Aon Radford / Mercer executive codes – E3–E4 SVP · IRIS Vs Competitor Benchmark — regtech / SaaS executive titles – SVP Credentials: MBA / PGDM · preferred at C+ Must already know: Governance, risk and regulatory accountability
A28: Competencies & skill level to hire for | B28: =IFERROR(IF(INDEX('2. Talent Mapping'!$W$7:$W$221,$J$7)="","—",INDEX('2. Talent Mapping'!$W$7:$W$221,$J$7)),"") -> FUNCTIONAL — skill level 4 of 5 · Advanced ★ Strategic Thinking & Business Acumen: Shapes strategy, pricing or investment choices ★ People Leadership & Mentoring: Leads leaders; builds succession • Stakeholder & Client Management: Owns key relationships; resolves escalations • Product, Platform & Domain Knowledge: Recognised product / domain expert; trains others • Regulatory & BFSI Domain: Interprets new regulation; advises clients and product • Communication & Presentation: Presents to senior stakeholders; shapes messaging CORE — skill level 5 of 5 · Expert • Ownership & Accountability: Owns business outcomes; builds a culture of accountability • Problem Solving & Critical Thinking: Frames enterprise-level problems; sets the approach for others • Communication & Collaboration: Represents IRIS externally; builds cross-business partnerships • Client & Quality Focus: Defines client and quality strategy for a business • Learning Agility & Adaptability: Anticipates change; builds a learning organisation • Integrity, Compliance & Information Security: Sets ethical and compliance standards for the business FUTURE-READY — skill level 4 of 5 · Advanced • AI Literacy & Augmentation: Designs AI-enabled processes for a team; sets safe-use practices • Data Literacy & Analytics: Defines metrics and dashboards for a team • Digital Fluency & Automation: Automates team processes; selects tools • Innovation & Continuous Improvement: Leads improvement initiatives for a team LEADERSHIP — skill level 5 of 5 · Expert • Leading & Developing People: Builds the leadership pipeline and culture • Decision Making & Delegation: Makes enterprise / business-line decisions • Strategic & Business Acumen: Sets business strategy and P&L direction • Influence & Change Leadership: Leads enterprise change; influences clients, regulators and partners SKILLS · from role-holders and HRIS: Product Management ★ = must-have for the family. Scale: 1 Awareness · 2 Working · 3 Practitioner · 4 Advanced · 5 Expert.
A29: Interview questions for the perfect fit | B29: =IFERROR(IF(INDEX('2. Talent Mapping'!$X$7:$X$221,$J$7)="","—",INDEX('2. Talent Mapping'!$X$7:$X$221,$J$7)),"") -> Draft — generated from the framework; hiring-manager review pending · HR Super Master, sheet T5. 1. [Strategic Thinking & Business Acumen · level 4] Tell me about recent work that shows this: "Shapes strategy, pricing or investment choices". What exactly did you do, how, and what was the result? Assess with: Case interview. 2. [People Leadership & Mentoring · level 4] Tell me about recent work that shows this: "Leads leaders; builds succession". What exactly did you do, how, and what was the result? Assess with: Behavioural interview. 3. [Stakeholder & Client Management · level 4] Give an example that shows you can do this: "Owns key relationships; resolves escalations". Assess with: Role play / behavioural interview. 4. [Product, Platform & Domain Knowledge · level 4] Give an example that shows you can do this: "Recognised product / domain expert; trains others". Assess with: Scenario interview. 5. [Regulatory & BFSI Domain · level 4] Give an example that shows you can do this: "Interprets new regulation; advises clients and product". Assess with: Domain interview. 6. [Ownership & Accountability · level 5] Describe a time you held a team to a standard on an outcome that mattered to the business. How did you make ownership stick? Listen for: "Owns business outcomes; builds a culture of accountability". 7. [Problem Solving & Critical Thinking · level 5] Tell me about an ambiguous, high-stakes problem with no clear answer. How did you frame it and decide? Listen for: "Frames enterprise-level problems; sets the approach for others". 8. [Client & Quality Focus · level 5] Describe how you raised quality or client outcomes across a team or service. How did you measure it? Listen for: "Defines client and quality strategy for a business". 9. [AI Literacy & Augmentation · level 4] Where have you introduced AI or automation into a team's work, and how did you manage the risks? Listen for: "Designs AI-enabled processes for a team; sets safe-use practices". 10. [Leading & Developing People · level 5] Tell me about building a team: who you hired, how you developed them, and a difficult people decision you made. Listen for: "Builds the leadership pipeline and culture". 11. [Decision Making & Delegation · level 5] Tell me about a decision you delegated and one you kept. Why, and what happened? Listen for: "Makes enterprise / business-line decisions". 12. [Strategic & Business Acumen · level 5] Tell me about a strategy or plan you shaped. What trade-offs did you make, and what was the business result? Listen for: "Sets business strategy and P&L direction". 13. [Influence & Change Leadership · level 5] Describe a change you led across teams or the business. How did you deal with resistance? Listen for: "Leads enterprise change; influences clients, regulators and partners". Fit check: Why this role, why IRIS · regulatory reporting / XBRL / regtech, and what would you change in your first 90 days?
A30: HOW THE LEVEL IS WORKED OUT
A31: Factor | B31: Rating | C31: Bar | E31: Weight | F31: Points
A32: Complexity & Expertise | B32: =IFERROR(INDEX('2. Talent Mapping'!$Z$7:$Z$221,$J$7),"") -> 9 | C32: =IF(B32="","",REPT("█",ROUND(B32,0))&REPT("░",12-ROUND(B32,0))) -> █████████░░░ | E32: =IFERROR(INDEX('2. Talent Mapping'!$AA$7:$AA$221,$J$7),"") -> 0.37 | F32: =IF(OR(B32="",E32=""),"",B32*E32) -> 3.33
A33: Autonomy & Decision | B33: =IFERROR(INDEX('2. Talent Mapping'!$AC$7:$AC$221,$J$7),"") -> 9 | C33: =IF(B33="","",REPT("█",ROUND(B33,0))&REPT("░",12-ROUND(B33,0))) -> █████████░░░ | E33: =IFERROR(INDEX('2. Talent Mapping'!$AD$7:$AD$221,$J$7),"") -> 0.19 | F33: =IF(OR(B33="",E33=""),"",B33*E33) -> 1.71
A34: Accountability & Impact | B34: =IFERROR(INDEX('2. Talent Mapping'!$AF$7:$AF$221,$J$7),"") -> 9 | C34: =IF(B34="","",REPT("█",ROUND(B34,0))&REPT("░",12-ROUND(B34,0))) -> █████████░░░ | E34: =IFERROR(INDEX('2. Talent Mapping'!$AG$7:$AG$221,$J$7),"") -> 0.11 | F34: =IF(OR(B34="",E34=""),"",B34*E34) -> 0.99
A35: Leadership & Strategy | B35: =IFERROR(INDEX('2. Talent Mapping'!$AI$7:$AI$221,$J$7),"") -> 9 | C35: =IF(B35="","",REPT("█",ROUND(B35,0))&REPT("░",12-ROUND(B35,0))) -> █████████░░░ | E35: =IFERROR(INDEX('2. Talent Mapping'!$AJ$7:$AJ$221,$J$7),"") -> 0.2 | F35: =IF(OR(B35="",E35=""),"",B35*E35) -> 1.8
A36: Experience & Qualification | B36: =IFERROR(INDEX('2. Talent Mapping'!$AL$7:$AL$221,$J$7),"") -> 9.5 | C36: =IF(B36="","",REPT("█",ROUND(B36,0))&REPT("░",12-ROUND(B36,0))) -> ██████████░░ | E36: =IFERROR(INDEX('2. Talent Mapping'!$AM$7:$AM$221,$J$7),"") -> 0.05 | F36: =IF(OR(B36="",E36=""),"",B36*E36) -> 0.475
A37: Business Impact | B37: =IFERROR(INDEX('2. Talent Mapping'!$AO$7:$AO$221,$J$7),"") -> 9 | C37: =IF(B37="","",REPT("█",ROUND(B37,0))&REPT("░",12-ROUND(B37,0))) -> █████████░░░ | E37: =IFERROR(INDEX('2. Talent Mapping'!$AP$7:$AP$221,$J$7),"") -> 0.08 | F37: =IF(OR(B37="",E37=""),"",B37*E37) -> 0.72
A38: Weighted score | F38: =IF(COUNT(F32:F37)=6,SUM(F32:F37),"Placed by rule") -> 9.025
A39: Level the score indicates | F39: =IFERROR(INDEX('2. Talent Mapping'!$AS$7:$AS$221,$J$7),"") -> D1
A40: FINAL LEVEL | F40: =IFERROR(INDEX('2. Talent Mapping'!$M$7:$M$221,$J$7),"") -> D2
A42: Why these weights | B42: =IFERROR(IF(INDEX('2. Talent Mapping'!$AT$7:$AT$221,$J$7)="","—",INDEX('2. Talent Mapping'!$AT$7:$AT$221,$J$7)),"") -> Weights: Complexity 37% · Leadership 20% · Autonomy 19% · Accountability 11% · Business impact 8% · Experience 5% Why: leaders are judged on the hardest problems, on leading — 20% — and on the decisions, scope and business impact of the job. Type of work in the department: no adjustment at this level. Live: change the department's row on the Weightage Matrix and these weights, the points and the score update.
A43: Calculation | B43: =IFERROR(IF(INDEX('2. Talent Mapping'!$AU$7:$AU$221,$J$7)="","—",INDEX('2. Talent Mapping'!$AU$7:$AU$221,$J$7)),"") -> At build: Complexity 3.33 + Autonomy 1.71 + Accountability 0.99 + Leadership 1.80 + Experience 0.48 + Business impact 0.72 = 9.03 points → nearest level 9 = D1 Final level: D2 · a rule applied: see the next column
A44: Rules applied — with the numbers | B44: =IFERROR(IF(INDEX('2. Talent Mapping'!$AV$7:$AV$221,$J$7)="","—",INDEX('2. Talent Mapping'!$AV$7:$AV$221,$J$7)),"") -> • Set at D2 by leadership decision · the model indicated D1: Leadership structure: CARBON Business Head at D2. Final level: D2.
A45: JUSTIFICATION FOR EACH RATING
...

Sheet 1d. Weightage Matrix
A1: Weightage Matrix — how much each factor counts, by department and role group · editable | U1: ◂ Contents
A2: 1d · Leaders: change the yellow weights. Sheet 2 recalculates points, score and 'Level the score indicates' at once. Below the matrix: what each factor means, what a weight means, and what each rating means.
A3: IRIS · Job Architecture & Job Design · Final v1.12 · October 2026 · Internal — Confidential
A5: SETTINGS — Experience & Qualification weight · kept low by design; change it here for everyone
A6: Experience & Qualification weight — Bands A–B | B6: 10 | C6: Band A, Band B and B+ · Corporate functions rows add 5 for professional qualifications
A7: Experience & Qualification weight — Bands C–E | B7: 5 | C7: Band C, C+ and Bands D–E · Corporate functions rows add 5 for professional qualifications
A8: Why it is low: Sources: S05, S49 Hay know-how includes experience however acquired · S04, S52 Mercer IPE knowledge · S07 WTW GGS · S58 McKinsey · S59 Deloitte · S60 WEF · S61 EY India, 2026 — skills over tenure. The 10% / 5% level is an IRIS leadership decision.
A10: HOW TO USE IT — in four steps
A11: 1. Find your department and role group in the matrix below · filter the Department column.
A12: 2. Change the yellow weights in steps of 5%. Each row should add up to about 100% — the 'Used' columns show the weights actually applied.
A13: 3. Look at sheet 2: points, the score and 'Level the score indicates' have already changed for everyone in that department and role group.
A14: 4. Write why you changed a row in the last column and send the file back; HR imports it and the final levels follow on the next run.
A15: THE MATRIX — one row per department × role group in this file
A16: Weight row | B16: Business | C16: Department | D16: Role group | E16: People | F16: Main type of work | G16: How hard % | H16: Decides alone % | I16: Answers for % | J16: Leads % | K16: Experience % | L16: Business impact % | M16: Entered total | N16: Used · How hard | O16: Used · Decides alone | P16: Used · Answers for | Q16: Used · Leads | R16: Used · Experience | S16: Used · Business impact | T16: Why changed · leader | U16: Default · How hard | V16: Default · Decides alone | W16: Default · Answers for | X16: Default · Leads | Y16: Default · Experience | Z16: Default · Business impact
A17: CARBON · CARBON Business Head · Bands D–E · Leadership | B17: CARBON | C17: CARBON Business Head | D17: Bands D–E · Leadership | E17: 1 | F17: General management | G17: 37 | H17: 19 | I17: 11 | J17: 20 | K17: =WM_EXP_CE -> 5 | L17: 8 | M17: =SUM(G17:L17) -> 100 | N17: =IF((G17+H17+I17+J17+L17)=0,0,G17*(100-MAX(0,MIN(100,K17)))/(G17+H17+I17+J17+L17))/100 -> 0.37 | O17: =IF((G17+H17+I17+J17+L17)=0,0,H17*(100-MAX(0,MIN(100,K17)))/(G17+H17+I17+J17+L17))/100 -> 0.19 | P17: =IF((G17+H17+I17+J17+L17)=0,0,I17*(100-MAX(0,MIN(100,K17)))/(G17+H17+I17+J17+L17))/100 -> 0.11 | Q17: =IF((G17+H17+I17+J17+L17)=0,0,J17*(100-MAX(0,MIN(100,K17)))/(G17+H17+I17+J17+L17))/100 -> 0.2 | R17: =MAX(0,MIN(100,K17))/100 -> 0.05 | S17: =IF((G17+H17+I17+J17+L17)=0,0,L17*(100-MAX(0,MIN(100,K17)))/(G17+H17+I17+J17+L17))/100 -> 0.08 | U17: 37 | V17: 19 | W17: 11 | X17: 20 | Y17: 5 | Z17: 8
A18: CARBON · CRO - Carbon · Bands D–E · Leadership | B18: CARBON | C18: CRO - Carbon | D18: Bands D–E · Leadership | E18: 1 | F18: Sales & marketing | G18: 37 | H18: 19 | I18: 11 | J18: 20 | K18: =WM_EXP_CE -> 5 | L18: 8 | M18: =SUM(G18:L18) -> 100 | N18: =IF((G18+H18+I18+J18+L18)=0,0,G18*(100-MAX(0,MIN(100,K18)))/(G18+H18+I18+J18+L18))/100 -> 0.37 | O18: =IF((G18+H18+I18+J18+L18)=0,0,H18*(100-MAX(0,MIN(100,K18)))/(G18+H18+I18+J18+L18))/100 -> 0.19 | P18: =IF((G18+H18+I18+J18+L18)=0,0,I18*(100-MAX(0,MIN(100,K18)))/(G18+H18+I18+J18+L18))/100 -> 0.11 | Q18: =IF((G18+H18+I18+J18+L18)=0,0,J18*(100-MAX(0,MIN(100,K18)))/(G18+H18+I18+J18+L18))/100 -> 0.2 | R18: =MAX(0,MIN(100,K18))/100 -> 0.05 | S18: =IF((G18+H18+I18+J18+L18)=0,0,L18*(100-MAX(0,MIN(100,K18)))/(G18+H18+I18+J18+L18))/100 -> 0.08 | U18: 37 | V18: 19 | W18: 11 | X18: 20 | Y18: 5 | Z18: 8
A19: CARBON · Customer Experience · Bands D–E · Leadership | B19: CARBON | C19: Customer Experience | D19: Bands D–E · Leadership | E19: 1 | F19: Customer support & success | G19: 37 | H19: 19 | I19: 11 | J19: 20 | K19: =WM_EXP_CE -> 5 | L19: 8 | M19: =SUM(G19:L19) -> 100 | N19: =IF((G19+H19+I19+J19+L19)=0,0,G19*(100-MAX(0,MIN(100,K19)))/(G19+H19+I19+J19+L19))/100 -> 0.37 | O19: =IF((G19+H19+I19+J19+L19)=0,0,H19*(100-MAX(0,MIN(100,K19)))/(G19+H19+I19+J19+L19))/100 -> 0.19 | P19: =IF((G19+H19+I19+J19+L19)=0,0,I19*(100-MAX(0,MIN(100,K19)))/(G19+H19+I19+J19+L19))/100 -> 0.11 | Q19: =IF((G19+H19+I19+J19+L19)=0,0,J19*(100-MAX(0,MIN(100,K19)))/(G19+H19+I19+J19+L19))/100 -> 0.2 | R19: =MAX(0,MIN(100,K19))/100 -> 0.05 | S19: =IF((G19+H19+I19+J19+L19)=0,0,L19*(100-MAX(0,MIN(100,K19)))/(G19+H19+I19+J19+L19))/100 -> 0.08 | U19: 37 | V19: 19 | W19: 11 | X19: 20 | Y19: 5 | Z19: 8
A20: CARBON · Digitizing · Band A · Early career | B20: CARBON | C20: Digitizing | D20: Band A · Early career | E20: 17 | F20: Service delivery & data operations | G20: 54 | H20: 16 | I20: 14 | J20: 0 | K20: =WM_EXP_AB -> 10 | L20: 6 | M20: =SUM(G20:L20) -> 100 | N20: =IF((G20+H20+I20+J20+L20)=0,0,G20*(100-MAX(0,MIN(100,K20)))/(G20+H20+I20+J20+L20))/100 -> 0.54 | O20: =IF((G20+H20+I20+J20+L20)=0,0,H20*(100-MAX(0,MIN(100,K20)))/(G20+H20+I20+J20+L20))/100 -> 0.16 | P20: =IF((G20+H20+I20+J20+L20)=0,0,I20*(100-MAX(0,MIN(100,K20)))/(G20+H20+I20+J20+L20))/100 -> 0.14 | Q20: =IF((G20+H20+I20+J20+L20)=0,0,J20*(100-MAX(0,MIN(100,K20)))/(G20+H20+I20+J20+L20))/100 -> 0 | R20: =MAX(0,MIN(100,K20))/100 -> 0.1 | S20: =IF((G20+H20+I20+J20+L20)=0,0,L20*(100-MAX(0,MIN(100,K20)))/(G20+H20+I20+J20+L20))/100 -> 0.06 | U20: 54 | V20: 16 | W20: 14 | X20: 0 | Y20: 10 | Z20: 6
A21: CARBON · Digitizing · Band B · Expert / POD Lead | B21: CARBON | C21: Digitizing | D21: Band B · Expert / POD Lead | E21: 4 | F21: Service delivery & data operations | G21: 46 | H21: 17 | I21: 15 | J21: 5 | K21: =WM_EXP_AB -> 10 | L21: 7 | M21: =SUM(G21:L21) -> 100 | N21: =IF((G21+H21+I21+J21+L21)=0,0,G21*(100-MAX(0,MIN(100,K21)))/(G21+H21+I21+J21+L21))/100 -> 0.46 | O21: =IF((G21+H21+I21+J21+L21)=0,0,H21*(100-MAX(0,MIN(100,K21)))/(G21+H21+I21+J21+L21))/100 -> 0.17 | P21: =IF((G21+H21+I21+J21+L21)=0,0,I21*(100-MAX(0,MIN(100,K21)))/(G21+H21+I21+J21+L21))/100 -> 0.15 | Q21: =IF((G21+H21+I21+J21+L21)=0,0,J21*(100-MAX(0,MIN(100,K21)))/(G21+H21+I21+J21+L21))/100 -> 0.05 | R21: =MAX(0,MIN(100,K21))/100 -> 0.1 | S21: =IF((G21+H21+I21+J21+L21)=0,0,L21*(100-MAX(0,MIN(100,K21)))/(G21+H21+I21+J21+L21))/100 -> 0.07 | U21: 46 | V21: 17 | W21: 15 | X21: 5 | Y21: 10 | Z21: 7
A22: CARBON · Digitizing · Band B · People Manager | B22: CARBON | C22: Digitizing | D22: Band B · People Manager | E22: 2 | F22: Service delivery & data operations | G22: 32 | H22: 18 | I22: 16 | J22: 15 | K22: =WM_EXP_AB -> 10 | L22: 9 | M22: =SUM(G22:L22) -> 100 | N22: =IF((G22+H22+I22+J22+L22)=0,0,G22*(100-MAX(0,MIN(100,K22)))/(G22+H22+I22+J22+L22))/100 -> 0.32 | O22: =IF((G22+H22+I22+J22+L22)=0,0,H22*(100-MAX(0,MIN(100,K22)))/(G22+H22+I22+J22+L22))/100 -> 0.18 | P22: =IF((G22+H22+I22+J22+L22)=0,0,I22*(100-MAX(0,MIN(100,K22)))/(G22+H22+I22+J22+L22))/100 -> 0.16 | Q22: =IF((G22+H22+I22+J22+L22)=0,0,J22*(100-MAX(0,MIN(100,K22)))/(G22+H22+I22+J22+L22))/100 -> 0.15 | R22: =MAX(0,MIN(100,K22))/100 -> 0.1 | S22: =IF((G22+H22+I22+J22+L22)=0,0,L22*(100-MAX(0,MIN(100,K22)))/(G22+H22+I22+J22+L22))/100 -> 0.09 | U22: 32 | V22: 18 | W22: 16 | X22: 15 | Y22: 10 | Z22: 9
A23: CARBON · Digitizing · Band C · Head / Manager | B23: CARBON | C23: Digitizing | D23: Band C · Head / Manager | E23: 1 | F23: Service delivery & data operations | G23: 38 | H23: 18 | I23: 16 | J23: 15 | K23: =WM_EXP_CE -> 5 | L23: 8 | M23: =SUM(G23:L23) -> 100 | N23: =IF((G23+H23+I23+J23+L23)=0,0,G23*(100-MAX(0,MIN(100,K23)))/(G23+H23+I23+J23+L23))/100 -> 0.38 | O23: =IF((G23+H23+I23+J23+L23)=0,0,H23*(100-MAX(0,MIN(100,K23)))/(G23+H23+I23+J23+L23))/100 -> 0.18 | P23: =IF((G23+H23+I23+J23+L23)=0,0,I23*(100-MAX(0,MIN(100,K23)))/(G23+H23+I23+J23+L23))/100 -> 0.16 | Q23: =IF((G23+H23+I23+J23+L23)=0,0,J23*(100-MAX(0,MIN(100,K23)))/(G23+H23+I23+J23+L23))/100 -> 0.15 | R23: =MAX(0,MIN(100,K23))/100 -> 0.05 | S23: =IF((G23+H23+I23+J23+L23)=0,0,L23*(100-MAX(0,MIN(100,K23)))/(G23+H23+I23+J23+L23))/100 -> 0.08 | U23: 38 | V23: 18 | W23: 16 | X23: 15 | Y23: 5 | Z23: 8
A24: CARBON · Functional · Band A · Early career | B24: CARBON | C24: Functional | D24: Band A · Early career | E24: 2 | F24: Regulatory & domain consulting | G24: 59 | H24: 16 | I24: 9 | J24: 0 | K24: =WM_EXP_AB -> 10 | L24: 6 | M24: =SUM(G24:L24) -> 100 | N24: =IF((G24+H24+I24+J24+L24)=0,0,G24*(100-MAX(0,MIN(100,K24)))/(G24+H24+I24+J24+L24))/100 -> 0.59 | O24: =IF((G24+H24+I24+J24+L24)=0,0,H24*(100-MAX(0,MIN(100,K24)))/(G24+H24+I24+J24+L24))/100 -> 0.16 | P24: =IF((G24+H24+I24+J24+L24)=0,0,I24*(100-MAX(0,MIN(100,K24)))/(G24+H24+I24+J24+L24))/100 -> 0.09 | Q24: =IF((G24+H24+I24+J24+L24)=0,0,J24*(100-MAX(0,MIN(100,K24)))/(G24+H24+I24+J24+L24))/100 -> 0 | R24: =MAX(0,MIN(100,K24))/100 -> 0.1 | S24: =IF((G24+H24+I24+J24+L24)=0,0,L24*(100-MAX(0,MIN(100,K24)))/(G24+H24+I24+J24+L24))/100 -> 0.06 | U24: 59 | V24: 16 | W24: 9 | X24: 0 | Y24: 10 | Z24: 6
A25: CARBON · Functional · Band B · Expert / POD Lead | B25: CARBON | C25: Functional | D25: Band B · Expert / POD Lead | E25: 11 | F25: Regulatory & domain consulting | G25: 51 | H25: 17 | I25: 10 | J25: 5 | K25: =WM_EXP_AB -> 10 | L25: 7 | M25: =SUM(G25:L25) -> 100 | N25: =IF((G25+H25+I25+J25+L25)=0,0,G25*(100-MAX(0,MIN(100,K25)))/(G25+H25+I25+J25+L25))/100 -> 0.51 | O25: =IF((G25+H25+I25+J25+L25)=0,0,H25*(100-MAX(0,MIN(100,K25)))/(G25+H25+I25+J25+L25))/100 -> 0.17 | P25: =IF((G25+H25+I25+J25+L25)=0,0,I25*(100-MAX(0,MIN(100,K25)))/(G25+H25+I25+J25+L25))/100 -> 0.1 | Q25: =IF((G25+H25+I25+J25+L25)=0,0,J25*(100-MAX(0,MIN(100,K25)))/(G25+H25+I25+J25+L25))/100 -> 0.05 | R25: =MAX(0,MIN(100,K25))/100 -> 0.1 | S25: =IF((G25+H25+I25+J25+L25)=0,0,L25*(100-MAX(0,MIN(100,K25)))/(G25+H25+I25+J25+L25))/100 -> 0.07 | U25: 51 | V25: 17 | W25: 10 | X25: 5 | Y25: 10 | Z25: 7
A26: CARBON · Functional · Band B · People Manager | B26: CARBON | C26: Functional | D26: Band B · People Manager | E26: 1 | F26: Regulatory & domain consulting | G26: 37 | H26: 18 | I26: 11 | J26: 15 | K26: =WM_EXP_AB -> 10 | L26: 9 | M26: =SUM(G26:L26) -> 100 | N26: =IF((G26+H26+I26+J26+L26)=0,0,G26*(100-MAX(0,MIN(100,K26)))/(G26+H26+I26+J26+L26))/100 -> 0.37 | O26: =IF((G26+H26+I26+J26+L26)=0,0,H26*(100-MAX(0,MIN(100,K26)))/(G26+H26+I26+J26+L26))/100 -> 0.18 | P26: =IF((G26+H26+I26+J26+L26)=0,0,I26*(100-MAX(0,MIN(100,K26)))/(G26+H26+I26+J26+L26))/100 -> 0.11 | Q26: =IF((G26+H26+I26+J26+L26)=0,0,J26*(100-MAX(0,MIN(100,K26)))/(G26+H26+I26+J26+L26))/100 -> 0.15 | R26: =MAX(0,MIN(100,K26))/100 -> 0.1 | S26: =IF((G26+H26+I26+J26+L26)=0,0,L26*(100-MAX(0,MIN(100,K26)))/(G26+H26+I26+J26+L26))/100 -> 0.09 | U26: 37 | V26: 18 | W26: 11 | X26: 15 | Y26: 10 | Z26: 9
A27: CARBON · Marketing · Band A · Early career | B27: CARBON | C27: Marketing | D27: Band A · Early career | E27: 20 | F27: Sales & marketing | G27: 54 | H27: 21 | I27: 4 | J27: 0 | K27: =WM_EXP_AB -> 10 | L27: 11 | M27: =SUM(G27:L27) -> 100 | N27: =IF((G27+H27+I27+J27+L27)=0,0,G27*(100-MAX(0,MIN(100,K27)))/(G27+H27+I27+J27+L27))/100 -> 0.54 | O27: =IF((G27+H27+I27+J27+L27)=0,0,H27*(100-MAX(0,MIN(100,K27)))/(G27+H27+I27+J27+L27))/100 -> 0.21 | P27: =IF((G27+H27+I27+J27+L27)=0,0,I27*(100-MAX(0,MIN(100,K27)))/(G27+H27+I27+J27+L27))/100 -> 0.04 | Q27: =IF((G27+H27+I27+J27+L27)=0,0,J27*(100-MAX(0,MIN(100,K27)))/(G27+H27+I27+J27+L27))/100 -> 0 | R27: =MAX(0,MIN(100,K27))/100 -> 0.1 | S27: =IF((G27+H27+I27+J27+L27)=0,0,L27*(100-MAX(0,MIN(100,K27)))/(G27+H27+I27+J27+L27))/100 -> 0.11 | U27: 54 | V27: 21 | W27: 4 | X27: 0 | Y27: 10 | Z27: 11
A28: CARBON · Marketing · Band B · Expert / POD Lead | B28: CARBON | C28: Marketing | D28: Band B · Expert / POD Lead | E28: 4 | F28: Sales & marketing | G28: 46 | H28: 22 | I28: 5 | J28: 5 | K28: =WM_EXP_AB -> 10 | L28: 12 | M28: =SUM(G28:L28) -> 100 | N28: =IF((G28+H28+I28+J28+L28)=0,0,G28*(100-MAX(0,MIN(100,K28)))/(G28+H28+I28+J28+L28))/100 -> 0.46 | O28: =IF((G28+H28+I28+J28+L28)=0,0,H28*(100-MAX(0,MIN(100,K28)))/(G28+H28+I28+J28+L28))/100 -> 0.22 | P28: =IF((G28+H28+I28+J28+L28)=0,0,I28*(100-MAX(0,MIN(100,K28)))/(G28+H28+I28+J28+L28))/100 -> 0.05 | Q28: =IF((G28+H28+I28+J28+L28)=0,0,J28*(100-MAX(0,MIN(100,K28)))/(G28+H28+I28+J28+L28))/100 -> 0.05 | R28: =MAX(0,MIN(100,K28))/100 -> 0.1 | S28: =IF((G28+H28+I28+J28+L28)=0,0,L28*(100-MAX(0,MIN(100,K28)))/(G28+H28+I28+J28+L28))/100 -> 0.12 | U28: 46 | V28: 22 | W28: 5 | X28: 5 | Y28: 10 | Z28: 12
A29: CARBON · Marketing · Band B · People Manager | B29: CARBON | C29: Marketing | D29: Band B · People Manager | E29: 4 | F29: Sales & marketing | G29: 32 | H29: 23 | I29: 6 | J29: 15 | K29: =WM_EXP_AB -> 10 | L29: 14 | M29: =SUM(G29:L29) -> 100 | N29: =IF((G29+H29+I29+J29+L29)=0,0,G29*(100-MAX(0,MIN(100,K29)))/(G29+H29+I29+J29+L29))/100 -> 0.32 | O29: =IF((G29+H29+I29+J29+L29)=0,0,H29*(100-MAX(0,MIN(100,K29)))/(G29+H29+I29+J29+L29))/100 -> 0.23 | P29: =IF((G29+H29+I29+J29+L29)=0,0,I29*(100-MAX(0,MIN(100,K29)))/(G29+H29+I29+J29+L29))/100 -> 0.06 | Q29: =IF((G29+H29+I29+J29+L29)=0,0,J29*(100-MAX(0,MIN(100,K29)))/(G29+H29+I29+J29+L29))/100 -> 0.15 | R29: =MAX(0,MIN(100,K29))/100 -> 0.1 | S29: =IF((G29+H29+I29+J29+L29)=0,0,L29*(100-MAX(0,MIN(100,K29)))/(G29+H29+I29+J29+L29))/100 -> 0.14 | U29: 32 | V29: 23 | W29: 6 | X29: 15 | Y29: 10 | Z29: 14
A30: CARBON · Quality Assurance · Band A · Early career | B30: CARBON | C30: Quality Assurance | D30: Band A · Early career | E30: 7 | F30: Technology & engineering | G30: 64 | H30: 16 | I30: 4 | J30: 0 | K30: =WM_EXP_AB -> 10 | L30: 6 | M30: =SUM(G30:L30) -> 100 | N30: =IF((G30+H30+I30+J30+L30)=0,0,G30*(100-MAX(0,MIN(100,K30)))/(G30+H30+I30+J30+L30))/100 -> 0.64 | O30: =IF((G30+H30+I30+J30+L30)=0,0,H30*(100-MAX(0,MIN(100,K30)))/(G30+H30+I30+J30+L30))/100 -> 0.16 | P30: =IF((G30+H30+I30+J30+L30)=0,0,I30*(100-MAX(0,MIN(100,K30)))/(G30+H30+I30+J30+L30))/100 -> 0.04 | Q30: =IF((G30+H30+I30+J30+L30)=0,0,J30*(100-MAX(0,MIN(100,K30)))/(G30+H30+I30+J30+L30))/100 -> 0 | R30: =MAX(0,MIN(100,K30))/100 -> 0.1 | S30: =IF((G30+H30+I30+J30+L30)=0,0,L30*(100-MAX(0,MIN(100,K30)))/(G30+H30+I30+J30+L30))/100 -> 0.06 | U30: 64 | V30: 16 | W30: 4 | X30: 0 | Y30: 10 | Z30: 6
