Workbook
Name WM_EXP_AB: '1. Framework & Model'!$B$1123
Name WM_EXP_CE: '1. Framework & Model'!$B$1124
Name WM_KEY: '1. Framework & Model'!$A$1134:$A$1240
Name WM_C: '1. Framework & Model'!$N$1134:$N$1240
Name WM_AU: '1. Framework & Model'!$O$1134:$O$1240
Name WM_AC: '1. Framework & Model'!$P$1134:$P$1240
Name WM_L: '1. Framework & Model'!$Q$1134:$Q$1240
Name WM_E: '1. Framework & Model'!$R$1134:$R$1240
Name WM_BI: '1. Framework & Model'!$S$1134:$S$1240
Name PC_Products: Lists!$A$1:$A$6
Name L_CARBON: Lists!$D$1:$D$215
Name L_iFile: Lists!$D$216:$D$433
Name L_iDEAL: Lists!$D$434:$D$480
Name L_Datatech: Lists!$D$481:$D$514
Name L_Consume: Lists!$D$515:$D$537
Name L_Corporate: Lists!$D$538:$D$586

Sheet 1. Framework & Model
A1: HR Master — Simplified · Framework & Model
A2: Sheet 1 of 5 · The whole method on one page, top to bottom: how the job architecture works, how every number is calculated, how to track open items, and the references for each part. Then sheet 2 Talent Mapping, 3 Raw Data, 4 Person Card and 5 Role Profiles.
A3: IRIS · Job Architecture & Job Design · Final v1.14 · October 2026 · Internal — Confidential · HR only
A5: HOW TO USE THIS FILE
A6: This file | B6: HR Master — Simplified: five sheets that hold every person, every number and every reason from the HR Super Master v1.14, laid out in one line from the method to the person to the role. HR edits it; the other files are rebuilt from it.
A7: Sheet 2 · Talent Mapping | B7: One row per person · 586 people · every column grouped left to right: who → role before and after → the live score → how the level was set → the reasons for each rating → KRAs received from the manager → what the employee shared in the survey → role profile and business impact → talent, competencies, learning, mobility → recruitment → market → inputs, decisions and data quality → pay, blank → validation → HR update.
A8: Sheet 3 · Raw Data | B8: Every raw field as received from HRIS, the survey count, the manager talent-mapping files and the CARBON Mapping Master · values the earlier clean-up lost are restored from the source files · 20 people found in the source files but not yet mapped are added at the bottom, marked.
A9: Sheet 4 · Person Card | B9: Type or paste an Emp ID, or pick Product, then Name: every column of sheet 2 for that person, with their role profile from sheet 5 and a ratings chart.
A10: Sheet 5 · Role Profiles | B10: One row per role in the IRIS role catalogue · 181 roles · what the role is for, does, decides and needs; its weightage, live from the matrix in section 4; the step below and above on the ladder; market equivalents; references.
A11: Live numbers | B11: Weights, points, the score and 'Level the score indicates' are Excel formulas. Change a yellow weight in section 4 or a Business Impact rating on sheet 2 and they recalculate. FINAL LEVEL is a decision, not a formula: it moves through the rules R1–R13 or an approved leadership decision.
A12: How to update | B12: Write changes in the yellow HR UPDATE columns at the right of sheet 2 · field, new value, reason, source, who, date · or in the validation columns. Each change is read back on the next rebuild, so every number stays traceable.
A13: v1.14 decisions | B13: HR, 12 October 2026: D2 = Senior Vice President / Business Head · D1 = Associate Vice President / Distinguished Principal · B1 = Team Lead / Specialist / Asst Manager. The 18 department and function heads sit in Executive Leadership · Business Head. HR PROPOSED on sheet 2 applies the top-down manager rule: under a head at C1 or above a reportee sits in a lower band; below C1 at least one level below the manager. The business-head workbook takes the HR proposed level from here.
A14: Privacy | B14: HR only. Survey content is shown against names by HR's decision of 12 October 2026. Gender, date of birth, age, e-mail, mobile, resignation and relieving dates are never written. Pay columns stay blank until a pay survey is bought.
A16: CONTENTS OF THIS SHEET — click a section
A17: 0 | B17: How this exercise works — the journey from a base framework to today
A18: 1 | B18: The model the simple way — the 1–12 scale, six factors, weights, points, score → level, worked examples
A19: 2 | B19: The Master Framework M0–M17 — principles, architecture, families, levels, tracks, titles, factors, weights, rules, competencies, crosswalk, pay principles, governance, sources
A20: 3 | B20: Where the default weights come from — the market benchmark and its derivation
A21: 4 | B21: Weightage Matrix — LIVE: change a yellow weight and sheets 2, 4 and 5 recalculate
A22: 5 | B22: How to calculate and how to track
A23: 5b | B23: The end-to-end workflow and the review loop
A24: 5c | B24: Governance, data rules, validation and pay principles
A25: 6 | B25: References & benchmarks — evidence grades, peer universe, professional standards, department × level benchmarks, source register S01–S72
A26: 7 | B26: Decision log — every decision, its version and its effect
A27: 7b | B27: Glossary
A28: 8 | B28: Where everything in the HR Super Master lives in this file
A30: 0 · How this exercise works — the journey from a base framework to today
A31: References: S40 Employee Master HRIS · S41 How We Grow survey · S42 manager talent-mapping files · S43 IRIS talent-mapping workbooks
A32: 1. What we did — step by step
A33: # | B33: Step | C33: What we did | D33: What came out of it
A34: 1 | B34: Created a base framework | C34: Built IRIS's job architecture from established market methods — Aon Radford / Mercer career levels, Korn Ferry Hay factors, WTW banding and SFIA — with job families anchored to the ILO occupation standard. | D34: 19 job families, 61 sub-families, a 12-level ladder plus two Player-Coach steps · B+, C+, six factors, individual-contributor and manager tracks
A35: 2 | B35: Designed a survey around it | C35: The 'How We Grow' survey: 20 questions, each tied to the framework's factors — purpose of the role, what it delivers, what it is accountable for, what it can decide, the skills and tools it needs, and learning needs. | D35: One evidence form for every role, so each rating can be traced to an answer
A36: 3 | B36: Conducted 60–65 workshops | C36: Ran 60–65 workshops with teams across the six products and Corporate: explained the framework, walked through the questions and collected answers in the room. | D36: Survey responses from 520 people
A37: 4 | B37: Gathered the data | C37: Combined the survey with the HRIS employee master, KRAs · self and manager-set, the managers' talent mapping · rating, potential, 9-box and the reporting lines. | D37: One record per person — 586 people; KRAs on file for 453
A38: 5 | B38: Cleaned and protected it | C38: Matched responses to people · with consent where needed, removed personal data, and showed survey content only where three or more role-holders answered — never one person's words against a name. | D38: Privacy-safe evidence
A39: 6 | B39: Mapped every role | C39: Placed each person in a job family, a sub-family · the work they actually do and a track. | D39: 267 distinct employee roles; one IRIS-wide role catalogue
A40: 7 | B40: Rated and scored | C40: Rated six factors — Complexity, Autonomy, Accountability, Leadership, Experience & Qualification, Business Impact — on the ladder scale from the evidence; rating × weight = points; points add up to a score; the score points to a level. | D40: A score and an indicated level for 540 employees
A41: 8 | B41: Applied the rules | C41: Gates, limits and Player-Coach steps where the evidence calls for them, and leadership decisions for the top bands — each one written down with its numbers. | D41: A final level and designation for everyone, every move explained
A42: 9 | B42: Benchmarked to the market | C42: Matched every level to Aon Radford / Mercer codes and SFIA, and to competitor, regtech and SaaS ladders; every source re-read and corrected. | D42: A market code and a typical market title for every level
A43: 10 | B43: Built the file set | C43: One build produces every file from the same data, so they always agree: the HR Super Master, product masters and simplified editions, the framework & model master, the calibration panel pack, the ladder master and draft letters. | D43: Files by audience, rebuilt and re-checked in minutes
...

Sheet 2. Talent Mapping
A1: Talent Mapping — every person, every column, in one line | Q1: ◂ Start
A2: Sheet 2 of 5 · One row per person. Read left to right: who → role before and after → the live score → how the level was set → the reasons → KRAs from the manager → what the employee shared in the survey → role profile and business impact → talent, competencies, learning, mobility → recruitment → market → inputs, decisions and data quality → pay, blank → validation → HR update. Filter any column; the weights are live from sheet 1 section 4.
A3: IRIS · Job Architecture & Job Design · Final v1.14 · October 2026 · Internal — Confidential · HR only
A4: Section colours: each column group has its own header colour and a matching light tint | E4: Changed vs current | G4: Level up | H4: Level down · pay & title protected | J4: Newly mapped | K4: Player-Coach · B+ · C+ | M4: RED = critical input needed · says what and who | P4: YELLOW = to complete or edit | R4: GREY = pay · set later
A5: PERSON & KEYS | N5: ROLE — BEFORE → AFTER | AA5: HR PROPOSED — v1.14 · top-down manager rule · department heads in Executive Leadership | AJ5: SCORE — rating × weight = points · weights live from sheet 1 section 4 | BF5: HOW THE LEVEL WAS SET | BO5: JUSTIFICATION FOR EACH RATING — start point, evidence, market standard | BU5: KRAs RECEIVED FROM MANAGERS — as submitted | CB5: WHAT THE EMPLOYEE SHARED IN THE SURVEY — per person | CL5: ROLE PROFILE & BUSINESS IMPACT | CP5: TALENT · manager mapping, succession, critical roles | DA5: COMPETENCY RESULT | DJ5: LEARNING NEEDS | DO5: MOBILITY, OVERLAP & STRUCTURE | DU5: RECRUITMENT — REPLACEMENT PROFILE | DY5: MARKET STANDARD | EF5: INPUTS, DECISIONS & DATA QUALITY | EL5: PAY — set later from the pay survey · left blank | EQ5: VALIDATION — manager & HR | EY5: HR UPDATE — write a change here; it is read back on the next rebuild
A6: Business | B6: Emp ID | C6: Employee name | D6: Department | E6: Role ID · catalogue | F6: Reporting manager | G6: Reporting manager · Emp ID | H6: Reporting manager · final level | I6: Direct reports | J6: Total exp. · yrs | K6: Exp. at IRIS · yrs | L6: Qualification | M6: Emp ID in the source files · where different | N6: Current designation | O6: Final designation | P6: Job family | Q6: Sub-family · what they do | R6: Current level | S6: FINAL LEVEL | T6: Level title | U6: Band | V6: Track | W6: Change vs current | X6: Radford / Mercer code | Y6: Pave level | Z6: SFIA 9 | AA6: HR proposed level · v1.14 | AB6: HR proposed band | AC6: HR proposed level title | AD6: Move vs v1.13 model level | AE6: Manager's HR proposed level | AF6: Manager rule check | AG6: How the HR proposed level was set | AH6: Layer from the CEO | AI6: Job family & sub-family · v1.14 change | AJ6: Weight row — Weightage Matrix | AK6: Complexity rating | AL6: Complexity weight | AM6: Complexity points | AN6: Autonomy rating | AO6: Autonomy weight | AP6: Autonomy points | AQ6: Accountab. rating | AR6: Accountab. weight | AS6: Accountab. points | AT6: Leadership rating | AU6: Leadership weight | AV6: Leadership points | AW6: Exp + Qual rating | AX6: Exp + Qual weight | AY6: Exp + Qual points | AZ6: Bus. Impact rating | BA6: Bus. Impact weight | BB6: Bus. Impact points | BC6: WEIGHTED SCORE = Σ points | BD6: Level the score indicates | BE6: FINAL LEVEL · after the rules | BF6: What set the level | BG6: Why these weights | BH6: Calculation | BI6: Gates, limits & Player-Coach transition steps applied — with the numbers | BJ6: Flags | BK6: Player-Coach / calibration flag | BL6: Confidence | BM6: Points to confirm | BN6: Weight sensitivity | BO6: Complexity & Expertise — justification | BP6: Autonomy & Decision — justification | BQ6: Accountability & Impact — justification | BR6: Leadership & Strategy — justification | BS6: Experience & Qualification — justification | BT6: Business Impact — justification | BU6: KRAs set by manager · annual | BV6: KRAs · quarterly | BW6: KRAs · self-reported annual | BX6: Q1 tentative rating · scale 1-5 | BY6: Actual JD · from manager | BZ6: KRA status | CA6: KRA source | CB6: Survey questions answered · of 20 | CC6: Role mandate & core purpose · as shared | CD6: Deliverables, responsibilities & accountability · as shared | CE6: Capabilities, tools, workload & way of working · as shared | CF6: Development priorities & learning needs · as shared | CG6: Challenges & support required · as shared | CH6: Survey & KRA evidence used for each rating | CI6: Survey themes for this role · role-holders | CJ6: Learning topics named in the survey | CK6: Survey status | CL6: Role profile — what they do, responsibilities & competencies required | CM6: Business impact — from survey and data | CN6: Business impact — from manager / head · to complete | CO6: Bus. Impact — model start | CP6: Latest rating | CQ6: Potential | CR6: 9-box | CS6: Readiness | CT6: Top performer | CU6: Critical role · Y/N | CV6: Successor named | CW6: Succession · C–E roles | CX6: Critical-role risk | CY6: Possible cover · same sub-family | CZ6: Risk action | DA6: Competency index % | DB6: Fit | DC6: Core % | DD6: Future-ready % | DE6: Functional % | DF6: Leadership % | DG6: Top gaps | DH6: Readiness for next level | DI6: Ratings by competency · rating / required | DJ6: Self-identified — topics · survey; not quoted | DK6: Manager-identified | DL6: Role-based priorities | DM6: To move to the next role — topics · survey; not quoted | DN6: Training for next role | DO6: Lateral move options | DP6: Duplication — same business | DQ6: Alternate talent pool — other businesses | DR6: Span status | DS6: Span action | DT6: Org health & A3 notes | DU6: Replacement — what they do · simple | DV6: Hire equivalent · external market | DW6: Competencies & skill level to hire for | DX6: Interview questions for the perfect fit | DY6: Market standard for this role and level | DZ6: IRIS experience guide | EA6: Market experience · Accenture · Infosys | EB6: Typical market title based on competitor/market benchmark | EC6: Competitors, regtech & SaaS leaders | ED6: Professional standard | EE6: Required capability · Core · Future · Functional · Leadership | EF6: ADDITIONAL INPUTS NEEDED — what, and who provides it | EG6: Data used for this person | EH6: Open decisions | EI6: Data requests | EJ6: Data gaps | EK6: Data quality | EL6: Current fixed pay · annual CTC | EM6: Proposed range — minimum | EN6: Proposed range — midpoint | EO6: Proposed range — maximum | EP6: Compa-ratio | EQ6: Manager validation | ER6: Manager comment / proposed change | ES6: HR decision | ET6: Approved level | EU6: Approved designation | EV6: Pay / title protection · Y/N | EW6: Reviewer | EX6: Decision date | EY6: Field to update | EZ6: New value | FA6: Reason | FB6: Source | FC6: Updated by | FD6: Date
A7: CARBON | B7: IRIS0391 | C7: Anuradha RK | D7: CARBON Business Head | E7: RC-EL-BH-D2 | F7: Dixit Jasani | G7: IRIS2478 | H7: E1 | I7: 9 | J7: 17.1 | K7: 16.4 | L7: MBA | N7: Business Head | O7: Business Head | P7: Executive Leadership | Q7: Business Head | R7: Not in current mapping files | S7: D2 | T7: Senior Vice President / Business Head | U7: D | V7: People Manager | W7: ● Newly mapped | X7: E3–E4 | Y7: SVP | Z7: 7 Set strategy | AA7: D2 | AB7: Band D · Business leadership | AC7: Senior Vice President / Business Head | AD7: • Same as the model | AE7: E1 | AF7: OK | AG7: No change · already below the manager | AH7: 2 | AI7: Department head · moved to Executive Leadership · Business Head; was Executive Leadership · Business & Functional Leadership | AJ7: CARBON · CARBON Business Head · Bands D–E · Leadership | AK7: 9 | AL7: =IFERROR(INDEX(WM_C,MATCH($AJ7,WM_KEY,0)),"") -> 0.37 | AM7: =IF(OR(AK7="",AL7=""),"",AK7*AL7) -> 3.33 | AN7: 9 | AO7: =IFERROR(INDEX(WM_AU,MATCH($AJ7,WM_KEY,0)),"") -> 0.19 | AP7: =IF(OR(AN7="",AO7=""),"",AN7*AO7) -> 1.71 | AQ7: 9 | AR7: =IFERROR(INDEX(WM_AC,MATCH($AJ7,WM_KEY,0)),"") -> 0.11 | AS7: =IF(OR(AQ7="",AR7=""),"",AQ7*AR7) -> 0.99 | AT7: 9 | AU7: =IFERROR(INDEX(WM_L,MATCH($AJ7,WM_KEY,0)),"") -> 0.2 | AV7: =IF(OR(AT7="",AU7=""),"",AT7*AU7) -> 1.8 | AW7: 9.5 | AX7: =IFERROR(INDEX(WM_E,MATCH($AJ7,WM_KEY,0)),"") -> 0.05 | AY7: =IF(OR(AW7="",AX7=""),"",AW7*AX7) -> 0.475 | AZ7: 9 | BA7: =IFERROR(INDEX(WM_BI,MATCH($AJ7,WM_KEY,0)),"") -> 0.08 | BB7: =IF(OR(AZ7="",BA7=""),"",AZ7*BA7) -> 0.72 | BC7: =IF(COUNT(AM7,AP7,AS7,AV7,AY7,BB7)<6,"",SUM(AM7,AP7,AS7,AV7,AY7,BB7)) -> 9.025 | BD7: =IF(BC7="","",INDEX({"A1","A2","A3","B1","B2","B3","C1","C2","D1","D2","E1","E2"},MAX(1,MIN(12,ROUND(BC7,0))))) -> D1 | BE7: D2 | BF7: Rule: R11 leadership decision | BG7: Weights: Complexity 37% · Leadership 20% · Autonomy 19% · Accountability 11% · Business impact 8% · Experience 5% Why: leaders are judged on the hardest problems, on leading — 20% — and on the decisions, scope and business impact of the job. Type of work in the department: no adjustment at this level. Live: change the department's row on the Weightage Matrix and these weights, the points and the score update. | BH7: At build: Complexity 3.33 + Autonomy 1.71 + Accountability 0.99 + Leadership 1.80 + Experience 0.48 + Business impact 0.72 = 9.03 points → nearest level 9 = D1 Final level: D2 · a rule applied: see the next column | BI7: • Set at D2 by leadership decision · the model indicated D1: Leadership structure: CARBON Business Head at D2. Final level: D2. | BJ7: Input needed | BL7: Low | BM7: • CARBON Leadership Scorecard row 6 describes sales/implementation ownership for Anuradha, while the master says Business Head. Confirm full-business versus commercial-capability mandate and identity of the abbreviated reference • No survey answers or KRA — the role factors rest on designation and reporting lines only | BN7: Moves in 30 of 30 weight tests · calibrate first | BO7: Rated 9 of 12 Start: 9.0 · business head / director title Evidence: no survey answers or KRAs on file → rating stays at the start Market: D1 = Competing strategic, financial and regulatory priorities | BP7: Rated 9 of 12 Start: 9.0 · business head / director title Evidence: no survey answers or KRAs on file → rating stays at the start Market: D1 = Sets business-line direction, pricing and investment | BQ7: Rated 9 of 12 Start: 9.0 · business head / director title; 9 direct reports, 166 people in the organisation Evidence: no survey answers or KRAs on file → rating stays at the start Market: D1 = Business-line P&L and market position | BR7: Rated 9 of 12 Start: 9.0 Evidence: no survey answers or KRAs on file → rating stays at the start Team: 9 direct reports · People Manager Market: D1 = Defines business strategy; builds the leadership bench | BS7: Rated 9.5 of 12 · between D1 and D2 Experience: 17.1 yrs total · 0.7 before IRIS + 16.4 at IRIS = 8.9 on the experience scale Qualification: MBA · postgraduate, relevant to the work → +0.5 | BT7: Rated 9 of 12 — a starting estimate. Start: 9, the role's accountability scope — what it answers for. No survey or manager-mapping signal on criticality: kept at the start point. Managers and heads: overwrite this rating on the Weightage sheet with the business impact you see — the score updates at once. Ladder: D1 = Owns a business line's P&L and growth, or a company-wide function | BU7: KRAs not received · manager to supply | BZ7: KRAs not received · manager to supply | CB7: 0 | CC7: No survey response on file | CD7: — | CE7: — | CF7: — | CG7: — | CH7: Complexity: Evidence: no survey answers or KRAs on file → rating stays at the start Autonomy: Evidence: no survey answers or KRAs on file → rating stays at the start Accountability: Evidence: no survey answers or KRAs on file → rating stays at the start Leadership: Evidence: no survey answers or KRAs on file → rating stays at the start Business Impact: No survey or manager-mapping signal on criticality: kept at the start point. | CK7: No survey response on file | CL7: WHAT THE ROLE DOES: Owns a business line or enterprise function end to end. At D2: several business lines or an executive-scope enterprise function. KEY RESPONSIBILITIES: Owns a business line or enterprise function end to end; Portfolio-level strategic, financial and regulatory trade-offs; Multi-business results DELIVERS: Multi-business results DECIDES ALONE: Sets direction across business lines SKILLS & KNOWLEDGE · role-holders: Product Management COMPETENCIES REQUIRED — must-have ★: Strategic Thinking & Business Acumen · People Leadership & Mentoring OTHER FUNCTIONAL COMPETENCIES: Stakeholder & Client Management · Product, Platform & Domain Knowledge · Regulatory & BFSI Domain · Communication & Presentation PROFICIENCY NEEDED AT THIS LEVEL: Core 5 · Future-ready 4 · Functional 4 · Leadership 5 CREDENTIALS: MBA / PGDM · preferred at C+ SOURCE: Framework only · fewer than 3 answered — 3 holders, 0 answered the survey; sub-family 0 answered; catalogue RC-091 | CM7: What the role answers for: Multi-business results. Accountability & Impact rating: 9 of 12 · D1-level impact. Leads 9 direct reports. Manager talent mapping — Latest rating: Not rated · manager · 9-Box Grid placement: Not placed · manager. | CO7: 9 | CP7: Not rated · manager | CQ7: — | CR7: Not placed · manager | CS7: No rating data | CW7: Succession: Ready-now successor · ready now Vijay Parulekar · C1, CARBON, Shashikant Mudaliar · C1, CARBON · in 6–12 months Anushree Aparajit · C1, CARBON · high potential — | DB7: Not assessed — no survey or KRA evidence | DI7: Required at D1: Core 5 · Future-ready 4 · Functional Business acumen 4 · People leadership 4 · Stakeholder mgmt 4 · Product & domain 4 · Regulatory domain 4 · Communication 4 · Leadership 5 — rate in manager validation using sheet 4. | DL7: Strategic Thinking & Business Acumen | DP7: No survey text | DQ7: No survey text | DR7: Within norm | DU7: Business Head in CARBON Business Head · CARBON, D2 — People Manager. The work: Owns a business line or enterprise function end to end. At this level the role owns several business lines or an executive-scope enterprise function. Key responsibilities: Owns a business line or enterprise function end to end; Portfolio-level strategic, financial and regulatory trade-offs; Multi-business results. Leads 9 direct reports. | DV7: Hire as: Associate Vice President — IRIS D2 Vice President · People Manager Market level: E3–E4 · SFIA 7 Set strategy Experience: 18–24 yrs · Education: Postgraduate / professional qualification Team size at this level: 5–8 AVPs / heads Equivalent titles at peers: IRIS Vs Market Benchmark — Aon Radford / Mercer executive codes – E3–E4 SVP · IRIS Vs Competitor Benchmark — regtech / SaaS executive titles – SVP Credentials: MBA / PGDM · preferred at C+ Must already know: Governance, risk and regulatory accountability | DW7: FUNCTIONAL — skill level 4 of 5 · Advanced ★ Strategic Thinking & Business Acumen: Shapes strategy, pricing or investment choices ★ People Leadership & Mentoring: Leads leaders; builds succession • Stakeholder & Client Management: Owns key relationships; resolves escalations • Product, Platform & Domain Knowledge: Recognised product / domain expert; trains others • Regulatory & BFSI Domain: Interprets new regulation; advises clients and product • Communication & Presentation: Presents to senior stakeholders; shapes messaging CORE — skill level 5 of 5 · Expert • Ownership & Accountability: Owns business outcomes; builds a culture of accountability • Problem Solving & Critical Thinking: Frames enterprise-level problems; sets the approach for others • Communication & Collaboration: Represents IRIS externally; builds cross-business partnerships • Client & Quality Focus: Defines client and quality strategy for a business • Learning Agility & Adaptability: Anticipates change; builds a learning organisation • Integrity, Compliance & Information Security: Sets ethical and compliance standards for the business FUTURE-READY — skill level 4 of 5 · Advanced • AI Literacy & Augmentation: Designs AI-enabled processes for a team; sets safe-use practices • Data Literacy & Analytics: Defines metrics and dashboards for a team • Digital Fluency & Automation: Automates team processes; selects tools • Innovation & Continuous Improvement: Leads improvement initiatives for a team LEADERSHIP — skill level 5 of 5 · Expert • Leading & Developing People: Builds the leadership pipeline and culture • Decision Making & Delegation: Makes enterprise / business-line decisions • Strategic & Business Acumen: Sets business strategy and P&L direction • Influence & Change Leadership: Leads enterprise change; influences clients, regulators and partners SKILLS · from role-holders and HRIS: Product Management ★ = must-have for the family. Scale: 1 Awareness · 2 Working · 3 Practitioner · 4 Advanced · 5 Expert. | DX7: Draft — generated from the framework; hiring-manager review pending · HR Super Master, sheet T5. 1. [Strategic Thinking & Business Acumen · level 4] Tell me about recent work that shows this: "Shapes strategy, pricing or investment choices". What exactly did you do, how, and what was the result? Assess with: Case interview. 2. [People Leadership & Mentoring · level 4] Tell me about recent work that shows this: "Leads leaders; builds succession". What exactly did you do, how, and what was the result? Assess with: Behavioural interview. 3. [Stakeholder & Client Management · level 4] Give an example that shows you can do this: "Owns key relationships; resolves escalations". Assess with: Role play / behavioural interview. 4. [Product, Platform & Domain Knowledge · level 4] Give an example that shows you can do this: "Recognised product / domain expert; trains others". Assess with: Scenario interview. 5. [Regulatory & BFSI Domain · level 4] Give an example that shows you can do this: "Interprets new regulation; advises clients and product". Assess with: Domain interview. 6. [Ownership & Accountability · level 5] Describe a time you held a team to a standard on an outcome that mattered to the business. How did you make ownership stick? Listen for: "Owns business outcomes; builds a culture of accountability". 7. [Problem Solving & Critical Thinking · level 5] Tell me about an ambiguous, high-stakes problem with no clear answer. How did you frame it and decide? Listen for: "Frames enterprise-level problems; sets the approach for others". 8. [Client & Quality Focus · level 5] Describe how you raised quality or client outcomes across a team or service. How did you measure it? Listen for: "Defines client and quality strategy for a business". 9. [AI Literacy & Augmentation · level 4] Where have you introduced AI or automation into a team's work, and how did you manage the risks? Listen for: "Designs AI-enabled processes for a team; sets safe-use practices". 10. [Leading & Developing People · level 5] Tell me about building a team: who you hired, how you developed them, and a difficult people decision you made. Listen for: "Builds the leadership pipeline and culture". 11. [Decision Making & Delegation · level 5] Tell me about a decision you delegated and one you kept. Why, and what happened? Listen for: "Makes enterprise / business-line decisions". 12. [Strategic & Business Acumen · level 5] Tell me about a strategy or plan you shaped. What trade-offs did you make, and what was the business result? Listen for: "Sets business strategy and P&L direction". 13. [Influence & Change Leadership · level 5] Describe a change you led across teams or the business. How did you deal with resistance? Listen for: "Leads enterprise change; influences clients, regulators and partners". Fit check: Why this role, why IRIS · regulatory reporting / XBRL / regtech, and what would you change in your first 90 days? | DY7: Market level: E3–E4 · SFIA 7 Set strategy Typical title: Associate Vice President At peers: IRIS Vs Market Benchmark — Aon Radford / Mercer executive codes: E3–E4 SVP · IRIS Vs Competitor Benchmark — regtech / SaaS executive titles: SVP Standard: Aon Radford executive levels E1–E6; Mercer ET1–ET3 | DZ7: 18–24 yrs | EA7: — | EB7: Associate Vice President | EC7: IRIS Vs Market Benchmark — Aon Radford / Mercer executive codes: E3–E4 SVP · IRIS Vs Competitor Benchmark — regtech / SaaS executive titles: SVP | ED7: Aon Radford executive levels E1–E6; Mercer ET1–ET3; Korn Ferry Leadership Architect | EE7: Core 5 · Future 4 · Functional 4 · Leadership 5 | EF7: • Survey response or KRAs describing the work · nothing on file — Employee + manager • Resolve conflicting role records — Business head | EG7: ✓ HRIS: 17.1 yrs, MBA, 9 direct reports ✗ Survey: no response ✗ KRAs: none on file ✓ Manager mapping: rating, 9-box ✗ Job description: not on file ✓ Validated inputs: Approved level: D1 → D2 · Leadership structure: CARBON Business Head at D2 · Leadership decision · HR review of 9 Oct 2026 · 2026-10-09 | EH7: D129 · Title to review · Low: Check title against ladder · owner HR · D287 · Input needed · Medium: • Survey response or KRAs describing the work · nothing on file — Employee + manager • Resolve conflicting role records — Business head · owner Employee + manager · Business head · | EI7: R001 · Survey response or KRAs describing the work · nothing on file · Employee + manager · Open R002 · Resolve conflicting role records · Business head · Open | EJ7: Survey response or KRAs describing the work · nothing on file · Employee + manager Resolve conflicting role records · Business head | EK7: Survey: no response · KRAs: not received · Experience: on file
A8: CARBON | B8: IRIS2478 | C8: Dixit Jasani | D8: CRO - Carbon | E8: RC-EL-BH-E1 | F8: Balachandran K | G8: IRIS0001 | H8: E2 | I8: 1 | J8: 27.9 | K8: 0.6 | L8: PGDM | N8: Chief Revenue Officer- Enterprise Division | O8: Chief Revenue Officer | P8: Executive Leadership | Q8: Business Head | R8: Not in current mapping files | S8: E1 | T8: CXO / President | U8: E | V8: People Manager | W8: ● Newly mapped | X8: E5 | Y8: C-Level | Z8: 7 | AA8: E1 | AB8: Band E · Enterprise leadership | AC8: CXO / President | AD8: • Same as the model | AE8: E2 | AF8: Exception · Band E | AG8: Band E with Band E · agreed exception · manager E2 | AH8: 1 | AI8: Department head · moved to Executive Leadership · Business Head; was Executive Leadership · Enterprise Leadership | AJ8: CARBON · CRO - Carbon · Bands D–E · Leadership | AK8: 11 | AL8: =IFERROR(INDEX(WM_C,MATCH($AJ8,WM_KEY,0)),"") -> 0.37 | AM8: =IF(OR(AK8="",AL8=""),"",AK8*AL8) -> 4.07 | AN8: 11 | AO8: =IFERROR(INDEX(WM_AU,MATCH($AJ8,WM_KEY,0)),"") -> 0.19 | AP8: =IF(OR(AN8="",AO8=""),"",AN8*AO8) -> 2.09 | AQ8: 11 | AR8: =IFERROR(INDEX(WM_AC,MATCH($AJ8,WM_KEY,0)),"") -> 0.11 | AS8: =IF(OR(AQ8="",AR8=""),"",AQ8*AR8) -> 1.21 | AT8: 11 | AU8: =IFERROR(INDEX(WM_L,MATCH($AJ8,WM_KEY,0)),"") -> 0.2 | AV8: =IF(OR(AT8="",AU8=""),"",AT8*AU8) -> 2.2 | AW8: 12 | AX8: =IFERROR(INDEX(WM_E,MATCH($AJ8,WM_KEY,0)),"") -> 0.05 | AY8: =IF(OR(AW8="",AX8=""),"",AW8*AX8) -> 0.6 | AZ8: 11 | BA8: =IFERROR(INDEX(WM_BI,MATCH($AJ8,WM_KEY,0)),"") -> 0.08 | BB8: =IF(OR(AZ8="",BA8=""),"",AZ8*BA8) -> 0.88 | BC8: =IF(COUNT(AM8,AP8,AS8,AV8,AY8,BB8)<6,"",SUM(AM8,AP8,AS8,AV8,AY8,BB8)) -> 11.05 | BD8: =IF(BC8="","",INDEX({"A1","A2","A3","B1","B2","B3","C1","C2","D1","D2","E1","E2"},MAX(1,MIN(12,ROUND(BC8,0))))) -> E1 | BE8: E1 | BF8: The score decided the level | BG8: Weights: Complexity 37% · Leadership 20% · Autonomy 19% · Accountability 11% · Business impact 8% · Experience 5% Why: leaders are judged on the hardest problems, on leading — 20% — and on the decisions, scope and business impact of the job. Type of work in the department: no adjustment at this level. Live: change the department's row on the Weightage Matrix and these weights, the points and the score update. | BH8: At build: Complexity 4.07 + Autonomy 2.09 + Accountability 1.21 + Leadership 2.20 + Experience 0.60 + Business impact 0.88 = 11.05 points → nearest level 11 = E1 Final level: E1 · same as the score | BI8: No rule applied: the score decides. | BJ8: Input needed | BL8: Low | BM8: • CARBON Leadership Scorecard row 8 describes marketing/partnerships with no ARR ownership for Dixit, unlike the CRO designation. Confirm actual mandate and identity of the abbreviated reference • No survey answers or KRA — the role factors rest on designation and reporting lines only | BN8: Stable · moves in fewer than 5 of 30 weight tests | BO8: Rated 11 of 12 Start: 11.0 · CXO title Evidence: no survey answers or KRAs on file → rating stays at the start Market: E1 = Enterprise-level functional strategy | BP8: Rated 11 of 12 Start: 11.0 · CXO title Evidence: no survey answers or KRAs on file → rating stays at the start Market: E1 = Sets enterprise priorities for the function | BQ8: Rated 11 of 12 Start: 11.0 · CXO title; 1 direct report, 167 people in the organisation Evidence: no survey answers or KRAs on file → rating stays at the start Market: E1 = Enterprise-wide functional results | BR8: Rated 11 of 12 Start: 11.0 Evidence: no survey answers or KRAs on file → rating stays at the start Team: 1 direct report · People Manager Market: E1 = Shapes enterprise strategy | BS8: Rated 12 of 12 Experience: 27.9 yrs total · 27.3 before IRIS + 0.6 at IRIS = 12.0 on the experience scale Qualification: PGDM · postgraduate, relevant to the work → +0.5 | BT8: Rated 11 of 12 — a starting estimate. Start: 11, the role's accountability scope — what it answers for. No survey or manager-mapping signal on criticality: kept at the start point. Managers and heads: overwrite this rating on the Weightage sheet with the business impact you see — the score updates at once. Ladder: E1 = Shapes company-wide results through a function | BU8: KRAs not received · manager to supply | BZ8: KRAs not received · manager to supply | CB8: 0 | CC8: No survey response on file | CD8: — | CE8: — | CF8: — | CG8: — | CH8: Complexity: Evidence: no survey answers or KRAs on file → rating stays at the start Autonomy: Evidence: no survey answers or KRAs on file → rating stays at the start Accountability: Evidence: no survey answers or KRAs on file → rating stays at the start Leadership: Evidence: no survey answers or KRAs on file → rating stays at the start Business Impact: No survey or manager-mapping signal on criticality: kept at the start point. | CK8: No survey response on file | CL8: WHAT THE ROLE DOES: Sets enterprise strategy; leads the executive team. At E1: an enterprise-wide function. KEY RESPONSIBILITIES: Sets enterprise strategy; leads the executive team; Enterprise-level functional strategy; Enterprise-wide functional results DELIVERS: Enterprise-wide functional results DECIDES ALONE: Sets enterprise priorities for the function SKILLS & KNOWLEDGE · role-holders: Management · Sales COMPETENCIES REQUIRED — must-have ★: Strategic Thinking & Business Acumen · People Leadership & Mentoring OTHER FUNCTIONAL COMPETENCIES: Stakeholder & Client Management · Product, Platform & Domain Knowledge · Regulatory & BFSI Domain · Communication & Presentation PROFICIENCY NEEDED AT THIS LEVEL: Core 5 · Future-ready 5 · Functional 4 · Leadership 5 CREDENTIALS: MBA / PGDM · preferred at C+ SOURCE: Framework only · fewer than 3 answered — 4 holders, 0 answered the survey; sub-family 0 answered; catalogue RC-092 | CM8: What the role answers for: Enterprise-wide functional results. Accountability & Impact rating: 11 of 12 · E1-level impact. Leads 1 direct report. Manager talent mapping — Latest rating: Not rated · manager · 9-Box Grid placement: Not placed · manager. | CO8: 11 | CP8: Not rated · manager | CQ8: — | CR8: Not placed · manager | CS8: No rating data | CW8: Succession: No successor identified · ready now — · in 6–12 months — · high potential — | DB8: Not assessed — no survey or KRA evidence | DI8: Required at E1: Core 5 · Future-ready 5 · Functional Business acumen 4 · People leadership 4 · Stakeholder mgmt 4 · Product & domain 4 · Regulatory domain 4 · Communication 4 · Leadership 5 — rate in manager validation using sheet 4. | DL8: Strategic Thinking & Business Acumen | DP8: No survey text | DQ8: No survey text | DR8: Below norm | DT8: Span: 1 direct reports · layer 2 · Very small team: merge with a neighbouring team or make a POD Lead role | DU8: Chief Revenue Officer in CRO - Carbon · CARBON, E1 — People Manager. The work: Sets enterprise strategy; leads the executive team. At this level the role owns an enterprise-wide function. Key responsibilities: Sets enterprise strategy; leads the executive team; Enterprise-level functional strategy; Enterprise-wide functional results. Leads 1 direct report. | DV8: Hire as: CXO · functional chief — IRIS E1 CXO / President · People Manager Market level: E5 · SFIA 7 Experience: 20+ yrs · Education: Postgraduate / professional qualification Team size at this level: 5–8 function heads Equivalent titles at peers: IRIS Vs Market Benchmark — Aon Radford / Mercer executive codes – E5 C-level · functional · IRIS Vs Competitor Benchmark — regtech / SaaS executive titles – CTO · CFO · CRO · CCO · COO Credentials: MBA / PGDM · preferred at C+ Must already know: Governance, risk and regulatory accountability | DW8: FUNCTIONAL — skill level 4 of 5 · Advanced ★ Strategic Thinking & Business Acumen: Shapes strategy, pricing or investment choices ★ People Leadership & Mentoring: Leads leaders; builds succession • Stakeholder & Client Management: Owns key relationships; resolves escalations • Product, Platform & Domain Knowledge: Recognised product / domain expert; trains others • Regulatory & BFSI Domain: Interprets new regulation; advises clients and product • Communication & Presentation: Presents to senior stakeholders; shapes messaging CORE — skill level 5 of 5 · Expert • Ownership & Accountability: Owns business outcomes; builds a culture of accountability • Problem Solving & Critical Thinking: Frames enterprise-level problems; sets the approach for others • Communication & Collaboration: Represents IRIS externally; builds cross-business partnerships • Client & Quality Focus: Defines client and quality strategy for a business • Learning Agility & Adaptability: Anticipates change; builds a learning organisation • Integrity, Compliance & Information Security: Sets ethical and compliance standards for the business FUTURE-READY — skill level 5 of 5 · Expert • AI Literacy & Augmentation: Leads AI strategy and governance for a function or IRIS • Data Literacy & Analytics: Sets data strategy and data-driven decisions for a business • Digital Fluency & Automation: Drives digital transformation across a business • Innovation & Continuous Improvement: Creates new products, methods or business models LEADERSHIP — skill level 5 of 5 · Expert • Leading & Developing People: Builds the leadership pipeline and culture • Decision Making & Delegation: Makes enterprise / business-line decisions • Strategic & Business Acumen: Sets business strategy and P&L direction • Influence & Change Leadership: Leads enterprise change; influences clients, regulators and partners SKILLS · from role-holders and HRIS: Management · Sales ★ = must-have for the family. Scale: 1 Awareness · 2 Working · 3 Practitioner · 4 Advanced · 5 Expert. | DX8: Draft — generated from the framework; hiring-manager review pending · HR Super Master, sheet T5. 1. [Strategic Thinking & Business Acumen · level 4] Tell me about recent work that shows this: "Shapes strategy, pricing or investment choices". What exactly did you do, how, and what was the result? Assess with: Case interview. 2. [People Leadership & Mentoring · level 4] Tell me about recent work that shows this: "Leads leaders; builds succession". What exactly did you do, how, and what was the result? Assess with: Behavioural interview. 3. [Stakeholder & Client Management · level 4] Give an example that shows you can do this: "Owns key relationships; resolves escalations". Assess with: Role play / behavioural interview. 4. [Product, Platform & Domain Knowledge · level 4] Give an example that shows you can do this: "Recognised product / domain expert; trains others". Assess with: Scenario interview. 5. [Regulatory & BFSI Domain · level 4] Give an example that shows you can do this: "Interprets new regulation; advises clients and product". Assess with: Domain interview. 6. [Ownership & Accountability · level 5] Describe a time you held a team to a standard on an outcome that mattered to the business. How did you make ownership stick? Listen for: "Owns business outcomes; builds a culture of accountability". 7. [Problem Solving & Critical Thinking · level 5] Tell me about an ambiguous, high-stakes problem with no clear answer. How did you frame it and decide? Listen for: "Frames enterprise-level problems; sets the approach for others". 8. [Client & Quality Focus · level 5] Describe how you raised quality or client outcomes across a team or service. How did you measure it? Listen for: "Defines client and quality strategy for a business". 9. [AI Literacy & Augmentation · level 5] Where have you introduced AI or automation into a team's work, and how did you manage the risks? Listen for: "Leads AI strategy and governance for a function or IRIS". 10. [Leading & Developing People · level 5] Tell me about building a team: who you hired, how you developed them, and a difficult people decision you made. Listen for: "Builds the leadership pipeline and culture". 11. [Decision Making & Delegation · level 5] Tell me about a decision you delegated and one you kept. Why, and what happened? Listen for: "Makes enterprise / business-line decisions". 12. [Strategic & Business Acumen · level 5] Tell me about a strategy or plan you shaped. What trade-offs did you make, and what was the business result? Listen for: "Sets business strategy and P&L direction". 13. [Influence & Change Leadership · level 5] Describe a change you led across teams or the business. How did you deal with resistance? Listen for: "Leads enterprise change; influences clients, regulators and partners". Fit check: Why this role, why IRIS · regulatory reporting / XBRL / regtech, and what would you change in your first 90 days? | DY8: Market level: E5 · SFIA 7 Typical title: CXO · functional chief At peers: IRIS Vs Market Benchmark — Aon Radford / Mercer executive codes: E5 C-level · functional · IRIS Vs Competitor Benchmark — regtech / SaaS executive titles: CTO · CFO · CRO · CCO · COO Standard: Aon Radford executive levels E1–E6; Mercer ET1–ET3 | DZ8: 20+ yrs | EA8: — | EB8: CXO · functional chief | EC8: IRIS Vs Market Benchmark — Aon Radford / Mercer executive codes: E5 C-level · functional · IRIS Vs Competitor Benchmark — regtech / SaaS executive titles: CTO · CFO · CRO · CCO · COO | ED8: Aon Radford executive levels E1–E6; Mercer ET1–ET3; Korn Ferry Leadership Architect | EE8: Core 5 · Future 5 · Functional 4 · Leadership 5 | EF8: • Survey response or KRAs describing the work · nothing on file — Employee + manager • Resolve conflicting role records — Business head | EG8: ✓ HRIS: 27.9 yrs, PGDM, 1 direct report ✗ Survey: no response ✗ KRAs: none on file ✓ Manager mapping: rating, 9-box ✗ Job description: not on file | EH8: D288 · Input needed · Medium: • Survey response or KRAs describing the work · nothing on file — Employee + manager • Resolve conflicting role records — Business head · owner Employee + manager · Business head · | EI8: R003 · Survey response or KRAs describing the work · nothing on file · Employee + manager · Open R004 · Resolve conflicting role records · Business head · Open | EJ8: Survey response or KRAs describing the work · nothing on file · Employee + manager Resolve conflicting role records · Business head | EK8: Survey: no response · KRAs: not received · Experience: on file
A9: CARBON | B9: IRIS2359 | C9: Suman Adhikary | D9: Customer Experience | E9: RC-EL-BH-D1 | F9: Anuradha RK | G9: IRIS0391 | H9: D2 | I9: 8 | J9: 28.7 | K9: 1.5 | L9: B.E | N9: Senior Vice President - Customer Experience | O9: Senior Vice President – Customer Experience | P9: Executive Leadership | Q9: Business Head | R9: Not in current mapping files | S9: D1 | T9: Associate Vice President | U9: D | V9: People Manager | W9: ● Newly mapped | X9: E1–E2 | Y9: VP | Z9: 6–7 | AA9: C2 | AB9: Band C · Principal / Head | AC9: Head of Function | AD9: ▼ Down · pay and title protected | AE9: D2 | AF9: OK | AG9: Band rule: manager D2 is a head in Band D · Business leadership; a reportee sits in a lower band · D1 → C2 · move down · pay and title protected for one cycle | AH9: 3 | AI9: Department head · moved to Executive Leadership · Business Head; was Executive Leadership · Business & Functional Leadership | AJ9: CARBON · Customer Experience · Bands D–E · Leadership | AK9: 10 | AL9: =IFERROR(INDEX(WM_C,MATCH($AJ9,WM_KEY,0)),"") -> 0.37 | AM9: =IF(OR(AK9="",AL9=""),"",AK9*AL9) -> 3.7 | AN9: 10 | AO9: =IFERROR(INDEX(WM_AU,MATCH($AJ9,WM_KEY,0)),"") -> 0.19 | AP9: =IF(OR(AN9="",AO9=""),"",AN9*AO9) -> 1.9 | AQ9: 10 | AR9: =IFERROR(INDEX(WM_AC,MATCH($AJ9,WM_KEY,0)),"") -> 0.11 | AS9: =IF(OR(AQ9="",AR9=""),"",AQ9*AR9) -> 1.1 | AT9: 10 | AU9: =IFERROR(INDEX(WM_L,MATCH($AJ9,WM_KEY,0)),"") -> 0.2 | AV9: =IF(OR(AT9="",AU9=""),"",AT9*AU9) -> 2 | AW9: 12 | AX9: =IFERROR(INDEX(WM_E,MATCH($AJ9,WM_KEY,0)),"") -> 0.05 | AY9: =IF(OR(AW9="",AX9=""),"",AW9*AX9) -> 0.6 | AZ9: 10 | BA9: =IFERROR(INDEX(WM_BI,MATCH($AJ9,WM_KEY,0)),"") -> 0.08 | BB9: =IF(OR(AZ9="",BA9=""),"",AZ9*BA9) -> 0.8 | BC9: =IF(COUNT(AM9,AP9,AS9,AV9,AY9,BB9)<6,"",SUM(AM9,AP9,AS9,AV9,AY9,BB9)) -> 10.1 | BD9: =IF(BC9="","",INDEX({"A1","A2","A3","B1","B2","B3","C1","C2","D1","D2","E1","E2"},MAX(1,MIN(12,ROUND(BC9,0))))) -> D2 | BE9: D1 | BF9: Rule: R11 leadership decision | BG9: Weights: Complexity 37% · Leadership 20% · Autonomy 19% · Accountability 11% · Business impact 8% · Experience 5% Why: leaders are judged on the hardest problems, on leading — 20% — and on the decisions, scope and business impact of the job. Type of work in the department: no adjustment at this level. Live: change the department's row on the Weightage Matrix and these weights, the points and the score update. | BH9: At build: Complexity 3.70 + Autonomy 1.90 + Accountability 1.10 + Leadership 2.00 + Experience 0.60 + Business impact 0.80 = 10.10 points → nearest level 10 = D2 Final level: D1 · a rule applied: see the next column | BI9: • Set at D1 by leadership decision · the model indicated D2: Leadership structure: one level below her manager, the CARBON Business Head. Final level: D1. | BJ9: Input needed | BL9: Low | BM9: • CARBON Leadership Scorecard row 7 assigns services/customer-success revenue to Suman. Confirm identity, accountable functions and delegated resources/decision limits before choosing C2/C3/D1 • No survey answers or KRA — the role factors rest on designation and reporting lines only | BN9: Moves in 30 of 30 weight tests · calibrate first | BO9: Rated 10 of 12 Start: 10.0 · vice president title Evidence: no survey answers or KRAs on file → rating stays at the start Market: D2 = Portfolio-level strategic, financial and regulatory trade-offs | BP9: Rated 10 of 12 Start: 10.0 · vice president title Evidence: no survey answers or KRAs on file → rating stays at the start Market: D2 = Sets direction across business lines | BQ9: Rated 10 of 12 Start: 10.0 · vice president title; 8 direct reports, 121 people in the organisation Evidence: no survey answers or KRAs on file → rating stays at the start Market: D2 = Multi-business results | BR9: Rated 10 of 12 Start: 10.0 Evidence: no survey answers or KRAs on file → rating stays at the start Team: 8 direct reports · People Manager Market: D2 = Builds the leadership team across businesses | BS9: Rated 12 of 12 Experience: 28.7 yrs total · 27.2 before IRIS + 1.5 at IRIS = 12.0 on the experience scale Qualification: B.E · graduate → no change | BT9: Rated 10 of 12 — a starting estimate. Start: 10, the role's accountability scope — what it answers for. No survey or manager-mapping signal on criticality: kept at the start point. Managers and heads: overwrite this rating on the Weightage sheet with the business impact you see — the score updates at once. Ladder: D2 = Owns the results of several business lines | BU9: KRAs not received · manager to supply | BZ9: KRAs not received · manager to supply | CB9: 0 | CC9: No survey response on file | CD9: — | CE9: — | CF9: — | CG9: — | CH9: Complexity: Evidence: no survey answers or KRAs on file → rating stays at the start Autonomy: Evidence: no survey answers or KRAs on file → rating stays at the start Accountability: Evidence: no survey answers or KRAs on file → rating stays at the start Leadership: Evidence: no survey answers or KRAs on file → rating stays at the start Business Impact: No survey or manager-mapping signal on criticality: kept at the start point. | CK9: No survey response on file | CL9: WHAT THE ROLE DOES: Owns a business line or enterprise function end to end. At D1: a business line P&L, region or enterprise function. KEY RESPONSIBILITIES: Owns a business line or enterprise function end to end; Competing strategic, financial and regulatory priorities; Business-line P&L and market position DELIVERS: Business-line P&L and market position DECIDES ALONE: Sets business-line direction, pricing and investment SKILLS & KNOWLEDGE · role-holders: Product Management COMPETENCIES REQUIRED — must-have ★: Strategic Thinking & Business Acumen · People Leadership & Mentoring OTHER FUNCTIONAL COMPETENCIES: Stakeholder & Client Management · Product, Platform & Domain Knowledge · Regulatory & BFSI Domain · Communication & Presentation PROFICIENCY NEEDED AT THIS LEVEL: Core 5 · Future-ready 4 · Functional 4 · Leadership 5 CREDENTIALS: MBA / PGDM · preferred at C+ SOURCE: Framework only · fewer than 3 answered — 2 holders, 0 answered the survey; sub-family 0 answered; catalogue RC-090 | CM9: What the role answers for: Business-line P&L and market position. Accountability & Impact rating: 10 of 12 · D2-level impact. Leads 8 direct reports. From the survey and manager mapping — successor named: yes. Manager talent mapping — Latest rating: Not rated · manager · 9-Box Grid placement: Underperformer / Exit Risk. | CO9: 10 | CP9: Not rated · manager | CQ9: — | CR9: Underperformer / Exit Risk | CS9: No rating data | CU9: CARBON | CV9: Customer Experience | CW9: Succession: Ready-now successor · ready now Vijay Parulekar · C1, CARBON, Shashikant Mudaliar · C1, CARBON · in 6–12 months Anushree Aparajit · C1, CARBON · high potential — | DB9: Not assessed — no survey or KRA evidence | DI9: Required at D2: Core 5 · Future-ready 4 · Functional Business acumen 4 · People leadership 4 · Stakeholder mgmt 4 · Product & domain 4 · Regulatory domain 4 · Communication 4 · Leadership 5 — rate in manager validation using sheet 4. | DK9: Client Engagement | DL9: Strategic Thinking & Business Acumen | DN9: No | DP9: No survey text | DQ9: No survey text | DR9: Within norm | DU9: Senior Vice President – Customer Experience in Customer Experience · CARBON, D1 — People Manager. The work: Owns a business line or enterprise function end to end. At this level the role owns a business line P&L, region or enterprise function. Key responsibilities: Owns a business line or enterprise function end to end; Competing strategic, financial and regulatory priorities; Business-line P&L and market position. Leads 8 direct reports. | DV9: Hire as: Vice President / Senior Vice President / Senior Vice President — IRIS D1 Associate Vice President · People Manager Market level: E1–E2 · SFIA 6–7 Experience: 15–20 yrs · Education: Postgraduate / professional qualification Team size at this level: 5–8 heads Equivalent titles at peers: IRIS Vs Market Benchmark — Aon Radford / Mercer executive codes – E1–E2 VP / Business Head · IRIS Vs Competitor Benchmark — regtech / SaaS executive titles – General Manager / VP Credentials: MBA / PGDM · preferred at C+ Must already know: Governance, risk and regulatory accountability | DW9: FUNCTIONAL — skill level 4 of 5 · Advanced ★ Strategic Thinking & Business Acumen: Shapes strategy, pricing or investment choices ★ People Leadership & Mentoring: Leads leaders; builds succession • Stakeholder & Client Management: Owns key relationships; resolves escalations • Product, Platform & Domain Knowledge: Recognised product / domain expert; trains others • Regulatory & BFSI Domain: Interprets new regulation; advises clients and product • Communication & Presentation: Presents to senior stakeholders; shapes messaging CORE — skill level 5 of 5 · Expert • Ownership & Accountability: Owns business outcomes; builds a culture of accountability • Problem Solving & Critical Thinking: Frames enterprise-level problems; sets the approach for others • Communication & Collaboration: Represents IRIS externally; builds cross-business partnerships • Client & Quality Focus: Defines client and quality strategy for a business • Learning Agility & Adaptability: Anticipates change; builds a learning organisation • Integrity, Compliance & Information Security: Sets ethical and compliance standards for the business FUTURE-READY — skill level 4 of 5 · Advanced • AI Literacy & Augmentation: Designs AI-enabled processes for a team; sets safe-use practices • Data Literacy & Analytics: Defines metrics and dashboards for a team • Digital Fluency & Automation: Automates team processes; selects tools • Innovation & Continuous Improvement: Leads improvement initiatives for a team LEADERSHIP — skill level 5 of 5 · Expert • Leading & Developing People: Builds the leadership pipeline and culture • Decision Making & Delegation: Makes enterprise / business-line decisions • Strategic & Business Acumen: Sets business strategy and P&L direction • Influence & Change Leadership: Leads enterprise change; influences clients, regulators and partners SKILLS · from role-holders and HRIS: Product Management ★ = must-have for the family. Scale: 1 Awareness · 2 Working · 3 Practitioner · 4 Advanced · 5 Expert. | DX9: Draft — generated from the framework; hiring-manager review pending · HR Super Master, sheet T5. 1. [Strategic Thinking & Business Acumen · level 4] Tell me about recent work that shows this: "Shapes strategy, pricing or investment choices". What exactly did you do, how, and what was the result? Assess with: Case interview. 2. [People Leadership & Mentoring · level 4] Tell me about recent work that shows this: "Leads leaders; builds succession". What exactly did you do, how, and what was the result? Assess with: Behavioural interview. 3. [Stakeholder & Client Management · level 4] Give an example that shows you can do this: "Owns key relationships; resolves escalations". Assess with: Role play / behavioural interview. 4. [Product, Platform & Domain Knowledge · level 4] Give an example that shows you can do this: "Recognised product / domain expert; trains others". Assess with: Scenario interview. 5. [Regulatory & BFSI Domain · level 4] Give an example that shows you can do this: "Interprets new regulation; advises clients and product". Assess with: Domain interview. 6. [Ownership & Accountability · level 5] Describe a time you held a team to a standard on an outcome that mattered to the business. How did you make ownership stick? Listen for: "Owns business outcomes; builds a culture of accountability". 7. [Problem Solving & Critical Thinking · level 5] Tell me about an ambiguous, high-stakes problem with no clear answer. How did you frame it and decide? Listen for: "Frames enterprise-level problems; sets the approach for others". 8. [Client & Quality Focus · level 5] Describe how you raised quality or client outcomes across a team or service. How did you measure it? Listen for: "Defines client and quality strategy for a business". 9. [AI Literacy & Augmentation · level 4] Where have you introduced AI or automation into a team's work, and how did you manage the risks? Listen for: "Designs AI-enabled processes for a team; sets safe-use practices". 10. [Leading & Developing People · level 5] Tell me about building a team: who you hired, how you developed them, and a difficult people decision you made. Listen for: "Builds the leadership pipeline and culture". 11. [Decision Making & Delegation · level 5] Tell me about a decision you delegated and one you kept. Why, and what happened? Listen for: "Makes enterprise / business-line decisions". 12. [Strategic & Business Acumen · level 5] Tell me about a strategy or plan you shaped. What trade-offs did you make, and what was the business result? Listen for: "Sets business strategy and P&L direction". 13. [Influence & Change Leadership · level 5] Describe a change you led across teams or the business. How did you deal with resistance? Listen for: "Leads enterprise change; influences clients, regulators and partners". Fit check: Why this role, why IRIS · regulatory reporting / XBRL / regtech, and what would you change in your first 90 days? | DY9: Market level: E1–E2 · SFIA 6–7 Typical title: Vice President / Senior Vice President / Senior Vice President At peers: IRIS Vs Market Benchmark — Aon Radford / Mercer executive codes: E1–E2 VP / Business Head · IRIS Vs Competitor Benchmark — regtech / SaaS executive titles: General Manager / VP Standard: Aon Radford executive levels E1–E6; Mercer ET1–ET3 | DZ9: 15–20 yrs | EA9: — | EB9: Vice President / Senior Vice President / Senior Vice President | EC9: IRIS Vs Market Benchmark — Aon Radford / Mercer executive codes: E1–E2 VP / Business Head · IRIS Vs Competitor Benchmark — regtech / SaaS executive titles: General Manager / VP | ED9: Aon Radford executive levels E1–E6; Mercer ET1–ET3; Korn Ferry Leadership Architect | EE9: Core 5 · Future 4 · Functional 4 · Leadership 5 | EF9: • Survey response or KRAs describing the work · nothing on file — Employee + manager • Resolve conflicting role records — Business head | EG9: ✓ HRIS: 28.7 yrs, B.E, 8 direct reports ✗ Survey: no response ✗ KRAs: none on file ✓ Manager mapping: rating, 9-box — filled from talent-mapping files: 9-box · CARBON grid ✗ Job description: not on file ✓ Validated inputs: Approved level: D2 → D1 · Leadership structure: one level below her manager, the CARBON Business Head · Leadership decision · HR review of 9 Oct 2026 · 2026-10-09 | EH9: D130 · Title to review · Low: Check title against ladder · owner HR · D289 · Input needed · Medium: • Survey response or KRAs describing the work · nothing on file — Employee + manager • Resolve conflicting role records — Business head · owner Employee + manager · Business head · | EI9: R005 · Survey response or KRAs describing the work · nothing on file · Employee + manager · Open R006 · Resolve conflicting role records · Business head · Open | EJ9: Survey response or KRAs describing the work · nothing on file · Employee + manager Resolve conflicting role records · Business head | EK9: Survey: no response · KRAs: not received · Experience: on file
