Workbook

Sheet Start — How It Works
A1: How this exercise works — from a base framework to the final job architecture | E1: ◂ Contents
A2: Read this first: what we did step by step, what is happening now, how the model works, what it produced, the impact — then our framework, the Job Architecture process and the Job Design process. The same page opens every file. For the calibration panel: anchor roles rated blind by two raters and compared with the model, to confirm the weights. No names.
A3: IRIS · Job Architecture & Job Design · Final v1.12 · October 2026 · Internal — Confidential
A5: 1. What we did — step by step
A6: # | B6: Step | C6: What we did | D6: What came out of it
A7: 1 | B7: Created a base framework | C7: Built IRIS's job architecture from established market methods — Aon Radford / Mercer career levels, Korn Ferry Hay factors, WTW banding and SFIA — with job families anchored to the ILO occupation standard. | D7: 19 job families, 61 sub-families, a 12-level ladder plus two Player-Coach steps · B+, C+, six factors, individual-contributor and manager tracks
A8: 2 | B8: Designed a survey around it | C8: The 'How We Grow' survey: 20 questions, each tied to the framework's factors — purpose of the role, what it delivers, what it is accountable for, what it can decide, the skills and tools it needs, and learning needs. | D8: One evidence form for every role, so each rating can be traced to an answer
A9: 3 | B9: Conducted 60–65 workshops | C9: Ran 60–65 workshops with teams across the six products and Corporate: explained the framework, walked through the questions and collected answers in the room. | D9: Survey responses from 520 people
A10: 4 | B10: Gathered the data | C10: Combined the survey with the HRIS employee master, KRAs · self and manager-set, the managers' talent mapping · rating, potential, 9-box and the reporting lines. | D10: One record per person — 586 people; KRAs on file for 453
A11: 5 | B11: Cleaned and protected it | C11: Matched responses to people · with consent where needed, removed personal data, and showed survey content only where three or more role-holders answered — never one person's words against a name. | D11: Privacy-safe evidence
A12: 6 | B12: Mapped every role | C12: Placed each person in a job family, a sub-family · the work they actually do and a track. | D12: 267 distinct employee roles; one IRIS-wide role catalogue
A13: 7 | B13: Rated and scored | C13: Rated six factors — Complexity, Autonomy, Accountability, Leadership, Experience & Qualification, Business Impact — on the ladder scale from the evidence; rating × weight = points; points add up to a score; the score points to a level. | D13: A score and an indicated level for 540 employees
A14: 8 | B14: Applied the rules | C14: Gates, limits and Player-Coach steps where the evidence calls for them, and leadership decisions for the top bands — each one written down with its numbers. | D14: A final level and designation for everyone, every move explained
A15: 9 | B15: Benchmarked to the market | C15: Matched every level to Aon Radford / Mercer codes and SFIA, and to competitor, regtech and SaaS ladders; every source re-read and corrected. | D15: A market code and a typical market title for every level
A16: 10 | B16: Built the file set | C16: One build produces every file from the same data, so they always agree: the HR Super Master, product masters and simplified editions, the framework & model master, the calibration panel pack, the ladder master and draft letters. | D16: Files by audience, rebuilt and re-checked in minutes
A17: 11 | B17: Reviewed and corrected | C17: Business-head review, independent reviews, and 100+ automated checks on every build · placements, privacy, formulas, links, counts. | D17: Corrections fed back as validated inputs, never as hand edits
A19: 2. What we are doing now
A20: Now | C20: What happens | D20: Who
A21: Calibration | C21: The panel rates anchor roles blind and compares them with the model; close calls and moves down are decided. | D21: Calibration panel
A22: Decisions and data | C22: Open decisions and critical data requests are worked in the HR Super Master's tracker. | D22: HR, managers, business heads
A23: Business-head review | C23: Each business head marks Agree / Change / Discuss in their simplified edition; responses are imported and tracked. | D23: Business heads
A24: Sign-off | C24: The executive sponsor approves the structure; then the draft letters are issued. | D24: Executive sponsor, HR
A25: Pay · later | C25: Buy one India pay survey and price each level; pay columns stay blank until then. | D25: HR, Finance
A27: 3. How it works — in one minute
A28: Step | C28: In plain words
A29: 1 · A building with 12 floors | C29: IRIS is a building: floor 1 = first job, floor 12 = CEO; two half floors · B+, C+ for player-coaches. Every job lives on one floor.
A30: 2 · Six judges | C30: Six judges look at the job — How hard? Decides alone? Answers for? Leads? Experience? Business impact? — and each holds up a floor number · the rating, using the evidence: survey, KRAs, HRIS, reporting line.
A31: 3 · Some count more | C31: Starting out, the quality of the work counts most; for leaders, results, leading and business impact count most. Experience counts little. All six add to 100%, and leaders can edit them on the Weightage Matrix.
A32: 4 · Add up = the floor | C32: Card × how much it counts = points; add the points = the score; round it = the floor · 5.05 → 5 → B2. Fair-play checks can hold it — each one written down.
A34: The HR Super Master's sheet '1c. Scoring Made Simple' and the Process Explainer tell this story in full, with three worked examples.
A35: 4. What it produced — the output
A36: Output | D36: Count
A37: People mapped · employees + consultants | D37: 586
A38: Job families · sub-families | D38: 19 · 61
A39: Ladder steps in use · employees | D39: 13
A40: Designations on the new ladder · employees | D40: 184
A41: Distinct employee roles | D41: 267
A42: Products and Corporate | D42: 6
A43: People in leadership bands D–E | D43: 11
A45: 5. The impact
...

Sheet Contents
A1: IRIS Job Architecture — Calibration Panel Pack — contents
A2: Click a sheet name to go there; every sheet has a '◂ Contents' link at the top right to come back.
A3: IRIS · Job Architecture & Job Design · Final v1.12 · October 2026 · Internal — Confidential
A5: # | B5: Sheet | C5: What it holds
A6: 1 | B6: Start — How It Works | C6: Read this first: what we did step by step, what is happening now, how the model works, what it produced, the impact — then our framework, the Job Architecture process and the Job Design process.
A7: 2 | B7: 1. How to Use | C7: Two raters score the same anchor roles independently; the panel resolves differences on evidence; the pack compares the panel's levels with the model's and tells you whether the weights can be frozen for this cycle.
A8: 3 | B8: 2. Level Guide | C8: A rating means the factor is at the size of that level. Read across a row to see what a role at that level owns, decides and answers for.
A9: 4 | B9: 3. Anchor Roles | C9: 23 anchor roles across the ladder and across job families. Titles and levels are hidden so the raters judge the work itself.
A10: 5 | B10: 4. Rater A | C10: 4 · Enter a rating from 1 to 12 · half points allowed for every factor of every anchor, in the yellow cells.
A11: 6 | B11: 5. Rater B | C11: 5 · Enter a rating from 1 to 12 · half points allowed for every factor of every anchor, in the yellow cells.
A12: 7 | B12: 6. Comparison & Result | C12: Raters' ratings side by side; red = more than one point apart · discuss on evidence and enter the consensus in yellow; blank consensus = the average of the two.

Sheet 1. How to Use
A1: Calibration panel pack — testing the weights on anchor roles | E1: ◂ Contents
A2: Sheet 1 · Two raters score the same anchor roles independently; the panel resolves differences on evidence; the pack compares the panel's levels with the model's and tells you whether the weights can be frozen for this cycle.
A3: IRIS · Job Architecture & Job Design · Final v1.12 · October 2026 · Internal — Confidential
A5: The steps
A6: # | B6: Step | C6: What to do
A7: 1 | B7: Read the level guide | C7: Sheet 2 explains what each rating means for every factor · the same scale as the ladder: A1 = 1 … E2 = 12.
A8: 2 | B8: Read the anchor roles | C8: Sheet 3 describes 23 anchor roles by their work only — no titles, no levels — so you judge the work, not the label.
A9: 3 | B9: Rate independently | C9: Rater A uses sheet 4, Rater B sheet 5. Rate each factor · whole or half points in the yellow cells. Do not look at the other rater's sheet or at sheet 6 yet.
A10: 4 | B10: Compare | C10: Sheet 6 shows every factor where the raters differ by more than one point · red. Discuss those on evidence and enter the panel's consensus rating — never average a disagreement.
A11: 5 | B11: Read the result | C11: Sheet 6 scores the consensus with the model's weights for that role and compares the panel's level with the model's. The summary at the top says whether the weights are confirmed.
A12: 6 | B12: Act | C12: Weights confirmed: freeze them for the cycle. Not confirmed: look at which factor drives the gaps, adjust the weight model, rebuild, and re-run the weight-sensitivity test.
A14: Decision rule
A15: Measure | C15: Threshold | D15: Meaning
A16: Rater agreement | C16: ≥ 80% of factor ratings within 1 point | D16: The scale is being read the same way by both raters
A17: Level agreement | C17: ≥ 80% of anchors within one step of the model's level | D17: The weights reproduce what experienced people judge the role to be
A18: Both met | C18: Weights confirmed | D18: Freeze the weights for this cycle
A20: Ground rules
A21: • Rate the role as described, not a person you know in it.
A22: • Use the whole scale: a rating can sit above or below the level you expect overall.
A23: • Do not count the same demand twice · complexity is how hard the problems are; accountability is what the role answers for.
A24: • Access to senior people is not authority; tenure alone is not experience the role needs.

Sheet 2. Level Guide
A1: Level guide — what each rating means | J1: ◂ Contents
A2: Sheet 2 · A rating means the factor is at the size of that level. Read across a row to see what a role at that level owns, decides and answers for.
A3: IRIS · Job Architecture & Job Design · Final v1.12 · October 2026 · Internal — Confidential
A5: Rating | B5: Level | C5: What the role owns | D5: Complexity | E5: Autonomy | F5: Accountability | G5: Leadership | H5: Experience | I5: Bus. impact
A6: 1 | B6: A1 | C6: Learning the role; all work reviewed | D6: Learning; follows worked examples | E6: Needs approval / close guidance | F6: Learning tasks | G6: Not scored in Band A | H6: No experience yet | I6: Learning; little direct effect on business results yet
A7: 2 | B7: A2 | C7: Standard work delivered independently | D7: Standard work of the discipline | E7: Chooses own approach within standards | F7: Own deliverables · accuracy, TAT | G7: Not scored in Band A | H7: About 1 yr of total experience; relevant professional or postgraduate qualification counts in addition | I7: Own deliverables feed a team's output and turnaround
A8: 3 | B8: A3 | C8: Varied work; reviews juniors; go-to for a process | D8: Varied and non-standard work; handles exceptions | E8: Technical / QC / client calls on own work | F8: A module / process, or work with client or regulatory consequences | G8: Not scored in Band A | H8: About 3 yrs of total experience; relevant professional or postgraduate qualification counts in addition | I8: A process or client deliverable depends on this work
A9: 4 | B9: B1 | C9: A domain / module, or a small team | D9: Domain specialist work | E9: Technical / QC / client calls for the domain | F9: A domain or a small team | G9: IC: mentors and reviews · People: hands-on team lead of 3–5 | H9: About 5.5 yrs of total experience; relevant professional or postgraduate qualification counts in addition | I9: Moves a module's, product area's or client account's results
A10: 5 | B10: B2 | C10: Deep domain expertise, or one team | D10: Hardest problems in the domain | E10: Allocates people and sets team priorities | F10: One team or a client portfolio | G10: IC: guides others in the domain · People: manages a team of 6+ | H10: About 7.5 yrs of total experience; relevant professional or postgraduate qualification counts in addition | I10: Visible effect on a team's or client portfolio's revenue, quality or compliance
A11: 6 | B11: B3 | C11: A practice, or several teams through team leads | D11: Sets standards for a practice; cross-team problems | E11: Commercial / strategic calls for the unit | F11: Several teams or a practice | G11: IC: leads a practice · People: team leads / managers report in | H11: About 10 yrs of total experience; relevant professional or postgraduate qualification counts in addition | I11: Shapes the results of a practice or several teams
A12: 7 | B12: C1 | C12: A sub-function, or principal authority across products | D12: Ambiguous, cross-product problems | E12: Sets direction for a sub-function or domain | F12: Sub-function results or domain quality across products | G12: Leads managers or a community of practice | H12: About 12 yrs of total experience; relevant professional or postgraduate qualification counts in addition | I12: Changes results across a sub-function or across products
A13: 8 | B13: C2 | C13: A function or department, or a company-wide discipline | D13: Function-wide or company-wide problems; creates methods and standards | E13: Sets direction for a function | F13: Function results, budget and risk | G13: Leads a function; shapes functional strategy | H13: About 14.5 yrs of total experience; relevant professional or postgraduate qualification counts in addition | I13: Drives a function's or department's results and costs
A14: 9 | B14: D1 | C14: A business line P&L, region or enterprise function | D14: Competing strategic, financial and regulatory priorities | E14: Sets business-line direction, pricing and investment | F14: Business-line P&L and market position | G14: Defines business strategy; builds the leadership bench | H14: About 17.5 yrs of total experience; relevant professional or postgraduate qualification counts in addition | I14: Owns a business line's P&L and growth, or a company-wide function
A15: 10 | B15: D2 | C15: Several business lines or an executive-scope enterprise function | D15: Portfolio-level strategic, financial and regulatory trade-offs | E15: Sets direction across business lines | F15: Multi-business results | G15: Builds the leadership team across businesses | H15: About 21 yrs of total experience; relevant professional or postgraduate qualification counts in addition | I15: Owns the results of several business lines
A16: 11 | B16: E1 | C16: An enterprise-wide function | D16: Enterprise-level functional strategy | E16: Sets enterprise priorities for the function | F16: Enterprise-wide functional results | G16: Shapes enterprise strategy | H16: About 24 yrs of total experience; relevant professional or postgraduate qualification counts in addition | I16: Shapes company-wide results through a function
A17: 12 | B17: E2 | C17: The enterprise | D17: Enterprise-wide uncertainty, transformation and external forces | E17: Accountable to the board | F17: Enterprise results, risk, culture and long-term viability | G17: Sets enterprise strategy; leads the executive team | H17: About 28 yrs of total experience; relevant professional or postgraduate qualification counts in addition | I17: Answers for the whole company's results and long-term value
A19: Half points are allowed where a factor sits between two levels.

Sheet 3. Anchor Roles
A1: Anchor roles — described by their work, not their title | H1: ◂ Contents
A2: Sheet 3 · 23 anchor roles across the ladder and across job families. Titles and levels are hidden so the raters judge the work itself.
A3: IRIS · Job Architecture & Job Design · Final v1.12 · October 2026 · Internal — Confidential
A6: Anchor | B6: Job family | C6: Sub-family | D6: The work · sub-family definition | E6: What holders and managers say the role does · counted themes | F6: Skills · counted | G6: Facts
A7: AR-01 | B7: Engineering & Development | C7: Backend Development | D7: Builds back-end services, APIs, processing/validation logic and DB code; fixes defects and delivers change requests. | E7: Themes from role-holders' answers: software · time · maintain · take · solutions · efficiency Themes from role-holders' answers: fixing · quality · bug · development · client · code Common themes in manager-set KRAs: improve · deliver · modules · committed · coverage · automated | F7: NET MVC · Java | G7: Track: individual contributor · holders' total experience: 0–2 yrs · 7 holders
A8: AR-02 | B8: Engineering & Development | C8: Front-End / UI Development | D8: Builds user interfaces and reusable UI components. | E8: Themes from role-holders' answers: solutions · maintain · problems · core · purpose · while Themes from role-holders' answers: feature · code · quality · development · delivery Common themes in manager-set KRAs: complete · improve · assigned · resolve · code · leakage qa/uat | F8: Angular · React | G8: Track: individual contributor · holders' total experience: 0–2 yrs · 6 holders
A9: AR-03 | B9: Marketing & Communications | C9: Content Marketing | D9: Writes blogs, web copy, collateral and social content. | E9: Themes from role-holders' answers: content · marketing · leads · generate · management · creation Themes from role-holders' answers: content · blogs · week · campaign | F9: Marketing · Research skills | G9: Track: individual contributor · holders' total experience: 0–2 yrs · 5 holders
A10: AR-04 | B10: Consulting & Professional Services | C10: XBRL Tagging, Conversion & Filing | D10: Tags and converts financial statements and regulatory returns into XBRL/iXBRL, performs QC, clears validation errors and delivers filing-ready outputs. | E10: Themes from role-holders' answers: financial · accurately · tagging · reporting · us · core Themes from role-holders' answers: tagging · quality · validation · filing · resolution · financial Common themes in manager-set KRAs: resolve · full · coverage · cycles · defect · xbrl | F10: XBRL Domain · Taxonomy knowledge · attention to detail · validation · Problem-solving · filing procedures · XBRL concepts · QC | G10: Track: individual contributor · holders' total experience: 12–16 yrs · 38 holders
A11: AR-05 | B11: Data Operations & Digitization | C11: Document Conversion, Formatting & Web Publishing | D11: Converts and formats documents into HTML/PDF/Word to filing or web standards, and publishes content · incl. RBI website. | E11: Themes from role-holders' answers: purpose · core · quality · formatting · accuracy · information Themes from role-holders' answers: document · quality · formatting · accuracy · checks · conversion | F11: OCR/Image procesing · attention to detail · Excel · quality checking · HTML · timely delivery · OCR · Word | G11: Track: individual contributor · holders' total experience: 5–8 yrs · 20 holders
A12: AR-06 | B12: Quality Assurance | C12: Functional & Domain Testing | D12: Designs and executes functional, regression and domain/AI-feature test cases; logs defects; supports sign-off. | E12: Themes from role-holders' answers: software · product · user · quality · works · requirements Themes from role-holders' answers: test · regression · defect · case · reporting · execution Common themes in manager-set KRAs: project · qa · quality · production · knowledge · test | F12: Software testing · regression testing · Test case design · Manual Testing · Execution · Test case execution | G12: Track: individual contributor · holders' total experience: 5–8 yrs · 20 holders
A13: AR-07 | B13: Consulting & Professional Services | C13: XBRL Tagging, Conversion & Filing | D13: Tags and converts financial statements and regulatory returns into XBRL/iXBRL, performs QC, clears validation errors and delivers filing-ready outputs. | E13: Themes from role-holders' answers: reporting · financial · mandate · timely · while · us Themes from role-holders' answers: tagging · validation · quality · mapping · management · filing | F13: XBRL Domain · Attention to detail · Advanced XBRL Mapping knowledge · Different region Taxonomy Knowledge · Financial Reporting Standards (US-GAAP · IFRS · Validations · US mandate/process knowledge | G13: Track: individual contributor · holders' total experience: 12–16 yrs · 10 holders
A14: AR-08 | B14: Business Analysis | C14: Business Analysis | D14: Gathers and documents requirements · BRD/FRD/SRS/user stories, configures solutions and supports UAT and releases. | E14: Themes from role-holders' answers: business · smooth · between · client · am · requirements Themes from role-holders' answers: requirement · stakeholder · gathering · client · project · portfolio Common themes in manager-set KRAs: releases · satisfaction · delivery · assigned · uat · requirement | F14: Business Analysis | G14: Track: individual contributor · holders' total experience: 8–12 yrs · 7 holders
A15: AR-09 | B15: Product Management | C15: Product Management | D15: Owns product vision, roadmap, requirements · PRDs, prioritisation and adoption. | E15: Themes from role-holders' answers: product · management · customers · roadmap · shape · stakeholder Themes from role-holders' answers: research · demos · product · management · customer · analysis | F15: Product Management · Project management · Product sense · Market research · CA + CE | G15: Track: individual contributor · holders' total experience: 5–8 yrs · 5 holders
A16: AR-10 | B16: Project & Program Management | C16: Project & Program Delivery | D16: Plans and delivers projects/programmes to scope, time and cost; manages CRs, risks and stakeholders. | E16: Themes from role-holders' answers: project · management · support · business · stakeholder · client Themes from role-holders' answers: client · management · project · delivery · documentation Common themes in manager-set KRAs: project · management · level · support · scope · client | F16: Project Management · Stakeholder management | G16: Track: manages a team · typical team: 3–5 direct reports · holders' total experience: 12–16 yrs · 7 holders
A17: AR-11 | B17: Customer Success & Support | C17: Customer Success & Account Management | D17: Owns client relationships after sale — hypercare, renewals, upsell, CSAT/NPS, delivery follow-through. | E17: Themes from role-holders' answers: cross improve · upsell cross · nps follow · tech · improve nps · us market Themes from role-holders' answers: product · renewals · upsell · cross sell · update · testing | F17: XBRL Domain | G17: Track: individual contributor · holders' total experience: 12–16 yrs · 5 holders
... A29: AR-23 | B29: Executive Leadership | C29: Business & Functional Leadership | D29: Owns a business line or enterprise function end to end. | E29: No common theme recorded | F29: Product Management | G29: Track: manages a team · typical team: 6–10 direct reports · holders' total experience: 16–20 yrs · 3 holders

Sheet 4. Rater A
A1: Rater A — rate each factor | J1: ◂ Contents
A2: 4 · Enter a rating from 1 to 12 · half points allowed for every factor of every anchor, in the yellow cells. Use the level guide. Do not look at the other rater's sheet or at sheet 6 until you have finished.
A3: IRIS · Job Architecture & Job Design · Final v1.12 · October 2026 · Internal — Confidential
A6: Anchor | B6: Sub-family | C6: Complexity & Expertise | D6: Autonomy & Decision | E6: Accountability & Impact | F6: Leadership & Strategy | G6: Experience & Qualification | H6: Business Impact | I6: Notes / evidence
A7: AR-01 | B7: Backend Development
A8: AR-02 | B8: Front-End / UI Development
A9: AR-03 | B9: Content Marketing
A10: AR-04 | B10: XBRL Tagging, Conversion & Filing
A11: AR-05 | B11: Document Conversion, Formatting & Web Publishing
A12: AR-06 | B12: Functional & Domain Testing
A13: AR-07 | B13: XBRL Tagging, Conversion & Filing
A14: AR-08 | B14: Business Analysis
A15: AR-09 | B15: Product Management
A16: AR-10 | B16: Project & Program Delivery
A17: AR-11 | B17: Customer Success & Account Management
A18: AR-12 | B18: Product Management
... A29: AR-23 | B29: Business & Functional Leadership

Sheet 5. Rater B
A1: Rater B — rate each factor | J1: ◂ Contents
A2: 5 · Enter a rating from 1 to 12 · half points allowed for every factor of every anchor, in the yellow cells. Use the level guide. Do not look at the other rater's sheet or at sheet 6 until you have finished.
A3: IRIS · Job Architecture & Job Design · Final v1.12 · October 2026 · Internal — Confidential
A6: Anchor | B6: Sub-family | C6: Complexity & Expertise | D6: Autonomy & Decision | E6: Accountability & Impact | F6: Leadership & Strategy | G6: Experience & Qualification | H6: Business Impact | I6: Notes / evidence
A7: AR-01 | B7: Backend Development
A8: AR-02 | B8: Front-End / UI Development
A9: AR-03 | B9: Content Marketing
A10: AR-04 | B10: XBRL Tagging, Conversion & Filing
A11: AR-05 | B11: Document Conversion, Formatting & Web Publishing
A12: AR-06 | B12: Functional & Domain Testing
A13: AR-07 | B13: XBRL Tagging, Conversion & Filing
A14: AR-08 | B14: Business Analysis
A15: AR-09 | B15: Product Management
A16: AR-10 | B16: Project & Program Delivery
A17: AR-11 | B17: Customer Success & Account Management
A18: AR-12 | B18: Product Management
... A29: AR-23 | B29: Business & Functional Leadership

Sheet 6. Comparison & Result
A1: Comparison and result — do the weights hold? | AN1: ◂ Contents
A2: Sheet 6 · Raters' ratings side by side; red = more than one point apart · discuss on evidence and enter the consensus in yellow; blank consensus = the average of the two. The consensus is scored with the model's weights for each role and compared with the model's level.
A3: IRIS · Job Architecture & Job Design · Final v1.12 · October 2026 · Internal — Confidential
A4: Rater agreement · factor ratings within 1 point | D4: =IFERROR(COUNTIF(P7:U29,"<=1")/COUNT(P7:U29),"") | E4: Anchors rated by both | G4: =COUNT(AH7:AH29) -> 0 | H4: Level agreement · within one step of the model | J4: =IFERROR(COUNTIF(AM7:AM29,"Yes")/(COUNTIF(AM7:AM29,"Yes")+COUNTIF(AM7:AM29,"No")),"") | K4: Same level as the model | M4: =IFERROR(COUNTIF(AL7:AL29,0)/MAX(1,COUNT(AL7:AL29)),"") -> 0 | N4: Result | P4: =IF(COUNT(AH7:AH29)=0,"Waiting for ratings",IF(AND(D4>=0.8,J4>=0.8),"Weights confirmed — freeze for this cycle","Review the weights: see the red cells and the rows marked No")) -> Waiting for ratings
A6: Anchor | B6: Sub-family | C6: Title · model | D6: A · Complexity | E6: A · Autonomy | F6: A · Accountability | G6: A · Leadership | H6: A · Experience | I6: A · Bus. impact | J6: B · Complexity | K6: B · Autonomy | L6: B · Accountability | M6: B · Leadership | N6: B · Experience | O6: B · Bus. impact | P6: Gap · Complexity | Q6: Gap · Autonomy | R6: Gap · Accountability | S6: Gap · Leadership | T6: Gap · Experience | U6: Gap · Bus. impact | V6: Consensus · Complexity | W6: Consensus · Autonomy | X6: Consensus · Accountability | Y6: Consensus · Leadership | Z6: Consensus · Experience | AA6: Consensus · Bus. impact | AB6: Weight · Complexity | AC6: Weight · Autonomy | AD6: Weight · Accountability | AE6: Weight · Leadership | AF6: Weight · Experience | AG6: Weight · Bus. impact | AH6: Panel score | AI6: Panel level | AJ6: Model score | AK6: Model level | AL6: Steps apart | AM6: Within one step
A7: AR-01 | B7: Backend Development | C7: Software Engineer | D7: =IF('4. Rater A'!C7="","",'4. Rater A'!C7) | E7: =IF('4. Rater A'!D7="","",'4. Rater A'!D7) | F7: =IF('4. Rater A'!E7="","",'4. Rater A'!E7) | G7: =IF('4. Rater A'!F7="","",'4. Rater A'!F7) | H7: =IF('4. Rater A'!G7="","",'4. Rater A'!G7) | I7: =IF('4. Rater A'!H7="","",'4. Rater A'!H7) | J7: =IF('5. Rater B'!C7="","",'5. Rater B'!C7) | K7: =IF('5. Rater B'!D7="","",'5. Rater B'!D7) | L7: =IF('5. Rater B'!E7="","",'5. Rater B'!E7) | M7: =IF('5. Rater B'!F7="","",'5. Rater B'!F7) | N7: =IF('5. Rater B'!G7="","",'5. Rater B'!G7) | O7: =IF('5. Rater B'!H7="","",'5. Rater B'!H7) | P7: =IF(OR(D7="",J7=""),"",ABS(D7-J7)) | Q7: =IF(OR(E7="",K7=""),"",ABS(E7-K7)) | R7: =IF(OR(F7="",L7=""),"",ABS(F7-L7)) | S7: =IF(OR(G7="",M7=""),"",ABS(G7-M7)) | T7: =IF(OR(H7="",N7=""),"",ABS(H7-N7)) | U7: =IF(OR(I7="",O7=""),"",ABS(I7-O7)) | AB7: 0.64 | AC7: 0.16 | AD7: 0.04 | AE7: 0 | AF7: 0.1 | AG7: 0.06 | AH7: =IF(OR((IF(V7<>"",V7,IF(OR(D7="",J7=""),"",(D7+J7)/2)))="",(IF(W7<>"",W7,IF(OR(E7="",K7=""),"",(E7+K7)/2)))="",(IF(X7<>"",X7,IF(OR(F7="",L7=""),"",(F7+L7)/2)))="",(IF(Y7<>"",Y7,IF(OR(G7="",M7=""),"",(G7+M7)/2)))="",(IF(Z7<>"",Z7,IF(OR(H7="",N7=""),"",(H7+N7)/2)))="",(IF(AA7<>"",AA7,IF(OR(I7="",O7=""),"",(I7+O7)/2)))=""),"",(IF(V7<>"",V7,IF(OR(D7="",J7=""),"",(D7+J7)/2)))*AB7+(IF(W7<>"",W7,IF(OR(E7="",K7=""),"",(E7+K7)/2)))*AC7+(IF(X7<>"",X7,IF(OR(F7="",L7=""),"",(F7+L7)/2)))*AD7+(IF(Y7<>"",Y7,IF(OR(G7="",M7=""),"",(G7+M7)/2)))*AE7+(IF(Z7<>"",Z7,IF(OR(H7="",N7=""),"",(H7+N7)/2)))*AF7+(IF(AA7<>"",AA7,IF(OR(I7="",O7=""),"",(I7+O7)/2)))*AG7) | AI7: =IF(AH7="","",INDEX({"A1","A2","A3","B1","B2","B3","C1","C2","D1","D2","E1","E2"},MAX(1,MIN(12,ROUND(AH7,0))))) | AJ7: 1.9 | AK7: A2 | AL7: =IF(AH7="","",ROUND(MAX(1,MIN(12,ROUND(AH7,0)))-2,1)) | AM7: =IF(AL7="","",IF(ABS(AL7)<=1,"Yes","No"))
A8: AR-02 | B8: Front-End / UI Development | C8: UI Developer | D8: =IF('4. Rater A'!C8="","",'4. Rater A'!C8) | E8: =IF('4. Rater A'!D8="","",'4. Rater A'!D8) | F8: =IF('4. Rater A'!E8="","",'4. Rater A'!E8) | G8: =IF('4. Rater A'!F8="","",'4. Rater A'!F8) | H8: =IF('4. Rater A'!G8="","",'4. Rater A'!G8) | I8: =IF('4. Rater A'!H8="","",'4. Rater A'!H8) | J8: =IF('5. Rater B'!C8="","",'5. Rater B'!C8) | K8: =IF('5. Rater B'!D8="","",'5. Rater B'!D8) | L8: =IF('5. Rater B'!E8="","",'5. Rater B'!E8) | M8: =IF('5. Rater B'!F8="","",'5. Rater B'!F8) | N8: =IF('5. Rater B'!G8="","",'5. Rater B'!G8) | O8: =IF('5. Rater B'!H8="","",'5. Rater B'!H8) | P8: =IF(OR(D8="",J8=""),"",ABS(D8-J8)) | Q8: =IF(OR(E8="",K8=""),"",ABS(E8-K8)) | R8: =IF(OR(F8="",L8=""),"",ABS(F8-L8)) | S8: =IF(OR(G8="",M8=""),"",ABS(G8-M8)) | T8: =IF(OR(H8="",N8=""),"",ABS(H8-N8)) | U8: =IF(OR(I8="",O8=""),"",ABS(I8-O8)) | AB8: 0.64 | AC8: 0.16 | AD8: 0.04 | AE8: 0 | AF8: 0.1 | AG8: 0.06 | AH8: =IF(OR((IF(V8<>"",V8,IF(OR(D8="",J8=""),"",(D8+J8)/2)))="",(IF(W8<>"",W8,IF(OR(E8="",K8=""),"",(E8+K8)/2)))="",(IF(X8<>"",X8,IF(OR(F8="",L8=""),"",(F8+L8)/2)))="",(IF(Y8<>"",Y8,IF(OR(G8="",M8=""),"",(G8+M8)/2)))="",(IF(Z8<>"",Z8,IF(OR(H8="",N8=""),"",(H8+N8)/2)))="",(IF(AA8<>"",AA8,IF(OR(I8="",O8=""),"",(I8+O8)/2)))=""),"",(IF(V8<>"",V8,IF(OR(D8="",J8=""),"",(D8+J8)/2)))*AB8+(IF(W8<>"",W8,IF(OR(E8="",K8=""),"",(E8+K8)/2)))*AC8+(IF(X8<>"",X8,IF(OR(F8="",L8=""),"",(F8+L8)/2)))*AD8+(IF(Y8<>"",Y8,IF(OR(G8="",M8=""),"",(G8+M8)/2)))*AE8+(IF(Z8<>"",Z8,IF(OR(H8="",N8=""),"",(H8+N8)/2)))*AF8+(IF(AA8<>"",AA8,IF(OR(I8="",O8=""),"",(I8+O8)/2)))*AG8) | AI8: =IF(AH8="","",INDEX({"A1","A2","A3","B1","B2","B3","C1","C2","D1","D2","E1","E2"},MAX(1,MIN(12,ROUND(AH8,0))))) | AJ8: 2.08 | AK8: A2 | AL8: =IF(AH8="","",ROUND(MAX(1,MIN(12,ROUND(AH8,0)))-2,1)) | AM8: =IF(AL8="","",IF(ABS(AL8)<=1,"Yes","No"))
A9: AR-03 | B9: Content Marketing | C9: Content Marketing Associate | D9: =IF('4. Rater A'!C9="","",'4. Rater A'!C9) | E9: =IF('4. Rater A'!D9="","",'4. Rater A'!D9) | F9: =IF('4. Rater A'!E9="","",'4. Rater A'!E9) | G9: =IF('4. Rater A'!F9="","",'4. Rater A'!F9) | H9: =IF('4. Rater A'!G9="","",'4. Rater A'!G9) | I9: =IF('4. Rater A'!H9="","",'4. Rater A'!H9) | J9: =IF('5. Rater B'!C9="","",'5. Rater B'!C9) | K9: =IF('5. Rater B'!D9="","",'5. Rater B'!D9) | L9: =IF('5. Rater B'!E9="","",'5. Rater B'!E9) | M9: =IF('5. Rater B'!F9="","",'5. Rater B'!F9) | N9: =IF('5. Rater B'!G9="","",'5. Rater B'!G9) | O9: =IF('5. Rater B'!H9="","",'5. Rater B'!H9) | P9: =IF(OR(D9="",J9=""),"",ABS(D9-J9)) | Q9: =IF(OR(E9="",K9=""),"",ABS(E9-K9)) | R9: =IF(OR(F9="",L9=""),"",ABS(F9-L9)) | S9: =IF(OR(G9="",M9=""),"",ABS(G9-M9)) | T9: =IF(OR(H9="",N9=""),"",ABS(H9-N9)) | U9: =IF(OR(I9="",O9=""),"",ABS(I9-O9)) | AB9: 0.54 | AC9: 0.21 | AD9: 0.04 | AE9: 0 | AF9: 0.1 | AG9: 0.11 | AH9: =IF(OR((IF(V9<>"",V9,IF(OR(D9="",J9=""),"",(D9+J9)/2)))="",(IF(W9<>"",W9,IF(OR(E9="",K9=""),"",(E9+K9)/2)))="",(IF(X9<>"",X9,IF(OR(F9="",L9=""),"",(F9+L9)/2)))="",(IF(Y9<>"",Y9,IF(OR(G9="",M9=""),"",(G9+M9)/2)))="",(IF(Z9<>"",Z9,IF(OR(H9="",N9=""),"",(H9+N9)/2)))="",(IF(AA9<>"",AA9,IF(OR(I9="",O9=""),"",(I9+O9)/2)))=""),"",(IF(V9<>"",V9,IF(OR(D9="",J9=""),"",(D9+J9)/2)))*AB9+(IF(W9<>"",W9,IF(OR(E9="",K9=""),"",(E9+K9)/2)))*AC9+(IF(X9<>"",X9,IF(OR(F9="",L9=""),"",(F9+L9)/2)))*AD9+(IF(Y9<>"",Y9,IF(OR(G9="",M9=""),"",(G9+M9)/2)))*AE9+(IF(Z9<>"",Z9,IF(OR(H9="",N9=""),"",(H9+N9)/2)))*AF9+(IF(AA9<>"",AA9,IF(OR(I9="",O9=""),"",(I9+O9)/2)))*AG9) | AI9: =IF(AH9="","",INDEX({"A1","A2","A3","B1","B2","B3","C1","C2","D1","D2","E1","E2"},MAX(1,MIN(12,ROUND(AH9,0))))) | AJ9: 2.08 | AK9: A2 | AL9: =IF(AH9="","",ROUND(MAX(1,MIN(12,ROUND(AH9,0)))-2,1)) | AM9: =IF(AL9="","",IF(ABS(AL9)<=1,"Yes","No"))
A10: AR-04 | B10: XBRL Tagging, Conversion & Filing | C10: Senior Financial Analyst | D10: =IF('4. Rater A'!C10="","",'4. Rater A'!C10) | E10: =IF('4. Rater A'!D10="","",'4. Rater A'!D10) | F10: =IF('4. Rater A'!E10="","",'4. Rater A'!E10) | G10: =IF('4. Rater A'!F10="","",'4. Rater A'!F10) | H10: =IF('4. Rater A'!G10="","",'4. Rater A'!G10) | I10: =IF('4. Rater A'!H10="","",'4. Rater A'!H10) | J10: =IF('5. Rater B'!C10="","",'5. Rater B'!C10) | K10: =IF('5. Rater B'!D10="","",'5. Rater B'!D10) | L10: =IF('5. Rater B'!E10="","",'5. Rater B'!E10) | M10: =IF('5. Rater B'!F10="","",'5. Rater B'!F10) | N10: =IF('5. Rater B'!G10="","",'5. Rater B'!G10) | O10: =IF('5. Rater B'!H10="","",'5. Rater B'!H10) | P10: =IF(OR(D10="",J10=""),"",ABS(D10-J10)) | Q10: =IF(OR(E10="",K10=""),"",ABS(E10-K10)) | R10: =IF(OR(F10="",L10=""),"",ABS(F10-L10)) | S10: =IF(OR(G10="",M10=""),"",ABS(G10-M10)) | T10: =IF(OR(H10="",N10=""),"",ABS(H10-N10)) | U10: =IF(OR(I10="",O10=""),"",ABS(I10-O10)) | AB10: 0.54 | AC10: 0.16 | AD10: 0.14 | AE10: 0 | AF10: 0.1 | AG10: 0.06 | AH10: =IF(OR((IF(V10<>"",V10,IF(OR(D10="",J10=""),"",(D10+J10)/2)))="",(IF(W10<>"",W10,IF(OR(E10="",K10=""),"",(E10+K10)/2)))="",(IF(X10<>"",X10,IF(OR(F10="",L10=""),"",(F10+L10)/2)))="",(IF(Y10<>"",Y10,IF(OR(G10="",M10=""),"",(G10+M10)/2)))="",(IF(Z10<>"",Z10,IF(OR(H10="",N10=""),"",(H10+N10)/2)))="",(IF(AA10<>"",AA10,IF(OR(I10="",O10=""),"",(I10+O10)/2)))=""),"",(IF(V10<>"",V10,IF(OR(D10="",J10=""),"",(D10+J10)/2)))*AB10+(IF(W10<>"",W10,IF(OR(E10="",K10=""),"",(E10+K10)/2)))*AC10+(IF(X10<>"",X10,IF(OR(F10="",L10=""),"",(F10+L10)/2)))*AD10+(IF(Y10<>"",Y10,IF(OR(G10="",M10=""),"",(G10+M10)/2)))*AE10+(IF(Z10<>"",Z10,IF(OR(H10="",N10=""),"",(H10+N10)/2)))*AF10+(IF(AA10<>"",AA10,IF(OR(I10="",O10=""),"",(I10+O10)/2)))*AG10) | AI10: =IF(AH10="","",INDEX({"A1","A2","A3","B1","B2","B3","C1","C2","D1","D2","E1","E2"},MAX(1,MIN(12,ROUND(AH10,0))))) | AJ10: 3.08 | AK10: A3 | AL10: =IF(AH10="","",ROUND(MAX(1,MIN(12,ROUND(AH10,0)))-3,1)) | AM10: =IF(AL10="","",IF(ABS(AL10)<=1,"Yes","No"))
A11: AR-05 | B11: Document Conversion, Formatting & Web Publishing | C11: Senior Digitization Associate | D11: =IF('4. Rater A'!C11="","",'4. Rater A'!C11) | E11: =IF('4. Rater A'!D11="","",'4. Rater A'!D11) | F11: =IF('4. Rater A'!E11="","",'4. Rater A'!E11) | G11: =IF('4. Rater A'!F11="","",'4. Rater A'!F11) | H11: =IF('4. Rater A'!G11="","",'4. Rater A'!G11) | I11: =IF('4. Rater A'!H11="","",'4. Rater A'!H11) | J11: =IF('5. Rater B'!C11="","",'5. Rater B'!C11) | K11: =IF('5. Rater B'!D11="","",'5. Rater B'!D11) | L11: =IF('5. Rater B'!E11="","",'5. Rater B'!E11) | M11: =IF('5. Rater B'!F11="","",'5. Rater B'!F11) | N11: =IF('5. Rater B'!G11="","",'5. Rater B'!G11) | O11: =IF('5. Rater B'!H11="","",'5. Rater B'!H11) | P11: =IF(OR(D11="",J11=""),"",ABS(D11-J11)) | Q11: =IF(OR(E11="",K11=""),"",ABS(E11-K11)) | R11: =IF(OR(F11="",L11=""),"",ABS(F11-L11)) | S11: =IF(OR(G11="",M11=""),"",ABS(G11-M11)) | T11: =IF(OR(H11="",N11=""),"",ABS(H11-N11)) | U11: =IF(OR(I11="",O11=""),"",ABS(I11-O11)) | AB11: 0.54 | AC11: 0.16 | AD11: 0.14 | AE11: 0 | AF11: 0.1 | AG11: 0.06 | AH11: =IF(OR((IF(V11<>"",V11,IF(OR(D11="",J11=""),"",(D11+J11)/2)))="",(IF(W11<>"",W11,IF(OR(E11="",K11=""),"",(E11+K11)/2)))="",(IF(X11<>"",X11,IF(OR(F11="",L11=""),"",(F11+L11)/2)))="",(IF(Y11<>"",Y11,IF(OR(G11="",M11=""),"",(G11+M11)/2)))="",(IF(Z11<>"",Z11,IF(OR(H11="",N11=""),"",(H11+N11)/2)))="",(IF(AA11<>"",AA11,IF(OR(I11="",O11=""),"",(I11+O11)/2)))=""),"",(IF(V11<>"",V11,IF(OR(D11="",J11=""),"",(D11+J11)/2)))*AB11+(IF(W11<>"",W11,IF(OR(E11="",K11=""),"",(E11+K11)/2)))*AC11+(IF(X11<>"",X11,IF(OR(F11="",L11=""),"",(F11+L11)/2)))*AD11+(IF(Y11<>"",Y11,IF(OR(G11="",M11=""),"",(G11+M11)/2)))*AE11+(IF(Z11<>"",Z11,IF(OR(H11="",N11=""),"",(H11+N11)/2)))*AF11+(IF(AA11<>"",AA11,IF(OR(I11="",O11=""),"",(I11+O11)/2)))*AG11) | AI11: =IF(AH11="","",INDEX({"A1","A2","A3","B1","B2","B3","C1","C2","D1","D2","E1","E2"},MAX(1,MIN(12,ROUND(AH11,0))))) | AJ11: 2.33 | AK11: A3 | AL11: =IF(AH11="","",ROUND(MAX(1,MIN(12,ROUND(AH11,0)))-3,1)) | AM11: =IF(AL11="","",IF(ABS(AL11)<=1,"Yes","No"))
A12: AR-06 | B12: Functional & Domain Testing | C12: Senior QA Engineer | D12: =IF('4. Rater A'!C12="","",'4. Rater A'!C12) | E12: =IF('4. Rater A'!D12="","",'4. Rater A'!D12) | F12: =IF('4. Rater A'!E12="","",'4. Rater A'!E12) | G12: =IF('4. Rater A'!F12="","",'4. Rater A'!F12) | H12: =IF('4. Rater A'!G12="","",'4. Rater A'!G12) | I12: =IF('4. Rater A'!H12="","",'4. Rater A'!H12) | J12: =IF('5. Rater B'!C12="","",'5. Rater B'!C12) | K12: =IF('5. Rater B'!D12="","",'5. Rater B'!D12) | L12: =IF('5. Rater B'!E12="","",'5. Rater B'!E12) | M12: =IF('5. Rater B'!F12="","",'5. Rater B'!F12) | N12: =IF('5. Rater B'!G12="","",'5. Rater B'!G12) | O12: =IF('5. Rater B'!H12="","",'5. Rater B'!H12) | P12: =IF(OR(D12="",J12=""),"",ABS(D12-J12)) | Q12: =IF(OR(E12="",K12=""),"",ABS(E12-K12)) | R12: =IF(OR(F12="",L12=""),"",ABS(F12-L12)) | S12: =IF(OR(G12="",M12=""),"",ABS(G12-M12)) | T12: =IF(OR(H12="",N12=""),"",ABS(H12-N12)) | U12: =IF(OR(I12="",O12=""),"",ABS(I12-O12)) | AB12: 0.64 | AC12: 0.16 | AD12: 0.04 | AE12: 0 | AF12: 0.1 | AG12: 0.06 | AH12: =IF(OR((IF(V12<>"",V12,IF(OR(D12="",J12=""),"",(D12+J12)/2)))="",(IF(W12<>"",W12,IF(OR(E12="",K12=""),"",(E12+K12)/2)))="",(IF(X12<>"",X12,IF(OR(F12="",L12=""),"",(F12+L12)/2)))="",(IF(Y12<>"",Y12,IF(OR(G12="",M12=""),"",(G12+M12)/2)))="",(IF(Z12<>"",Z12,IF(OR(H12="",N12=""),"",(H12+N12)/2)))="",(IF(AA12<>"",AA12,IF(OR(I12="",O12=""),"",(I12+O12)/2)))=""),"",(IF(V12<>"",V12,IF(OR(D12="",J12=""),"",(D12+J12)/2)))*AB12+(IF(W12<>"",W12,IF(OR(E12="",K12=""),"",(E12+K12)/2)))*AC12+(IF(X12<>"",X12,IF(OR(F12="",L12=""),"",(F12+L12)/2)))*AD12+(IF(Y12<>"",Y12,IF(OR(G12="",M12=""),"",(G12+M12)/2)))*AE12+(IF(Z12<>"",Z12,IF(OR(H12="",N12=""),"",(H12+N12)/2)))*AF12+(IF(AA12<>"",AA12,IF(OR(I12="",O12=""),"",(I12+O12)/2)))*AG12) | AI12: =IF(AH12="","",INDEX({"A1","A2","A3","B1","B2","B3","C1","C2","D1","D2","E1","E2"},MAX(1,MIN(12,ROUND(AH12,0))))) | AJ12: 2.38 | AK12: A3 | AL12: =IF(AH12="","",ROUND(MAX(1,MIN(12,ROUND(AH12,0)))-3,1)) | AM12: =IF(AL12="","",IF(ABS(AL12)<=1,"Yes","No"))
A13: AR-07 | B13: XBRL Tagging, Conversion & Filing | C13: XBRL Specialist | D13: =IF('4. Rater A'!C13="","",'4. Rater A'!C13) | E13: =IF('4. Rater A'!D13="","",'4. Rater A'!D13) | F13: =IF('4. Rater A'!E13="","",'4. Rater A'!E13) | G13: =IF('4. Rater A'!F13="","",'4. Rater A'!F13) | H13: =IF('4. Rater A'!G13="","",'4. Rater A'!G13) | I13: =IF('4. Rater A'!H13="","",'4. Rater A'!H13) | J13: =IF('5. Rater B'!C13="","",'5. Rater B'!C13) | K13: =IF('5. Rater B'!D13="","",'5. Rater B'!D13) | L13: =IF('5. Rater B'!E13="","",'5. Rater B'!E13) | M13: =IF('5. Rater B'!F13="","",'5. Rater B'!F13) | N13: =IF('5. Rater B'!G13="","",'5. Rater B'!G13) | O13: =IF('5. Rater B'!H13="","",'5. Rater B'!H13) | P13: =IF(OR(D13="",J13=""),"",ABS(D13-J13)) | Q13: =IF(OR(E13="",K13=""),"",ABS(E13-K13)) | R13: =IF(OR(F13="",L13=""),"",ABS(F13-L13)) | S13: =IF(OR(G13="",M13=""),"",ABS(G13-M13)) | T13: =IF(OR(H13="",N13=""),"",ABS(H13-N13)) | U13: =IF(OR(I13="",O13=""),"",ABS(I13-O13)) | AB13: 0.46 | AC13: 0.17 | AD13: 0.15 | AE13: 0.05 | AF13: 0.1 | AG13: 0.07 | AH13: =IF(OR((IF(V13<>"",V13,IF(OR(D13="",J13=""),"",(D13+J13)/2)))="",(IF(W13<>"",W13,IF(OR(E13="",K13=""),"",(E13+K13)/2)))="",(IF(X13<>"",X13,IF(OR(F13="",L13=""),"",(F13+L13)/2)))="",(IF(Y13<>"",Y13,IF(OR(G13="",M13=""),"",(G13+M13)/2)))="",(IF(Z13<>"",Z13,IF(OR(H13="",N13=""),"",(H13+N13)/2)))="",(IF(AA13<>"",AA13,IF(OR(I13="",O13=""),"",(I13+O13)/2)))=""),"",(IF(V13<>"",V13,IF(OR(D13="",J13=""),"",(D13+J13)/2)))*AB13+(IF(W13<>"",W13,IF(OR(E13="",K13=""),"",(E13+K13)/2)))*AC13+(IF(X13<>"",X13,IF(OR(F13="",L13=""),"",(F13+L13)/2)))*AD13+(IF(Y13<>"",Y13,IF(OR(G13="",M13=""),"",(G13+M13)/2)))*AE13+(IF(Z13<>"",Z13,IF(OR(H13="",N13=""),"",(H13+N13)/2)))*AF13+(IF(AA13<>"",AA13,IF(OR(I13="",O13=""),"",(I13+O13)/2)))*AG13) | AI13: =IF(AH13="","",INDEX({"A1","A2","A3","B1","B2","B3","C1","C2","D1","D2","E1","E2"},MAX(1,MIN(12,ROUND(AH13,0))))) | AJ13: 3.62 | AK13: B1 | AL13: =IF(AH13="","",ROUND(MAX(1,MIN(12,ROUND(AH13,0)))-4,1)) | AM13: =IF(AL13="","",IF(ABS(AL13)<=1,"Yes","No"))
A14: AR-08 | B14: Business Analysis | C14: Business Analysis Specialist – POD Lead | D14: =IF('4. Rater A'!C14="","",'4. Rater A'!C14) | E14: =IF('4. Rater A'!D14="","",'4. Rater A'!D14) | F14: =IF('4. Rater A'!E14="","",'4. Rater A'!E14) | G14: =IF('4. Rater A'!F14="","",'4. Rater A'!F14) | H14: =IF('4. Rater A'!G14="","",'4. Rater A'!G14) | I14: =IF('4. Rater A'!H14="","",'4. Rater A'!H14) | J14: =IF('5. Rater B'!C14="","",'5. Rater B'!C14) | K14: =IF('5. Rater B'!D14="","",'5. Rater B'!D14) | L14: =IF('5. Rater B'!E14="","",'5. Rater B'!E14) | M14: =IF('5. Rater B'!F14="","",'5. Rater B'!F14) | N14: =IF('5. Rater B'!G14="","",'5. Rater B'!G14) | O14: =IF('5. Rater B'!H14="","",'5. Rater B'!H14) | P14: =IF(OR(D14="",J14=""),"",ABS(D14-J14)) | Q14: =IF(OR(E14="",K14=""),"",ABS(E14-K14)) | R14: =IF(OR(F14="",L14=""),"",ABS(F14-L14)) | S14: =IF(OR(G14="",M14=""),"",ABS(G14-M14)) | T14: =IF(OR(H14="",N14=""),"",ABS(H14-N14)) | U14: =IF(OR(I14="",O14=""),"",ABS(I14-O14)) | AB14: 0.56 | AC14: 0.17 | AD14: 0.05 | AE14: 0.05 | AF14: 0.1 | AG14: 0.07 | AH14: =IF(OR((IF(V14<>"",V14,IF(OR(D14="",J14=""),"",(D14+J14)/2)))="",(IF(W14<>"",W14,IF(OR(E14="",K14=""),"",(E14+K14)/2)))="",(IF(X14<>"",X14,IF(OR(F14="",L14=""),"",(F14+L14)/2)))="",(IF(Y14<>"",Y14,IF(OR(G14="",M14=""),"",(G14+M14)/2)))="",(IF(Z14<>"",Z14,IF(OR(H14="",N14=""),"",(H14+N14)/2)))="",(IF(AA14<>"",AA14,IF(OR(I14="",O14=""),"",(I14+O14)/2)))=""),"",(IF(V14<>"",V14,IF(OR(D14="",J14=""),"",(D14+J14)/2)))*AB14+(IF(W14<>"",W14,IF(OR(E14="",K14=""),"",(E14+K14)/2)))*AC14+(IF(X14<>"",X14,IF(OR(F14="",L14=""),"",(F14+L14)/2)))*AD14+(IF(Y14<>"",Y14,IF(OR(G14="",M14=""),"",(G14+M14)/2)))*AE14+(IF(Z14<>"",Z14,IF(OR(H14="",N14=""),"",(H14+N14)/2)))*AF14+(IF(AA14<>"",AA14,IF(OR(I14="",O14=""),"",(I14+O14)/2)))*AG14) | AI14: =IF(AH14="","",INDEX({"A1","A2","A3","B1","B2","B3","C1","C2","D1","D2","E1","E2"},MAX(1,MIN(12,ROUND(AH14,0))))) | AJ14: 3.74 | AK14: B1 | AL14: =IF(AH14="","",ROUND(MAX(1,MIN(12,ROUND(AH14,0)))-4,1)) | AM14: =IF(AL14="","",IF(ABS(AL14)<=1,"Yes","No"))
A15: AR-09 | B15: Product Management | C15: Associate Product Manager | D15: =IF('4. Rater A'!C15="","",'4. Rater A'!C15) | E15: =IF('4. Rater A'!D15="","",'4. Rater A'!D15) | F15: =IF('4. Rater A'!E15="","",'4. Rater A'!E15) | G15: =IF('4. Rater A'!F15="","",'4. Rater A'!F15) | H15: =IF('4. Rater A'!G15="","",'4. Rater A'!G15) | I15: =IF('4. Rater A'!H15="","",'4. Rater A'!H15) | J15: =IF('5. Rater B'!C15="","",'5. Rater B'!C15) | K15: =IF('5. Rater B'!D15="","",'5. Rater B'!D15) | L15: =IF('5. Rater B'!E15="","",'5. Rater B'!E15) | M15: =IF('5. Rater B'!F15="","",'5. Rater B'!F15) | N15: =IF('5. Rater B'!G15="","",'5. Rater B'!G15) | O15: =IF('5. Rater B'!H15="","",'5. Rater B'!H15) | P15: =IF(OR(D15="",J15=""),"",ABS(D15-J15)) | Q15: =IF(OR(E15="",K15=""),"",ABS(E15-K15)) | R15: =IF(OR(F15="",L15=""),"",ABS(F15-L15)) | S15: =IF(OR(G15="",M15=""),"",ABS(G15-M15)) | T15: =IF(OR(H15="",N15=""),"",ABS(H15-N15)) | U15: =IF(OR(I15="",O15=""),"",ABS(I15-O15)) | AB15: 0.46 | AC15: 0.22 | AD15: 0.1 | AE15: 0.05 | AF15: 0.1 | AG15: 0.07 | AH15: =IF(OR((IF(V15<>"",V15,IF(OR(D15="",J15=""),"",(D15+J15)/2)))="",(IF(W15<>"",W15,IF(OR(E15="",K15=""),"",(E15+K15)/2)))="",(IF(X15<>"",X15,IF(OR(F15="",L15=""),"",(F15+L15)/2)))="",(IF(Y15<>"",Y15,IF(OR(G15="",M15=""),"",(G15+M15)/2)))="",(IF(Z15<>"",Z15,IF(OR(H15="",N15=""),"",(H15+N15)/2)))="",(IF(AA15<>"",AA15,IF(OR(I15="",O15=""),"",(I15+O15)/2)))=""),"",(IF(V15<>"",V15,IF(OR(D15="",J15=""),"",(D15+J15)/2)))*AB15+(IF(W15<>"",W15,IF(OR(E15="",K15=""),"",(E15+K15)/2)))*AC15+(IF(X15<>"",X15,IF(OR(F15="",L15=""),"",(F15+L15)/2)))*AD15+(IF(Y15<>"",Y15,IF(OR(G15="",M15=""),"",(G15+M15)/2)))*AE15+(IF(Z15<>"",Z15,IF(OR(H15="",N15=""),"",(H15+N15)/2)))*AF15+(IF(AA15<>"",AA15,IF(OR(I15="",O15=""),"",(I15+O15)/2)))*AG15) | AI15: =IF(AH15="","",INDEX({"A1","A2","A3","B1","B2","B3","C1","C2","D1","D2","E1","E2"},MAX(1,MIN(12,ROUND(AH15,0))))) | AJ15: 4 | AK15: B1 | AL15: =IF(AH15="","",ROUND(MAX(1,MIN(12,ROUND(AH15,0)))-4,1)) | AM15: =IF(AL15="","",IF(ABS(AL15)<=1,"Yes","No"))
A16: AR-10 | B16: Project & Program Delivery | C16: Delivery Manager | D16: =IF('4. Rater A'!C16="","",'4. Rater A'!C16) | E16: =IF('4. Rater A'!D16="","",'4. Rater A'!D16) | F16: =IF('4. Rater A'!E16="","",'4. Rater A'!E16) | G16: =IF('4. Rater A'!F16="","",'4. Rater A'!F16) | H16: =IF('4. Rater A'!G16="","",'4. Rater A'!G16) | I16: =IF('4. Rater A'!H16="","",'4. Rater A'!H16) | J16: =IF('5. Rater B'!C16="","",'5. Rater B'!C16) | K16: =IF('5. Rater B'!D16="","",'5. Rater B'!D16) | L16: =IF('5. Rater B'!E16="","",'5. Rater B'!E16) | M16: =IF('5. Rater B'!F16="","",'5. Rater B'!F16) | N16: =IF('5. Rater B'!G16="","",'5. Rater B'!G16) | O16: =IF('5. Rater B'!H16="","",'5. Rater B'!H16) | P16: =IF(OR(D16="",J16=""),"",ABS(D16-J16)) | Q16: =IF(OR(E16="",K16=""),"",ABS(E16-K16)) | R16: =IF(OR(F16="",L16=""),"",ABS(F16-L16)) | S16: =IF(OR(G16="",M16=""),"",ABS(G16-M16)) | T16: =IF(OR(H16="",N16=""),"",ABS(H16-N16)) | U16: =IF(OR(I16="",O16=""),"",ABS(I16-O16)) | AB16: 0.42 | AC16: 0.18 | AD16: 0.06 | AE16: 0.15 | AF16: 0.1 | AG16: 0.09 | AH16: =IF(OR((IF(V16<>"",V16,IF(OR(D16="",J16=""),"",(D16+J16)/2)))="",(IF(W16<>"",W16,IF(OR(E16="",K16=""),"",(E16+K16)/2)))="",(IF(X16<>"",X16,IF(OR(F16="",L16=""),"",(F16+L16)/2)))="",(IF(Y16<>"",Y16,IF(OR(G16="",M16=""),"",(G16+M16)/2)))="",(IF(Z16<>"",Z16,IF(OR(H16="",N16=""),"",(H16+N16)/2)))="",(IF(AA16<>"",AA16,IF(OR(I16="",O16=""),"",(I16+O16)/2)))=""),"",(IF(V16<>"",V16,IF(OR(D16="",J16=""),"",(D16+J16)/2)))*AB16+(IF(W16<>"",W16,IF(OR(E16="",K16=""),"",(E16+K16)/2)))*AC16+(IF(X16<>"",X16,IF(OR(F16="",L16=""),"",(F16+L16)/2)))*AD16+(IF(Y16<>"",Y16,IF(OR(G16="",M16=""),"",(G16+M16)/2)))*AE16+(IF(Z16<>"",Z16,IF(OR(H16="",N16=""),"",(H16+N16)/2)))*AF16+(IF(AA16<>"",AA16,IF(OR(I16="",O16=""),"",(I16+O16)/2)))*AG16) | AI16: =IF(AH16="","",INDEX({"A1","A2","A3","B1","B2","B3","C1","C2","D1","D2","E1","E2"},MAX(1,MIN(12,ROUND(AH16,0))))) | AJ16: 5.2 | AK16: B2 | AL16: =IF(AH16="","",ROUND(MAX(1,MIN(12,ROUND(AH16,0)))-5,1)) | AM16: =IF(AL16="","",IF(ABS(AL16)<=1,"Yes","No"))
A17: AR-11 | B17: Customer Success & Account Management | C17: Senior Customer Success Specialist – POD Lead | D17: =IF('4. Rater A'!C17="","",'4. Rater A'!C17) | E17: =IF('4. Rater A'!D17="","",'4. Rater A'!D17) | F17: =IF('4. Rater A'!E17="","",'4. Rater A'!E17) | G17: =IF('4. Rater A'!F17="","",'4. Rater A'!F17) | H17: =IF('4. Rater A'!G17="","",'4. Rater A'!G17) | I17: =IF('4. Rater A'!H17="","",'4. Rater A'!H17) | J17: =IF('5. Rater B'!C17="","",'5. Rater B'!C17) | K17: =IF('5. Rater B'!D17="","",'5. Rater B'!D17) | L17: =IF('5. Rater B'!E17="","",'5. Rater B'!E17) | M17: =IF('5. Rater B'!F17="","",'5. Rater B'!F17) | N17: =IF('5. Rater B'!G17="","",'5. Rater B'!G17) | O17: =IF('5. Rater B'!H17="","",'5. Rater B'!H17) | P17: =IF(OR(D17="",J17=""),"",ABS(D17-J17)) | Q17: =IF(OR(E17="",K17=""),"",ABS(E17-K17)) | R17: =IF(OR(F17="",L17=""),"",ABS(F17-L17)) | S17: =IF(OR(G17="",M17=""),"",ABS(G17-M17)) | T17: =IF(OR(H17="",N17=""),"",ABS(H17-N17)) | U17: =IF(OR(I17="",O17=""),"",ABS(I17-O17)) | AB17: 0.46 | AC17: 0.17 | AD17: 0.1 | AE17: 0.05 | AF17: 0.1 | AG17: 0.12 | AH17: =IF(OR((IF(V17<>"",V17,IF(OR(D17="",J17=""),"",(D17+J17)/2)))="",(IF(W17<>"",W17,IF(OR(E17="",K17=""),"",(E17+K17)/2)))="",(IF(X17<>"",X17,IF(OR(F17="",L17=""),"",(F17+L17)/2)))="",(IF(Y17<>"",Y17,IF(OR(G17="",M17=""),"",(G17+M17)/2)))="",(IF(Z17<>"",Z17,IF(OR(H17="",N17=""),"",(H17+N17)/2)))="",(IF(AA17<>"",AA17,IF(OR(I17="",O17=""),"",(I17+O17)/2)))=""),"",(IF(V17<>"",V17,IF(OR(D17="",J17=""),"",(D17+J17)/2)))*AB17+(IF(W17<>"",W17,IF(OR(E17="",K17=""),"",(E17+K17)/2)))*AC17+(IF(X17<>"",X17,IF(OR(F17="",L17=""),"",(F17+L17)/2)))*AD17+(IF(Y17<>"",Y17,IF(OR(G17="",M17=""),"",(G17+M17)/2)))*AE17+(IF(Z17<>"",Z17,IF(OR(H17="",N17=""),"",(H17+N17)/2)))*AF17+(IF(AA17<>"",AA17,IF(OR(I17="",O17=""),"",(I17+O17)/2)))*AG17) | AI17: =IF(AH17="","",INDEX({"A1","A2","A3","B1","B2","B3","C1","C2","D1","D2","E1","E2"},MAX(1,MIN(12,ROUND(AH17,0))))) | AJ17: 4.62 | AK17: B2 | AL17: =IF(AH17="","",ROUND(MAX(1,MIN(12,ROUND(AH17,0)))-5,1)) | AM17: =IF(AL17="","",IF(ABS(AL17)<=1,"Yes","No"))
A18: AR-12 | B18: Product Management | C18: Product Manager | D18: =IF('4. Rater A'!C18="","",'4. Rater A'!C18) | E18: =IF('4. Rater A'!D18="","",'4. Rater A'!D18) | F18: =IF('4. Rater A'!E18="","",'4. Rater A'!E18) | G18: =IF('4. Rater A'!F18="","",'4. Rater A'!F18) | H18: =IF('4. Rater A'!G18="","",'4. Rater A'!G18) | I18: =IF('4. Rater A'!H18="","",'4. Rater A'!H18) | J18: =IF('5. Rater B'!C18="","",'5. Rater B'!C18) | K18: =IF('5. Rater B'!D18="","",'5. Rater B'!D18) | L18: =IF('5. Rater B'!E18="","",'5. Rater B'!E18) | M18: =IF('5. Rater B'!F18="","",'5. Rater B'!F18) | N18: =IF('5. Rater B'!G18="","",'5. Rater B'!G18) | O18: =IF('5. Rater B'!H18="","",'5. Rater B'!H18) | P18: =IF(OR(D18="",J18=""),"",ABS(D18-J18)) | Q18: =IF(OR(E18="",K18=""),"",ABS(E18-K18)) | R18: =IF(OR(F18="",L18=""),"",ABS(F18-L18)) | S18: =IF(OR(G18="",M18=""),"",ABS(G18-M18)) | T18: =IF(OR(H18="",N18=""),"",ABS(H18-N18)) | U18: =IF(OR(I18="",O18=""),"",ABS(I18-O18)) | AB18: 0.32 | AC18: 0.23 | AD18: 0.11 | AE18: 0.15 | AF18: 0.1 | AG18: 0.09 | AH18: =IF(OR((IF(V18<>"",V18,IF(OR(D18="",J18=""),"",(D18+J18)/2)))="",(IF(W18<>"",W18,IF(OR(E18="",K18=""),"",(E18+K18)/2)))="",(IF(X18<>"",X18,IF(OR(F18="",L18=""),"",(F18+L18)/2)))="",(IF(Y18<>"",Y18,IF(OR(G18="",M18=""),"",(G18+M18)/2)))="",(IF(Z18<>"",Z18,IF(OR(H18="",N18=""),"",(H18+N18)/2)))="",(IF(AA18<>"",AA18,IF(OR(I18="",O18=""),"",(I18+O18)/2)))=""),"",(IF(V18<>"",V18,IF(OR(D18="",J18=""),"",(D18+J18)/2)))*AB18+(IF(W18<>"",W18,IF(OR(E18="",K18=""),"",(E18+K18)/2)))*AC18+(IF(X18<>"",X18,IF(OR(F18="",L18=""),"",(F18+L18)/2)))*AD18+(IF(Y18<>"",Y18,IF(OR(G18="",M18=""),"",(G18+M18)/2)))*AE18+(IF(Z18<>"",Z18,IF(OR(H18="",N18=""),"",(H18+N18)/2)))*AF18+(IF(AA18<>"",AA18,IF(OR(I18="",O18=""),"",(I18+O18)/2)))*AG18) | AI18: =IF(AH18="","",INDEX({"A1","A2","A3","B1","B2","B3","C1","C2","D1","D2","E1","E2"},MAX(1,MIN(12,ROUND(AH18,0))))) | AJ18: 5.32 | AK18: B2 | AL18: =IF(AH18="","",ROUND(MAX(1,MIN(12,ROUND(AH18,0)))-5,1)) | AM18: =IF(AL18="","",IF(ABS(AL18)<=1,"Yes","No"))
A19: AR-13 | B19: Solution & Technical Architecture | C19: Associate Technical Architect | D19: =IF('4. Rater A'!C19="","",'4. Rater A'!C19) | E19: =IF('4. Rater A'!D19="","",'4. Rater A'!D19) | F19: =IF('4. Rater A'!E19="","",'4. Rater A'!E19) | G19: =IF('4. Rater A'!F19="","",'4. Rater A'!F19) | H19: =IF('4. Rater A'!G19="","",'4. Rater A'!G19) | I19: =IF('4. Rater A'!H19="","",'4. Rater A'!H19) | J19: =IF('5. Rater B'!C19="","",'5. Rater B'!C19) | K19: =IF('5. Rater B'!D19="","",'5. Rater B'!D19) | L19: =IF('5. Rater B'!E19="","",'5. Rater B'!E19) | M19: =IF('5. Rater B'!F19="","",'5. Rater B'!F19) | N19: =IF('5. Rater B'!G19="","",'5. Rater B'!G19) | O19: =IF('5. Rater B'!H19="","",'5. Rater B'!H19) | P19: =IF(OR(D19="",J19=""),"",ABS(D19-J19)) | Q19: =IF(OR(E19="",K19=""),"",ABS(E19-K19)) | R19: =IF(OR(F19="",L19=""),"",ABS(F19-L19)) | S19: =IF(OR(G19="",M19=""),"",ABS(G19-M19)) | T19: =IF(OR(H19="",N19=""),"",ABS(H19-N19)) | U19: =IF(OR(I19="",O19=""),"",ABS(I19-O19)) | AB19: 0.56 | AC19: 0.17 | AD19: 0.05 | AE19: 0.05 | AF19: 0.1 | AG19: 0.07 | AH19: =IF(OR((IF(V19<>"",V19,IF(OR(D19="",J19=""),"",(D19+J19)/2)))="",(IF(W19<>"",W19,IF(OR(E19="",K19=""),"",(E19+K19)/2)))="",(IF(X19<>"",X19,IF(OR(F19="",L19=""),"",(F19+L19)/2)))="",(IF(Y19<>"",Y19,IF(OR(G19="",M19=""),"",(G19+M19)/2)))="",(IF(Z19<>"",Z19,IF(OR(H19="",N19=""),"",(H19+N19)/2)))="",(IF(AA19<>"",AA19,IF(OR(I19="",O19=""),"",(I19+O19)/2)))=""),"",(IF(V19<>"",V19,IF(OR(D19="",J19=""),"",(D19+J19)/2)))*AB19+(IF(W19<>"",W19,IF(OR(E19="",K19=""),"",(E19+K19)/2)))*AC19+(IF(X19<>"",X19,IF(OR(F19="",L19=""),"",(F19+L19)/2)))*AD19+(IF(Y19<>"",Y19,IF(OR(G19="",M19=""),"",(G19+M19)/2)))*AE19+(IF(Z19<>"",Z19,IF(OR(H19="",N19=""),"",(H19+N19)/2)))*AF19+(IF(AA19<>"",AA19,IF(OR(I19="",O19=""),"",(I19+O19)/2)))*AG19) | AI19: =IF(AH19="","",INDEX({"A1","A2","A3","B1","B2","B3","C1","C2","D1","D2","E1","E2"},MAX(1,MIN(12,ROUND(AH19,0))))) | AJ19: 6.3 | AK19: B3 | AL19: =IF(AH19="","",ROUND(MAX(1,MIN(12,ROUND(AH19,0)))-6,1)) | AM19: =IF(AL19="","",IF(ABS(AL19)<=1,"Yes","No"))
A20: AR-14 | B20: HR Transformation & OD | C20: Lead HR Specialist – Transformation & OD | D20: =IF('4. Rater A'!C20="","",'4. Rater A'!C20) | E20: =IF('4. Rater A'!D20="","",'4. Rater A'!D20) | F20: =IF('4. Rater A'!E20="","",'4. Rater A'!E20) | G20: =IF('4. Rater A'!F20="","",'4. Rater A'!F20) | H20: =IF('4. Rater A'!G20="","",'4. Rater A'!G20) | I20: =IF('4. Rater A'!H20="","",'4. Rater A'!H20) | J20: =IF('5. Rater B'!C20="","",'5. Rater B'!C20) | K20: =IF('5. Rater B'!D20="","",'5. Rater B'!D20) | L20: =IF('5. Rater B'!E20="","",'5. Rater B'!E20) | M20: =IF('5. Rater B'!F20="","",'5. Rater B'!F20) | N20: =IF('5. Rater B'!G20="","",'5. Rater B'!G20) | O20: =IF('5. Rater B'!H20="","",'5. Rater B'!H20) | P20: =IF(OR(D20="",J20=""),"",ABS(D20-J20)) | Q20: =IF(OR(E20="",K20=""),"",ABS(E20-K20)) | R20: =IF(OR(F20="",L20=""),"",ABS(F20-L20)) | S20: =IF(OR(G20="",M20=""),"",ABS(G20-M20)) | T20: =IF(OR(H20="",N20=""),"",ABS(H20-N20)) | U20: =IF(OR(I20="",O20=""),"",ABS(I20-O20)) | AB20: 0.46 | AC20: 0.17 | AD20: 0.1 | AE20: 0.05 | AF20: 0.15 | AG20: 0.07 | AH20: =IF(OR((IF(V20<>"",V20,IF(OR(D20="",J20=""),"",(D20+J20)/2)))="",(IF(W20<>"",W20,IF(OR(E20="",K20=""),"",(E20+K20)/2)))="",(IF(X20<>"",X20,IF(OR(F20="",L20=""),"",(F20+L20)/2)))="",(IF(Y20<>"",Y20,IF(OR(G20="",M20=""),"",(G20+M20)/2)))="",(IF(Z20<>"",Z20,IF(OR(H20="",N20=""),"",(H20+N20)/2)))="",(IF(AA20<>"",AA20,IF(OR(I20="",O20=""),"",(I20+O20)/2)))=""),"",(IF(V20<>"",V20,IF(OR(D20="",J20=""),"",(D20+J20)/2)))*AB20+(IF(W20<>"",W20,IF(OR(E20="",K20=""),"",(E20+K20)/2)))*AC20+(IF(X20<>"",X20,IF(OR(F20="",L20=""),"",(F20+L20)/2)))*AD20+(IF(Y20<>"",Y20,IF(OR(G20="",M20=""),"",(G20+M20)/2)))*AE20+(IF(Z20<>"",Z20,IF(OR(H20="",N20=""),"",(H20+N20)/2)))*AF20+(IF(AA20<>"",AA20,IF(OR(I20="",O20=""),"",(I20+O20)/2)))*AG20) | AI20: =IF(AH20="","",INDEX({"A1","A2","A3","B1","B2","B3","C1","C2","D1","D2","E1","E2"},MAX(1,MIN(12,ROUND(AH20,0))))) | AJ20: 5.73 | AK20: B3 | AL20: =IF(AH20="","",ROUND(MAX(1,MIN(12,ROUND(AH20,0)))-6,1)) | AM20: =IF(AL20="","",IF(ABS(AL20)<=1,"Yes","No"))
A21: AR-15 | B21: Marketing Leadership | C21: Senior Marketing Manager | D21: =IF('4. Rater A'!C21="","",'4. Rater A'!C21) | E21: =IF('4. Rater A'!D21="","",'4. Rater A'!D21) | F21: =IF('4. Rater A'!E21="","",'4. Rater A'!E21) | G21: =IF('4. Rater A'!F21="","",'4. Rater A'!F21) | H21: =IF('4. Rater A'!G21="","",'4. Rater A'!G21) | I21: =IF('4. Rater A'!H21="","",'4. Rater A'!H21) | J21: =IF('5. Rater B'!C21="","",'5. Rater B'!C21) | K21: =IF('5. Rater B'!D21="","",'5. Rater B'!D21) | L21: =IF('5. Rater B'!E21="","",'5. Rater B'!E21) | M21: =IF('5. Rater B'!F21="","",'5. Rater B'!F21) | N21: =IF('5. Rater B'!G21="","",'5. Rater B'!G21) | O21: =IF('5. Rater B'!H21="","",'5. Rater B'!H21) | P21: =IF(OR(D21="",J21=""),"",ABS(D21-J21)) | Q21: =IF(OR(E21="",K21=""),"",ABS(E21-K21)) | R21: =IF(OR(F21="",L21=""),"",ABS(F21-L21)) | S21: =IF(OR(G21="",M21=""),"",ABS(G21-M21)) | T21: =IF(OR(H21="",N21=""),"",ABS(H21-N21)) | U21: =IF(OR(I21="",O21=""),"",ABS(I21-O21)) | AB21: 0.32 | AC21: 0.23 | AD21: 0.06 | AE21: 0.15 | AF21: 0.1 | AG21: 0.14 | AH21: =IF(OR((IF(V21<>"",V21,IF(OR(D21="",J21=""),"",(D21+J21)/2)))="",(IF(W21<>"",W21,IF(OR(E21="",K21=""),"",(E21+K21)/2)))="",(IF(X21<>"",X21,IF(OR(F21="",L21=""),"",(F21+L21)/2)))="",(IF(Y21<>"",Y21,IF(OR(G21="",M21=""),"",(G21+M21)/2)))="",(IF(Z21<>"",Z21,IF(OR(H21="",N21=""),"",(H21+N21)/2)))="",(IF(AA21<>"",AA21,IF(OR(I21="",O21=""),"",(I21+O21)/2)))=""),"",(IF(V21<>"",V21,IF(OR(D21="",J21=""),"",(D21+J21)/2)))*AB21+(IF(W21<>"",W21,IF(OR(E21="",K21=""),"",(E21+K21)/2)))*AC21+(IF(X21<>"",X21,IF(OR(F21="",L21=""),"",(F21+L21)/2)))*AD21+(IF(Y21<>"",Y21,IF(OR(G21="",M21=""),"",(G21+M21)/2)))*AE21+(IF(Z21<>"",Z21,IF(OR(H21="",N21=""),"",(H21+N21)/2)))*AF21+(IF(AA21<>"",AA21,IF(OR(I21="",O21=""),"",(I21+O21)/2)))*AG21) | AI21: =IF(AH21="","",INDEX({"A1","A2","A3","B1","B2","B3","C1","C2","D1","D2","E1","E2"},MAX(1,MIN(12,ROUND(AH21,0))))) | AJ21: 6 | AK21: B3 | AL21: =IF(AH21="","",ROUND(MAX(1,MIN(12,ROUND(AH21,0)))-6,1)) | AM21: =IF(AL21="","",IF(ABS(AL21)<=1,"Yes","No"))
A22: AR-16 | B22: Solution & Technical Architecture | C22: Practice Lead – Solution & Technical Architecture · Player-Coach | D22: =IF('4. Rater A'!C22="","",'4. Rater A'!C22) | E22: =IF('4. Rater A'!D22="","",'4. Rater A'!D22) | F22: =IF('4. Rater A'!E22="","",'4. Rater A'!E22) | G22: =IF('4. Rater A'!F22="","",'4. Rater A'!F22) | H22: =IF('4. Rater A'!G22="","",'4. Rater A'!G22) | I22: =IF('4. Rater A'!H22="","",'4. Rater A'!H22) | J22: =IF('5. Rater B'!C22="","",'5. Rater B'!C22) | K22: =IF('5. Rater B'!D22="","",'5. Rater B'!D22) | L22: =IF('5. Rater B'!E22="","",'5. Rater B'!E22) | M22: =IF('5. Rater B'!F22="","",'5. Rater B'!F22) | N22: =IF('5. Rater B'!G22="","",'5. Rater B'!G22) | O22: =IF('5. Rater B'!H22="","",'5. Rater B'!H22) | P22: =IF(OR(D22="",J22=""),"",ABS(D22-J22)) | Q22: =IF(OR(E22="",K22=""),"",ABS(E22-K22)) | R22: =IF(OR(F22="",L22=""),"",ABS(F22-L22)) | S22: =IF(OR(G22="",M22=""),"",ABS(G22-M22)) | T22: =IF(OR(H22="",N22=""),"",ABS(H22-N22)) | U22: =IF(OR(I22="",O22=""),"",ABS(I22-O22)) | AB22: 0.49 | AC22: 0.18 | AD22: 0.05 | AE22: 0.1 | AF22: 0.1 | AG22: 0.08 | AH22: =IF(OR((IF(V22<>"",V22,IF(OR(D22="",J22=""),"",(D22+J22)/2)))="",(IF(W22<>"",W22,IF(OR(E22="",K22=""),"",(E22+K22)/2)))="",(IF(X22<>"",X22,IF(OR(F22="",L22=""),"",(F22+L22)/2)))="",(IF(Y22<>"",Y22,IF(OR(G22="",M22=""),"",(G22+M22)/2)))="",(IF(Z22<>"",Z22,IF(OR(H22="",N22=""),"",(H22+N22)/2)))="",(IF(AA22<>"",AA22,IF(OR(I22="",O22=""),"",(I22+O22)/2)))=""),"",(IF(V22<>"",V22,IF(OR(D22="",J22=""),"",(D22+J22)/2)))*AB22+(IF(W22<>"",W22,IF(OR(E22="",K22=""),"",(E22+K22)/2)))*AC22+(IF(X22<>"",X22,IF(OR(F22="",L22=""),"",(F22+L22)/2)))*AD22+(IF(Y22<>"",Y22,IF(OR(G22="",M22=""),"",(G22+M22)/2)))*AE22+(IF(Z22<>"",Z22,IF(OR(H22="",N22=""),"",(H22+N22)/2)))*AF22+(IF(AA22<>"",AA22,IF(OR(I22="",O22=""),"",(I22+O22)/2)))*AG22) | AI22: =IF(AH22="","",INDEX({"A1","A2","A3","B1","B2","B3","C1","C2","D1","D2","E1","E2"},MAX(1,MIN(12,ROUND(AH22,0))))) | AJ22: 6.54 | AK22: B+ | AL22: =IF(AH22="","",ROUND(MAX(1,MIN(12,ROUND(AH22,0)))-6.5,1)) | AM22: =IF(AL22="","",IF(ABS(AL22)<=1,"Yes","No"))
