Workbook
Name LMH_KEY: 'Backend Data'!$A$6:$A$8
Name LMH_PTS: 'Backend Data'!$C$6:$C$8
Name LMH_STEP: 'Backend Data'!$D$6:$D$8
Name LIST_LMH: 'Backend Data'!$A$6:$A$8
Name B_LVL: 'Backend Data'!$A$11:$A$27
Name B_VAL: 'Backend Data'!$B$11:$B$27
Name B_RANK: 'Backend Data'!$D$11:$D$27
Name LAD_STD: 'Backend Data'!$E$11:$E$22
Name LAD_PC: 'Backend Data'!$F$11:$F$24
Name LIST_LEVELS: 'Backend Data'!$A$11:$A$27
Name LIST_PEOPLE: 'Backend Data'!$A$30:$A$615
Name PEOPLE_ID: 'Backend Data'!$B$30:$B$615
Name RM_KEY: '3. Role Model'!$A$7:$A$275
Name RM_I_C: '3. Role Model'!$I$7:$I$275
Name RM_M_C: '3. Role Model'!$P$7:$P$275
Name RM_L_C: '3. Role Model'!$W$7:$W$275
Name RM_E_C: '3. Role Model'!$AD$7:$AD$275
Name RM_I_Au: '3. Role Model'!$J$7:$J$275
Name RM_M_Au: '3. Role Model'!$Q$7:$Q$275
Name RM_L_Au: '3. Role Model'!$X$7:$X$275
Name RM_E_Au: '3. Role Model'!$AE$7:$AE$275
Name RM_I_Ac: '3. Role Model'!$K$7:$K$275
Name RM_M_Ac: '3. Role Model'!$R$7:$R$275
Name RM_L_Ac: '3. Role Model'!$Y$7:$Y$275
Name RM_E_Ac: '3. Role Model'!$AF$7:$AF$275
Name RM_I_L: '3. Role Model'!$L$7:$L$275
Name RM_M_L: '3. Role Model'!$S$7:$S$275
Name RM_L_L: '3. Role Model'!$Z$7:$Z$275
Name RM_E_L: '3. Role Model'!$AG$7:$AG$275
Name RM_I_BI: '3. Role Model'!$M$7:$M$275
Name RM_M_BI: '3. Role Model'!$T$7:$T$275
Name RM_L_BI: '3. Role Model'!$AA$7:$AA$275
Name RM_E_BI: '3. Role Model'!$AH$7:$AH$275
Name RM_I_Exp: '3. Role Model'!$N$7:$N$275
Name RM_M_Exp: '3. Role Model'!$U$7:$U$275
Name RM_L_Exp: '3. Role Model'!$AB$7:$AB$275
Name RM_E_Exp: '3. Role Model'!$AI$7:$AI$275
Name RM_I_Edu: '3. Role Model'!$O$7:$O$275
Name RM_M_Edu: '3. Role Model'!$V$7:$V$275
Name RM_L_Edu: '3. Role Model'!$AC$7:$AC$275
Name RM_E_Edu: '3. Role Model'!$AJ$7:$AJ$275
Name RM_LCNT: '3. Role Model'!$AK$7:$AK$275

Sheet 1. How it works
A1: IRIS Job Architecture Model — how it works
A2: Read this first · five steps, in the order they happened.
A3: IRIS · Job Architecture Model v2.0 · October 2026 · Internal — Confidential · HR and business leaders
A5: 1 · We asked | B5: The How We Grow survey: 20 questions to every employee about the work, decisions, accountability, skills and learning; and the managers' talent mapping: KRAs, rating, potential, 9-box. Where nothing came back, the cell is blank.
A6: 2 · We built the ladder | B6: There was no level framework. From the answers and the market we built one ladder of 12 levels in five bands, plus two Player-Coach steps. Each level has its own experience range, scope and span, so the levels do not overlap · sheet 2.
A7: 3 · We placed everyone | B7: Each person got a job family, a sub-family, a role and a level from the evidence. Then we moved the fewest people needed so that no one shares a band with their manager: 36 down, pay and title protected, and 39 up. Where a reporting chain is deeper than the bands, we flag it for a structure decision instead of forcing a level: 22 cases.
A8: 4 · We checked the market | B8: Every parameter's weight is set against published job-evaluation methods — Korn Ferry Hay, Mercer IPE and five public plans — and shown as Low / Medium / High with the numbers behind it · sheet 4. Levels map to Radford / Mercer codes, SFIA and peer experience ranges.
A9: 5 · Leaders give their view | B9: On sheet 5 you see, for each person, what IRIS proposes and why. Rate any parameter Low, Medium or High against the level; re-weight a role on sheet 3; or set any level with the override. Your proposed level and band appear as soon as you give an input, and the manager check updates live.
A10: The model in one line | B10: Each parameter is rated Low / Medium / High against the level; each role weights the parameters Low / Medium / High. If your weighted rating is half a level or more above IRIS's, the person moves one level up; half a level or more below, one level down.
A11: The seven parameters | B11: Complexity & Expertise · Autonomy & Decision · Accountability & Impact · Leadership & Strategy · Business Impact · Experience · Education.
A12: Low · Medium · High | B12: Rating: Low = works at the level below on this parameter; Medium = as the level is defined; High = already at the level above. Weightage: Low counts 1, Medium 3, High 9 — the shares follow the published methods within a few points.
A13: Colours | B13: Yellow = yours to fill · red = a structure decision · orange = a title to align · band colours on levels.
A14: Privacy | B14: HR and business leaders only. Personal fields are never written; pay is not in this file.
A16: The sheets
A17: 1. How it works
A18: 2. Ladder
A19: 3. Role Model
A20: 4. Market Benchmark
A21: 5. Talent Mapping
A22: 6. Person Card
A23: 7. Raw Data
A24: Backend Data

Sheet 2. Ladder
A1: Ladder — one level, one place | M1: ◂ Start
A2: Sheet 2 · Every level has its own experience range, scope and span — the ranges do not overlap, so each person fits one level by the evidence. Player-Coach steps B+ and C+ are set by the role, not by years. Titles follow HR's decisions.
A3: IRIS · Job Architecture Model v2.0 · October 2026 · Internal — Confidential · HR and business leaders
A5: LEVEL | E5: WHAT DEFINES IT — distinct by level | I5: MARKET | M5: PEOPLE
A6: Level | B6: Band | C6: IC title | D6: Manager title | E6: Experience · distinct range | F6: What the role owns | G6: Span of control | H6: Education | I6: Market experience · yrs | J6: Radford / Mercer | K6: SFIA 9 | L6: References | M6: People · IRIS proposed
A7: E2 | B7: Band E · Enterprise leadership | C7: — | D7: Chief Executive Officer | E7: 22+ yrs · board appointment | F7: The enterprise | G7: Executive team | H7: Postgraduate / professional qualification; proven business leadership | I7: — | J7: E6 | K7: 7 | L7: S01 Aon Radford · S02 Pave · S08 SFIA 9 · S03 Mercer career levels · S32 Google, Microsoft, Amazon · S33 Infosys · S35 Accenture India · IRIS experience guide · S09 McKinsey spans of control · S37 GitLab layers · S44 Google Tech Lead Manager | M7: 1
A8: E1 | B8: Band E · Enterprise leadership | C8: — | D8: CXO / President | E8: 22+ yrs | F8: An enterprise-wide function | G8: 5–8 function heads | H8: Postgraduate / professional qualification; business leadership record | I8: — | J8: E5 | K8: 7 | L8: S01 Aon Radford · S02 Pave · S08 SFIA 9 · S03 Mercer career levels · S32 Google, Microsoft, Amazon · S33 Infosys · S35 Accenture India · IRIS experience guide · S09 McKinsey spans of control · S37 GitLab layers · S44 Google Tech Lead Manager | M8: 4
A9: D2 | B9: Band D · Business leadership | C9: — | D9: Senior Vice President / Business Head | E9: 19–22 yrs | F9: Several business lines or an executive-scope enterprise function | G9: 5–8 AVPs / heads | H9: Postgraduate / professional qualification preferred | I9: — | J9: E3–E4 | K9: 7 Set strategy | L9: S01 Aon Radford · S02 Pave · S08 SFIA 9 · S03 Mercer career levels · S32 Google, Microsoft, Amazon · S33 Infosys · S35 Accenture India · IRIS experience guide · S09 McKinsey spans of control · S37 GitLab layers · S44 Google Tech Lead Manager | M9: 4
A10: D1 | B10: Band D · Business leadership | C10: Distinguished Principal | D10: Associate Vice President | E10: 16–19 yrs | F10: A business line P&L, region or enterprise function | G10: 5–8 heads | H10: Postgraduate / professional qualification preferred | I10: — | J10: E1–E2 | K10: 6–7 | L10: S01 Aon Radford · S02 Pave · S08 SFIA 9 · S03 Mercer career levels · S32 Google, Microsoft, Amazon · S33 Infosys · S35 Accenture India · IRIS experience guide · S09 McKinsey spans of control · S37 GitLab layers · S44 Google Tech Lead Manager | M10: 3
A11: C+ | B11: C+ · Player-Coach | C11: Group Head · Player-Coach | D11: Group Head · Player-Coach | E11: 13–17 yrs · Player-Coach, set by the role, not by years | F11: A function or group of practices: answers for its results and personally delivers or sells the most critical work · player-coach | G11: 4–8 managers / leads with ≥ 25% of time on own principal delivery | H11: Postgraduate / professional qualification preferred | I11: 15–18 | J11: M6 / E1 | K11: 6 Initiate, influence | L11: S01 Aon Radford · S02 Pave · S08 SFIA 9 · S03 Mercer career levels · S32 Google, Microsoft, Amazon · S33 Infosys · S35 Accenture India · IRIS experience guide · S09 McKinsey spans of control · S37 GitLab layers · S44 Google Tech Lead Manager | M11: 0
A12: C2 | B12: Band C · Principal / Head | C12: Senior Principal / Architect | D12: Head of Function | E12: 13–16 yrs | F12: A function or department, or a company-wide discipline | G12: 5–8 managers / associate heads | H12: Postgraduate / professional qualification preferred | I12: — | J12: P7 / M6 | K12: 6 Initiate, influence | L12: S01 Aon Radford · S02 Pave · S08 SFIA 9 · S03 Mercer career levels · S32 Google, Microsoft, Amazon · S33 Infosys · S35 Accenture India · IRIS experience guide · S09 McKinsey spans of control · S37 GitLab layers · S44 Google Tech Lead Manager | M12: 5
A13: C1 | B13: Band C · Principal / Head | C13: Principal | D13: Associate Head | E13: 10–13 yrs | F13: A sub-function, or principal authority across products | G13: 5–8, mostly managers | H13: Postgraduate / professional qualification preferred | I13: 12–17 | J13: P6 / M5 | K13: 5–6 | L13: S01 Aon Radford · S02 Pave · S08 SFIA 9 · S03 Mercer career levels · S32 Google, Microsoft, Amazon · S33 Infosys · S35 Accenture India · IRIS experience guide · S09 McKinsey spans of control · S37 GitLab layers · S44 Google Tech Lead Manager | M13: 27
A14: B+ | B14: B+ · Player-Coach | C14: Practice Lead · Player-Coach | D14: Practice Lead · Player-Coach | E14: 8–12 yrs · Player-Coach, set by the role, not by years | F14: A practice or product area: does the hardest hands-on work itself and leads 3–6 people · player-coach | G14: 3–6 direct reports with ≥ 40% of time on own delivery · McKinsey player/coach 3–5; Google Tech Lead Manager | H14: Postgraduate or professional qualification preferred | I14: 9–14 | J14: P5–P6 / M4–M5 | K14: 5 Ensure, advise | L14: S01 Aon Radford · S02 Pave · S08 SFIA 9 · S03 Mercer career levels · S32 Google, Microsoft, Amazon · S33 Infosys · S35 Accenture India · IRIS experience guide · S09 McKinsey spans of control · S37 GitLab layers · S44 Google Tech Lead Manager | M14: 5
A15: B3 | B15: Band B · Specialist / Manager | C15: Lead Specialist | D15: Senior Manager | E15: 8–10 yrs | F15: A practice, or several teams through team leads | G15: IC: none · People: 5–8 incl. team leads | H15: Postgraduate or professional qualification preferred | I15: 8–13 | J15: P5 / M4 | K15: 5 Ensure, advise | L15: S01 Aon Radford · S02 Pave · S08 SFIA 9 · S03 Mercer career levels · S32 Google, Microsoft, Amazon · S33 Infosys · S35 Accenture India · IRIS experience guide · S09 McKinsey spans of control · S37 GitLab layers · S44 Google Tech Lead Manager | M15: 13
A16: B2 | B16: Band B · Specialist / Manager | C16: Senior Specialist | D16: Manager | E16: 6–8 yrs | F16: Deep domain expertise, or one team | G16: IC: none · People: 6–8 knowledge work, 8–12 standardised delivery | H16: Graduate or postgraduate; professional qualification preferred | I16: 6–10 | J16: P4 / M3 | K16: 4–5 | L16: S01 Aon Radford · S02 Pave · S08 SFIA 9 · S03 Mercer career levels · S32 Google, Microsoft, Amazon · S33 Infosys · S35 Accenture India · IRIS experience guide · S09 McKinsey spans of control · S37 GitLab layers · S44 Google Tech Lead Manager | M16: 54
A17: B1 | B17: Band B · Specialist / Manager | C17: Specialist | D17: Team Lead / Asst Manager | E17: 4–6 yrs | F17: A domain / module, or a small team | G17: IC: none · Team Lead: 3–5 | H17: Graduate + relevant qualification or certification preferred | I17: 4–8 | J17: P3 / M2 | K17: 4 Enable | L17: S01 Aon Radford · S02 Pave · S08 SFIA 9 · S03 Mercer career levels · S32 Google, Microsoft, Amazon · S33 Infosys · S35 Accenture India · IRIS experience guide · S09 McKinsey spans of control · S37 GitLab layers · S44 Google Tech Lead Manager | M17: 78
A18: A3 | B18: Band A · Practitioner | C18: Senior Associate | D18: Senior Associate | E18: 2–4 yrs | F18: Varied work; reviews juniors; go-to for a process | G18: None · guides 1–3 juniors informally | H18: Graduate; relevant certification preferred | I18: 2–5 | J18: P2 | K18: 3 Apply | L18: S01 Aon Radford · S02 Pave · S08 SFIA 9 · S03 Mercer career levels · S32 Google, Microsoft, Amazon · S33 Infosys · S35 Accenture India · IRIS experience guide · S09 McKinsey spans of control · S37 GitLab layers · S44 Google Tech Lead Manager | M18: 289
... A20: A1 | B20: Band A · Practitioner | C20: Intern / Trainee | D20: Intern / Trainee | E20: Intern / trainee · first year | F20: Learning the role; all work reviewed | G20: No direct reports | H20: Pursuing or completed graduation / diploma | I20: — | J20: Entry / P1 · intern | K20: 1 Follow | L20: S01 Aon Radford · S02 Pave · S08 SFIA 9 · S03 Mercer career levels · S32 Google, Microsoft, Amazon · S33 Infosys · S35 Accenture India · IRIS experience guide · S09 McKinsey spans of control · S37 GitLab layers · S44 Google Tech Lead Manager | M20: 21

Sheet 3. Role Model
A1: Role Model — every role, its levels one below the other | O1: ◂ Start
A2: Sheet 3 · Role-based: a role is a sub-family done as an individual contributor or as a manager. The ROLE row carries the role's weightage: IRIS · Market · Leader. Type L, M or H in the yellow Leader cells and everyone in the role is re-weighted on Talent Mapping at once. The LEVEL rows below say what Low, Medium and High mean at each level. Filter column A or D by role.
A3: IRIS · Job Architecture Model v2.0 · October 2026 · Internal — Confidential · HR and business leaders
A4: Section colours: each column group has its own header colour and a matching light tint | E4: Changed vs current | G4: Level up | H4: Level down · pay & title protected | J4: Newly mapped | K4: Player-Coach · B+ · C+ | M4: RED = critical input needed · says what and who | P4: YELLOW = to complete or edit | R4: GREY = pay · set later
A5: ROLE | I5: WEIGHTAGE · IRIS — what we set | P5: WEIGHTAGE · MARKET — published evidence, sheet 4 | W5: WEIGHTAGE · LEADER — your update, blank = agree with IRIS | AD5: IN USE · leader if given, else IRIS | AL5: COMPLEXITY & EXPERTISE — what L / M / H mean at this level | AO5: AUTONOMY & DECISION — what L / M / H mean at this level | AR5: ACCOUNTABILITY & IMPACT — what L / M / H mean at this level | AU5: LEADERSHIP & STRATEGY — what L / M / H mean at this level | AX5: BUSINESS IMPACT — what L / M / H mean at this level | BA5: EXPERIENCE — what L / M / H mean at this level | BD5: EDUCATION — what L / M / H mean at this level
A6: Role ID | B6: Role | C6: Job family | D6: Track | E6: Row | F6: Level | G6: Standard title at this level | H6: People | I6: IRIS · Complexity & Expertise | J6: IRIS · Autonomy & Decision | K6: IRIS · Accountability & Impact | L6: IRIS · Leadership & Strategy | M6: IRIS · Business Impact | N6: IRIS · Experience | O6: IRIS · Education | P6: Market · Complexity & Expertise | Q6: Market · Autonomy & Decision | R6: Market · Accountability & Impact | S6: Market · Leadership & Strategy | T6: Market · Business Impact | U6: Market · Experience | V6: Market · Education | W6: Leader · Complexity & Expertise | X6: Leader · Autonomy & Decision | Y6: Leader · Accountability & Impact | Z6: Leader · Leadership & Strategy | AA6: Leader · Business Impact | AB6: Leader · Experience | AC6: Leader · Education | AD6: In use · Complexity & Expertise | AE6: In use · Autonomy & Decision | AF6: In use · Accountability & Impact | AG6: In use · Leadership & Strategy | AH6: In use · Business Impact | AI6: In use · Experience | AJ6: In use · Education | AK6: Leader updates | AL6: Complexity & Expertise · Low | AM6: Complexity & Expertise · Medium | AN6: Complexity & Expertise · High | AO6: Autonomy & Decision · Low | AP6: Autonomy & Decision · Medium | AQ6: Autonomy & Decision · High | AR6: Accountability & Impact · Low | AS6: Accountability & Impact · Medium | AT6: Accountability & Impact · High | AU6: Leadership & Strategy · Low | AV6: Leadership & Strategy · Medium | AW6: Leadership & Strategy · High | AX6: Business Impact · Low | AY6: Business Impact · Medium | AZ6: Business Impact · High | BA6: Experience · Low | BB6: Experience · Medium | BC6: Experience · High | BD6: Education · Low | BE6: Education · Medium | BF6: Education · High
A7: R001 | B7: Administration & Facilities · Consultant | C7: Administration, Legal & Secretarial | D7: Consultant | E7: ROLE | F7: X1 | G7: Consultant · outside the ladder · Corporate functions | H7: 1 | AD7: =IF(W7<>"",W7,I7) -> 0 | AE7: =IF(X7<>"",X7,J7) -> 0 | AF7: =IF(Y7<>"",Y7,K7) -> 0 | AG7: =IF(Z7<>"",Z7,L7) -> 0 | AH7: =IF(AA7<>"",AA7,M7) -> 0 | AI7: =IF(AB7<>"",AB7,N7) -> 0 | AJ7: =IF(AC7<>"",AC7,O7) -> 0 | AK7: =COUNTA(W7:AC7) -> 0
A8: R002 | B8: Administration & Facilities · IC | C8: Administration, Legal & Secretarial | D8: IC | E8: ROLE | F8: A3 | G8: Band A · all tracks · Corporate functions | H8: 4 | I8: H | J8: M | K8: M | L8: L | M8: L | N8: L | O8: M | P8: H | Q8: M | R8: M | S8: L | T8: L | U8: L | V8: L | AD8: =IF(W8<>"",W8,I8) -> H | AE8: =IF(X8<>"",X8,J8) -> M | AF8: =IF(Y8<>"",Y8,K8) -> M | AG8: =IF(Z8<>"",Z8,L8) -> L | AH8: =IF(AA8<>"",AA8,M8) -> L | AI8: =IF(AB8<>"",AB8,N8) -> L | AJ8: =IF(AC8<>"",AC8,O8) -> M | AK8: =COUNTA(W8:AC8) -> 0
A9: R002 | B9: Administration & Facilities · IC | C9: Administration, Legal & Secretarial | D9: IC | E9: level | F9: A3 | G9: Senior Administration Executive | H9: 4 | AL9: Works at A2: Standard work of the discipline | AM9: Varied and non-standard work; handles exceptions · in this role: Administration | AN9: Works at B1: Domain specialist work | AO9: Works at A2: Chooses own approach within standards | AP9: Technical / QC / client calls on own work | AQ9: Works at B1: Technical / QC / client calls for the domain | AR9: Works at A2: Own deliverables · accuracy, TAT | AS9: A module / process, or work with client or regulatory consequences | AT9: Works at B1: A domain or a small team | AU9: Works at A2: contributes alone; guides others only informally | AV9: Helps peers and newer people informally · None · guides 1–3 juniors informally | AW9: Works at B1: IC: mentors and reviews · People: hands-on team lead of 3–5 | AX9: Works at A2: Own deliverables feed a team's output and turnaround | AY9: A process or client deliverable depends on this work | AZ9: Works at B1: Moves a module's, product area's or client account's results | BA9: Less than 2–4 yrs | BB9: 2–4 yrs · market 2–5 yrs | BC9: More than 2–4 yrs | BD9: Below: Graduate · or diploma with experience | BE9: Graduate; relevant certification preferred · licence-to-practise roles: CA, CS, CMA or LLB as the role needs | BF9: Above: Graduate + relevant qualification or certification preferred
A10: R003 | B10: Administration & Facilities · Manager | C10: Administration, Legal & Secretarial | D10: Manager | E10: ROLE | F10: B2 | G10: Band B · People Manager · Corporate functions | H10: 1 | I10: H | J10: M | K10: M | L10: M | M10: L | N10: L | O10: L | P10: H | Q10: M | R10: M | S10: M | T10: L | U10: L | V10: L | AD10: =IF(W10<>"",W10,I10) -> H | AE10: =IF(X10<>"",X10,J10) -> M | AF10: =IF(Y10<>"",Y10,K10) -> M | AG10: =IF(Z10<>"",Z10,L10) -> M | AH10: =IF(AA10<>"",AA10,M10) -> L | AI10: =IF(AB10<>"",AB10,N10) -> L | AJ10: =IF(AC10<>"",AC10,O10) -> L | AK10: =COUNTA(W10:AC10) -> 0
A11: R003 | B11: Administration & Facilities · Manager | C11: Administration, Legal & Secretarial | D11: Manager | E11: level | F11: B2 | G11: Manager | H11: 1 | AL11: Works at B1: Domain specialist work | AM11: Hardest problems in the domain · in this role: Administration | AN11: Works at B3: Sets standards for a practice; cross-team problems | AO11: Works at B1: Technical / QC / client calls for the domain | AP11: Allocates people and sets team priorities | AQ11: Works at B3: Commercial / strategic calls for the unit | AR11: Works at B1: A domain or a small team | AS11: One team or a client portfolio | AT11: Works at B3: Several teams or a practice | AU11: Works at B1: IC: mentors and reviews · People: hands-on team lead of 3–5 | AV11: IC: guides others in the domain · People: manages a team of 6+ | AW11: Works at B3: IC: leads a practice · People: team leads / managers report in | AX11: Works at B1: Moves a module's, product area's or client account's results | AY11: Visible effect on a team's or client portfolio's revenue, quality or compliance | AZ11: Works at B3: Shapes the results of a practice or several teams | BA11: Less than 6–8 yrs | BB11: 6–8 yrs · market 6–10 yrs | BC11: More than 6–8 yrs | BD11: Below: Graduate + relevant qualification or certification preferred | BE11: Graduate or postgraduate; professional qualification preferred · licence-to-practise roles: CA, CS, CMA or LLB as the role needs | BF11: Above: Postgraduate or professional qualification preferred
A12: R004 | B12: Company Secretarial & Legal · IC | C12: Administration, Legal & Secretarial | D12: IC | E12: ROLE | F12: A1 · A2 · A3 | G12: Band A · all tracks · Corporate functions | H12: 2 | I12: H | J12: M | K12: M | L12: L | M12: L | N12: L | O12: M | P12: H | Q12: M | R12: M | S12: L | T12: L | U12: L | V12: L | AD12: =IF(W12<>"",W12,I12) -> H | AE12: =IF(X12<>"",X12,J12) -> M | AF12: =IF(Y12<>"",Y12,K12) -> M | AG12: =IF(Z12<>"",Z12,L12) -> L | AH12: =IF(AA12<>"",AA12,M12) -> L | AI12: =IF(AB12<>"",AB12,N12) -> L | AJ12: =IF(AC12<>"",AC12,O12) -> M | AK12: =COUNTA(W12:AC12) -> 0
A13: R004 | B13: Company Secretarial & Legal · IC | C13: Administration, Legal & Secretarial | D13: IC | E13: level | F13: A3 | G13: Senior Secretarial Executive | H13: 1 | AL13: Works at A2: Standard work of the discipline | AM13: Varied and non-standard work; handles exceptions · in this role: Secretarial · Legal | AN13: Works at B1: Domain specialist work | AO13: Works at A2: Chooses own approach within standards | AP13: Technical / QC / client calls on own work | AQ13: Works at B1: Technical / QC / client calls for the domain | AR13: Works at A2: Own deliverables · accuracy, TAT | AS13: A module / process, or work with client or regulatory consequences | AT13: Works at B1: A domain or a small team | AU13: Works at A2: contributes alone; guides others only informally | AV13: Helps peers and newer people informally · None · guides 1–3 juniors informally | AW13: Works at B1: IC: mentors and reviews · People: hands-on team lead of 3–5 | AX13: Works at A2: Own deliverables feed a team's output and turnaround | AY13: A process or client deliverable depends on this work | AZ13: Works at B1: Moves a module's, product area's or client account's results | BA13: Less than 2–4 yrs | BB13: 2–4 yrs · market 2–5 yrs | BC13: More than 2–4 yrs | BD13: Below: Graduate · or diploma with experience | BE13: Graduate; relevant certification preferred · licence-to-practise roles: CA, CS, CMA or LLB as the role needs | BF13: Above: Graduate + relevant qualification or certification preferred
A14: R004 | B14: Company Secretarial & Legal · IC | C14: Administration, Legal & Secretarial | D14: IC | E14: level | F14: A2 | G14: — no one at this level today | H14: 0 | AL14: Works at A1: Learning; follows worked examples | AM14: Standard work of the discipline | AN14: Works at A3: Varied and non-standard work; handles exceptions | AO14: Works at A1: Needs approval / close guidance | AP14: Chooses own approach within standards | AQ14: Works at A3: Technical / QC / client calls on own work | AR14: Works at A1: Learning tasks | AS14: Own deliverables · accuracy, TAT | AT14: Works at A3: A module / process, or work with client or regulatory consequences | AU14: Works at A1: contributes alone; guides others only informally | AV14: Helps peers and newer people informally · No direct reports | AW14: Works at A3: Not scored in Band A | AX14: Works at A1: Learning; little direct effect on business results yet | AY14: Own deliverables feed a team's output and turnaround | AZ14: Works at A3: A process or client deliverable depends on this work | BA14: Less than 0–2 yrs | BB14: 0–2 yrs · market 0–3 yrs | BC14: More than 0–2 yrs | BD14: Below: Pursuing or completed graduation / diploma | BE14: Graduate · or diploma with experience · licence-to-practise roles: CA, CS, CMA or LLB as the role needs | BF14: Above: Graduate; relevant certification preferred
A15: R004 | B15: Company Secretarial & Legal · IC | C15: Administration, Legal & Secretarial | D15: IC | E15: level | F15: A1 | G15: Intern | H15: 1 | AL15: Not yet at the entry standard | AM15: Learning; follows worked examples · in this role: Secretarial · Legal | AN15: Works at A2: Standard work of the discipline | AO15: Not yet at the entry standard | AP15: Needs approval / close guidance | AQ15: Works at A2: Chooses own approach within standards | AR15: Not yet at the entry standard | AS15: Learning tasks | AT15: Works at A2: Own deliverables · accuracy, TAT | AU15: Not yet at the entry standard | AV15: Helps peers and newer people informally · No direct reports | AW15: Works at A2: Not scored in Band A | AX15: Not yet at the entry standard | AY15: Learning; little direct effect on business results yet | AZ15: Works at A2: Own deliverables feed a team's output and turnaround | BA15: Less than Intern / trainee · first year | BB15: Intern / trainee · first year · market — yrs | BC15: More than Intern / trainee · first year | BD15: Still studying | BE15: Pursuing or completed graduation / diploma · licence-to-practise roles: CA, CS, CMA or LLB as the role needs | BF15: Above: Graduate · or diploma with experience
A16: R005 | B16: Business Analysis · IC | C16: Business Analysis | D16: IC | E16: ROLE | F16: A1 · A2 · A3 · B1 · B2 · B3 · C1 | G16: Band A · all tracks · Technology & engineering | H16: 27 | I16: H | J16: M | K16: L | L16: L | M16: L | N16: L | O16: L | P16: H | Q16: M | R16: M | S16: L | T16: L | U16: L | V16: L | AD16: =IF(W16<>"",W16,I16) -> H | AE16: =IF(X16<>"",X16,J16) -> M | AF16: =IF(Y16<>"",Y16,K16) -> L | AG16: =IF(Z16<>"",Z16,L16) -> L | AH16: =IF(AA16<>"",AA16,M16) -> L | AI16: =IF(AB16<>"",AB16,N16) -> L | AJ16: =IF(AC16<>"",AC16,O16) -> L | AK16: =COUNTA(W16:AC16) -> 0
A17: R005 | B17: Business Analysis · IC | C17: Business Analysis | D17: IC | E17: level | F17: C1 | G17: Principal – Business Analysis | H17: 1 | AL17: Works at B3: Sets standards for a practice; cross-team problems | AM17: Ambiguous, cross-product problems | AN17: Works at C2: Function-wide or company-wide problems; creates methods and standards | AO17: Works at B3: Commercial / strategic calls for the unit | AP17: Sets direction for a sub-function or domain | AQ17: Works at C2: Sets direction for a function | AR17: Works at B3: Several teams or a practice | AS17: Sub-function results or domain quality across products | AT17: Works at C2: Function results, budget and risk | AU17: Works at B3: IC: leads a practice · People: team leads / managers report in | AV17: Leads managers or a community of practice | AW17: Works at C2: Leads a function; shapes functional strategy | AX17: Works at B3: Shapes the results of a practice or several teams | AY17: Changes results across a sub-function or across products | AZ17: Works at C2: Drives a function's or department's results and costs | BA17: Less than 10–13 yrs | BB17: 10–13 yrs · market 12–17 yrs | BC17: More than 10–13 yrs | BD17: Below: Postgraduate or professional qualification preferred | BE17: Postgraduate / professional qualification preferred | BF17: Above: Postgraduate / professional qualification preferred
A18: R005 | B18: Business Analysis · IC | C18: Business Analysis | D18: IC | E18: level | F18: B3 | G18: — no one at this level today | H18: 0 | AL18: Works at B2: Hardest problems in the domain | AM18: Sets standards for a practice; cross-team problems | AN18: Works at C1: Ambiguous, cross-product problems | AO18: Works at B2: Allocates people and sets team priorities | AP18: Commercial / strategic calls for the unit | AQ18: Works at C1: Sets direction for a sub-function or domain | AR18: Works at B2: One team or a client portfolio | AS18: Several teams or a practice | AT18: Works at C1: Sub-function results or domain quality across products | AU18: Works at B2: IC: guides others in the domain · People: manages a team of 6+ | AV18: IC: leads a practice · People: team leads / managers report in | AW18: Works at C1: Leads managers or a community of practice | AX18: Works at B2: Visible effect on a team's or client portfolio's revenue, quality or compliance | AY18: Shapes the results of a practice or several teams | AZ18: Works at C1: Changes results across a sub-function or across products | BA18: Less than 8–10 yrs | BB18: 8–10 yrs · market 8–13 yrs | BC18: More than 8–10 yrs | BD18: Below: Graduate or postgraduate; professional qualification preferred | BE18: Postgraduate or professional qualification preferred | BF18: Above: Postgraduate / professional qualification preferred
A19: R005 | B19: Business Analysis · IC | C19: Business Analysis | D19: IC | E19: level | F19: B2 | G19: — no one at this level today | H19: 0 | AL19: Works at B1: Domain specialist work | AM19: Hardest problems in the domain · in this role: Business Analysis · Documentation · Requirement analysis · Stakeholder Management · communication · XBRL · Requirement Elicitation · … | AN19: Works at B3: Sets standards for a practice; cross-team problems | AO19: Works at B1: Technical / QC / client calls for the domain | AP19: Allocates people and sets team priorities | AQ19: Works at B3: Commercial / strategic calls for the unit | AR19: Works at B1: A domain or a small team | AS19: One team or a client portfolio | AT19: Works at B3: Several teams or a practice | AU19: Works at B1: IC: mentors and reviews · People: hands-on team lead of 3–5 | AV19: IC: guides others in the domain · People: manages a team of 6+ | AW19: Works at B3: IC: leads a practice · People: team leads / managers report in | AX19: Works at B1: Moves a module's, product area's or client account's results | AY19: Visible effect on a team's or client portfolio's revenue, quality or compliance | AZ19: Works at B3: Shapes the results of a practice or several teams | BA19: Less than 6–8 yrs | BB19: 6–8 yrs · market 6–10 yrs | BC19: More than 6–8 yrs | BD19: Below: Graduate + relevant qualification or certification preferred | BE19: Graduate or postgraduate; professional qualification preferred | BF19: Above: Postgraduate or professional qualification preferred
A20: R005 | B20: Business Analysis · IC | C20: Business Analysis | D20: IC | E20: level | F20: B1 | G20: Business Analysis Specialist | H20: 5 | AL20: Works at A3: Varied and non-standard work; handles exceptions | AM20: Domain specialist work · in this role: Business Analysis | AN20: Works at B2: Hardest problems in the domain | AO20: Works at A3: Technical / QC / client calls on own work | AP20: Technical / QC / client calls for the domain | AQ20: Works at B2: Allocates people and sets team priorities | AR20: Works at A3: A module / process, or work with client or regulatory consequences | AS20: A domain or a small team · KRA themes: Common themes in manager-set KRAs: releases · satisfaction · delivery · assigned · uat · requirement | AT20: Works at B2: One team or a client portfolio | AU20: Works at A3: contributes alone; guides others only informally | AV20: IC: mentors and reviews · People: hands-on team lead of 3–5 | AW20: Works at B2: IC: guides others in the domain · People: manages a team of 6+ | AX20: Works at A3: A process or client deliverable depends on this work | AY20: Moves a module's, product area's or client account's results | AZ20: Works at B2: Visible effect on a team's or client portfolio's revenue, quality or compliance | BA20: Less than 4–6 yrs | BB20: 4–6 yrs · market 4–8 yrs | BC20: More than 4–6 yrs | BD20: Below: Graduate; relevant certification preferred | BE20: Graduate + relevant qualification or certification preferred | BF20: Above: Graduate or postgraduate; professional qualification preferred
A21: R005 | B21: Business Analysis · IC | C21: Business Analysis | D21: IC | E21: level | F21: A3 | G21: Senior Business Analyst | H21: 18 | AL21: Works at A2: Standard work of the discipline | AM21: Varied and non-standard work; handles exceptions · in this role: Business Analysis · Documentation · Stakeholder management · Requirement analysis · communication · Communication skills | AN21: Works at B1: Domain specialist work | AO21: Works at A2: Chooses own approach within standards | AP21: Technical / QC / client calls on own work | AQ21: Works at B1: Technical / QC / client calls for the domain | AR21: Works at A2: Own deliverables · accuracy, TAT | AS21: A module / process, or work with client or regulatory consequences · KRA themes: Common themes in manager-set KRAs: delivery · assigned · uat · project · requests · satisfaction | AT21: Works at B1: A domain or a small team | AU21: Works at A2: contributes alone; guides others only informally | AV21: Helps peers and newer people informally · None · guides 1–3 juniors informally | AW21: Works at B1: IC: mentors and reviews · People: hands-on team lead of 3–5 | AX21: Works at A2: Own deliverables feed a team's output and turnaround | AY21: A process or client deliverable depends on this work | AZ21: Works at B1: Moves a module's, product area's or client account's results | BA21: Less than 2–4 yrs | BB21: 2–4 yrs · market 2–5 yrs | BC21: More than 2–4 yrs | BD21: Below: Graduate · or diploma with experience | BE21: Graduate; relevant certification preferred | BF21: Above: Graduate + relevant qualification or certification preferred
A22: R005 | B22: Business Analysis · IC | C22: Business Analysis | D22: IC | E22: level | F22: A2 | G22: Business Analyst | H22: 2 | AL22: Works at A1: Learning; follows worked examples | AM22: Standard work of the discipline · in this role: Business Analysis · Documentation · Requirement analysis · Stakeholder Management · communication · XBRL · Requirement Elicitation · … | AN22: Works at A3: Varied and non-standard work; handles exceptions | AO22: Works at A1: Needs approval / close guidance | AP22: Chooses own approach within standards | AQ22: Works at A3: Technical / QC / client calls on own work | AR22: Works at A1: Learning tasks | AS22: Own deliverables · accuracy, TAT | AT22: Works at A3: A module / process, or work with client or regulatory consequences | AU22: Works at A1: contributes alone; guides others only informally | AV22: Helps peers and newer people informally · No direct reports | AW22: Works at A3: Not scored in Band A | AX22: Works at A1: Learning; little direct effect on business results yet | AY22: Own deliverables feed a team's output and turnaround | AZ22: Works at A3: A process or client deliverable depends on this work | BA22: Less than 0–2 yrs | BB22: 0–2 yrs · market 0–3 yrs | BC22: More than 0–2 yrs | BD22: Below: Pursuing or completed graduation / diploma | BE22: Graduate · or diploma with experience | BF22: Above: Graduate; relevant certification preferred
A23: R005 | B23: Business Analysis · IC | C23: Business Analysis | D23: IC | E23: level | F23: A1 | G23: Trainee Business Analyst | H23: 1 | AL23: Not yet at the entry standard | AM23: Learning; follows worked examples · in this role: Business Analysis · Documentation · Requirement analysis · Stakeholder Management · communication · XBRL · Requirement Elicitation · … | AN23: Works at A2: Standard work of the discipline | AO23: Not yet at the entry standard | AP23: Needs approval / close guidance | AQ23: Works at A2: Chooses own approach within standards | AR23: Not yet at the entry standard | AS23: Learning tasks | AT23: Works at A2: Own deliverables · accuracy, TAT | AU23: Not yet at the entry standard | AV23: Helps peers and newer people informally · No direct reports | AW23: Works at A2: Not scored in Band A | AX23: Not yet at the entry standard | AY23: Learning; little direct effect on business results yet | AZ23: Works at A2: Own deliverables feed a team's output and turnaround | BA23: Less than Intern / trainee · first year | BB23: Intern / trainee · first year · market — yrs | BC23: More than Intern / trainee · first year | BD23: Still studying | BE23: Pursuing or completed graduation / diploma | BF23: Above: Graduate · or diploma with experience
A24: R006 | B24: Business Analysis · Manager | C24: Business Analysis | D24: Manager | E24: ROLE | F24: B1 | G24: Band B · People Manager · Technology & engineering | H24: 2 | I24: H | J24: M | K24: L | L24: M | M24: L | N24: L | O24: L | P24: H | Q24: M | R24: M | S24: M | T24: L | U24: L | V24: L | AD24: =IF(W24<>"",W24,I24) -> H | AE24: =IF(X24<>"",X24,J24) -> M | AF24: =IF(Y24<>"",Y24,K24) -> L | AG24: =IF(Z24<>"",Z24,L24) -> M | AH24: =IF(AA24<>"",AA24,M24) -> L | AI24: =IF(AB24<>"",AB24,N24) -> L | AJ24: =IF(AC24<>"",AC24,O24) -> L | AK24: =COUNTA(W24:AC24) -> 0
A25: R006 | B25: Business Analysis · Manager | C25: Business Analysis | D25: Manager | E25: level | F25: B1 | G25: Team Lead | H25: 2 | AL25: Works at A3: Varied and non-standard work; handles exceptions | AM25: Domain specialist work · in this role: Business Analysis | AN25: Works at B2: Hardest problems in the domain | AO25: Works at A3: Technical / QC / client calls on own work | AP25: Technical / QC / client calls for the domain | AQ25: Works at B2: Allocates people and sets team priorities | AR25: Works at A3: A module / process, or work with client or regulatory consequences | AS25: A domain or a small team · KRA themes: Common themes in manager-set KRAs: releases · satisfaction · delivery · assigned · uat · requirement | AT25: Works at B2: One team or a client portfolio | AU25: Works at A3: contributes alone; guides others only informally | AV25: IC: mentors and reviews · People: hands-on team lead of 3–5 | AW25: Works at B2: IC: guides others in the domain · People: manages a team of 6+ | AX25: Works at A3: A process or client deliverable depends on this work | AY25: Moves a module's, product area's or client account's results | AZ25: Works at B2: Visible effect on a team's or client portfolio's revenue, quality or compliance | BA25: Less than 4–6 yrs | BB25: 4–6 yrs · market 4–8 yrs | BC25: More than 4–6 yrs | BD25: Below: Graduate; relevant certification preferred | BE25: Graduate + relevant qualification or certification preferred | BF25: Above: Graduate or postgraduate; professional qualification preferred
A26: R007 | B26: Professional Services Leadership · Manager | C26: Consulting & Professional Services | D26: Manager | E26: ROLE | F26: C1 | G26: Band C · Head / manager · Service delivery & data operations | H26: 1 | I26: H | J26: M | K26: M | L26: M | M26: L | N26: L | O26: L | P26: H | Q26: M | R26: M | S26: M | T26: L | U26: L | V26: L | AD26: =IF(W26<>"",W26,I26) -> H | AE26: =IF(X26<>"",X26,J26) -> M | AF26: =IF(Y26<>"",Y26,K26) -> M | AG26: =IF(Z26<>"",Z26,L26) -> M | AH26: =IF(AA26<>"",AA26,M26) -> L | AI26: =IF(AB26<>"",AB26,N26) -> L | AJ26: =IF(AC26<>"",AC26,O26) -> L | AK26: =COUNTA(W26:AC26) -> 0
A27: R007 | B27: Professional Services Leadership · Manager | C27: Consulting & Professional Services | D27: Manager | E27: level | F27: C1 | G27: Associate Head | H27: 1 | AL27: Works at B3: Sets standards for a practice; cross-team problems | AM27: Ambiguous, cross-product problems · in this role: XBRL Domain | AN27: Works at C2: Function-wide or company-wide problems; creates methods and standards | AO27: Works at B3: Commercial / strategic calls for the unit | AP27: Sets direction for a sub-function or domain | AQ27: Works at C2: Sets direction for a function | AR27: Works at B3: Several teams or a practice | AS27: Sub-function results or domain quality across products | AT27: Works at C2: Function results, budget and risk | AU27: Works at B3: IC: leads a practice · People: team leads / managers report in | AV27: Leads managers or a community of practice | AW27: Works at C2: Leads a function; shapes functional strategy | AX27: Works at B3: Shapes the results of a practice or several teams | AY27: Changes results across a sub-function or across products | AZ27: Works at C2: Drives a function's or department's results and costs | BA27: Less than 10–13 yrs | BB27: 10–13 yrs · market 12–17 yrs | BC27: More than 10–13 yrs | BD27: Below: Postgraduate or professional qualification preferred | BE27: Postgraduate / professional qualification preferred | BF27: Above: Postgraduate / professional qualification preferred
A28: R008 | B28: Service Delivery Operations · IC | C28: Consulting & Professional Services | D28: IC | E28: ROLE | F28: A3 | G28: Band A · all tracks · Service delivery & data operations | H28: 2 | I28: H | J28: M | K28: M | L28: L | M28: L | N28: L | O28: L | P28: H | Q28: M | R28: M | S28: L | T28: L | U28: L | V28: L | AD28: =IF(W28<>"",W28,I28) -> H | AE28: =IF(X28<>"",X28,J28) -> M | AF28: =IF(Y28<>"",Y28,K28) -> M | AG28: =IF(Z28<>"",Z28,L28) -> L | AH28: =IF(AA28<>"",AA28,M28) -> L | AI28: =IF(AB28<>"",AB28,N28) -> L | AJ28: =IF(AC28<>"",AC28,O28) -> L | AK28: =COUNTA(W28:AC28) -> 0
A29: R008 | B29: Service Delivery Operations · IC | C29: Consulting & Professional Services | D29: IC | E29: level | F29: A3 | G29: Senior Service Delivery Analyst | H29: 2 | AL29: Works at A2: Standard work of the discipline | AM29: Varied and non-standard work; handles exceptions · in this role: XBRL Domain | AN29: Works at B1: Domain specialist work | AO29: Works at A2: Chooses own approach within standards | AP29: Technical / QC / client calls on own work | AQ29: Works at B1: Technical / QC / client calls for the domain | AR29: Works at A2: Own deliverables · accuracy, TAT | AS29: A module / process, or work with client or regulatory consequences | AT29: Works at B1: A domain or a small team | AU29: Works at A2: contributes alone; guides others only informally | AV29: Helps peers and newer people informally · None · guides 1–3 juniors informally | AW29: Works at B1: IC: mentors and reviews · People: hands-on team lead of 3–5 | AX29: Works at A2: Own deliverables feed a team's output and turnaround | AY29: A process or client deliverable depends on this work | AZ29: Works at B1: Moves a module's, product area's or client account's results | BA29: Less than 2–4 yrs | BB29: 2–4 yrs · market 2–5 yrs | BC29: More than 2–4 yrs | BD29: Below: Graduate · or diploma with experience | BE29: Graduate; relevant certification preferred | BF29: Above: Graduate + relevant qualification or certification preferred
A30: R009 | B30: Service Delivery Operations · Manager | C30: Consulting & Professional Services | D30: Manager | E30: ROLE | F30: B2 | G30: Band B · People Manager · Service delivery & data operations | H30: 1 | I30: H | J30: M | K30: M | L30: M | M30: L | N30: L | O30: L | P30: H | Q30: M | R30: M | S30: M | T30: L | U30: L | V30: L | AD30: =IF(W30<>"",W30,I30) -> H | AE30: =IF(X30<>"",X30,J30) -> M | AF30: =IF(Y30<>"",Y30,K30) -> M | AG30: =IF(Z30<>"",Z30,L30) -> M | AH30: =IF(AA30<>"",AA30,M30) -> L | AI30: =IF(AB30<>"",AB30,N30) -> L | AJ30: =IF(AC30<>"",AC30,O30) -> L | AK30: =COUNTA(W30:AC30) -> 0
A31: R009 | B31: Service Delivery Operations · Manager | C31: Consulting & Professional Services | D31: Manager | E31: level | F31: B2 | G31: Senior Manager | H31: 1 | AL31: Works at B1: Domain specialist work | AM31: Hardest problems in the domain · in this role: XBRL Domain | AN31: Works at B3: Sets standards for a practice; cross-team problems | AO31: Works at B1: Technical / QC / client calls for the domain | AP31: Allocates people and sets team priorities | AQ31: Works at B3: Commercial / strategic calls for the unit | AR31: Works at B1: A domain or a small team | AS31: One team or a client portfolio | AT31: Works at B3: Several teams or a practice | AU31: Works at B1: IC: mentors and reviews · People: hands-on team lead of 3–5 | AV31: IC: guides others in the domain · People: manages a team of 6+ | AW31: Works at B3: IC: leads a practice · People: team leads / managers report in | AX31: Works at B1: Moves a module's, product area's or client account's results | AY31: Visible effect on a team's or client portfolio's revenue, quality or compliance | AZ31: Works at B3: Shapes the results of a practice or several teams | BA31: Less than 6–8 yrs | BB31: 6–8 yrs · market 6–10 yrs | BC31: More than 6–8 yrs | BD31: Below: Graduate + relevant qualification or certification preferred | BE31: Graduate or postgraduate; professional qualification preferred | BF31: Above: Postgraduate or professional qualification preferred
A32: R010 | B32: Taxonomy Design & Regulatory Consulting · Consultant | C32: Consulting & Professional Services | D32: Consultant | E32: ROLE | F32: X1 | G32: Consultant · outside the ladder · Regulatory & domain consulting | H32: 1 | AD32: =IF(W32<>"",W32,I32) -> 0 | AE32: =IF(X32<>"",X32,J32) -> 0 | AF32: =IF(Y32<>"",Y32,K32) -> 0 | AG32: =IF(Z32<>"",Z32,L32) -> 0 | AH32: =IF(AA32<>"",AA32,M32) -> 0 | AI32: =IF(AB32<>"",AB32,N32) -> 0 | AJ32: =IF(AC32<>"",AC32,O32) -> 0 | AK32: =COUNTA(W32:AC32) -> 0
A33: R011 | B33: Taxonomy Design & Regulatory Consulting · IC | C33: Consulting & Professional Services | D33: IC | E33: ROLE | F33: A2 · A3 · B1 · B2 | G33: Band A · all tracks · Regulatory & domain consulting | H33: 22 | I33: H | J33: M | K33: M | L33: L | M33: L | N33: L | O33: L | P33: H | Q33: M | R33: M | S33: L | T33: L | U33: L | V33: L | AD33: =IF(W33<>"",W33,I33) -> H | AE33: =IF(X33<>"",X33,J33) -> M | AF33: =IF(Y33<>"",Y33,K33) -> M | AG33: =IF(Z33<>"",Z33,L33) -> L | AH33: =IF(AA33<>"",AA33,M33) -> L | AI33: =IF(AB33<>"",AB33,N33) -> L | AJ33: =IF(AC33<>"",AC33,O33) -> L | AK33: =COUNTA(W33:AC33) -> 0
A34: R011 | B34: Taxonomy Design & Regulatory Consulting · IC | C34: Consulting & Professional Services | D34: IC | E34: level | F34: B2 | G34: Senior Taxonomy Specialist | H34: 3 | AL34: Works at B1: Domain specialist work | AM34: Hardest problems in the domain · in this role: XBRL Domain | AN34: Works at B3: Sets standards for a practice; cross-team problems | AO34: Works at B1: Technical / QC / client calls for the domain | AP34: Allocates people and sets team priorities | AQ34: Works at B3: Commercial / strategic calls for the unit | AR34: Works at B1: A domain or a small team | AS34: One team or a client portfolio · KRA themes: Common themes in manager-set KRAs: ifile business · analyst contribute · resolve · domain delivery · serve analyst · milestones on-time | AT34: Works at B3: Several teams or a practice | AU34: Works at B1: IC: mentors and reviews · People: hands-on team lead of 3–5 | AV34: IC: guides others in the domain · People: manages a team of 6+ | AW34: Works at B3: IC: leads a practice · People: team leads / managers report in | AX34: Works at B1: Moves a module's, product area's or client account's results | AY34: Visible effect on a team's or client portfolio's revenue, quality or compliance | AZ34: Works at B3: Shapes the results of a practice or several teams | BA34: Less than 6–8 yrs | BB34: 6–8 yrs · market 6–10 yrs | BC34: More than 6–8 yrs | BD34: Below: Graduate + relevant qualification or certification preferred | BE34: Graduate or postgraduate; professional qualification preferred | BF34: Above: Postgraduate or professional qualification preferred
A35: R011 | B35: Taxonomy Design & Regulatory Consulting · IC | C35: Consulting & Professional Services | D35: IC | E35: level | F35: B1 | G35: Taxonomy Specialist | H35: 1 | AL35: Works at A3: Varied and non-standard work; handles exceptions | AM35: Domain specialist work · in this role: XBRL Domain | AN35: Works at B2: Hardest problems in the domain | AO35: Works at A3: Technical / QC / client calls on own work | AP35: Technical / QC / client calls for the domain | AQ35: Works at B2: Allocates people and sets team priorities | AR35: Works at A3: A module / process, or work with client or regulatory consequences | AS35: A domain or a small team · KRA themes: Common themes in manager-set KRAs: resolve · business · excel webform · deliver assigned · defect · critical | AT35: Works at B2: One team or a client portfolio | AU35: Works at A3: contributes alone; guides others only informally | AV35: IC: mentors and reviews · People: hands-on team lead of 3–5 | AW35: Works at B2: IC: guides others in the domain · People: manages a team of 6+ | AX35: Works at A3: A process or client deliverable depends on this work | AY35: Moves a module's, product area's or client account's results | AZ35: Works at B2: Visible effect on a team's or client portfolio's revenue, quality or compliance | BA35: Less than 4–6 yrs | BB35: 4–6 yrs · market 4–8 yrs | BC35: More than 4–6 yrs | BD35: Below: Graduate; relevant certification preferred | BE35: Graduate + relevant qualification or certification preferred | BF35: Above: Graduate or postgraduate; professional qualification preferred
A36: R011 | B36: Taxonomy Design & Regulatory Consulting · IC | C36: Consulting & Professional Services | D36: IC | E36: level | F36: A3 | G36: Senior Taxonomy Analyst | H36: 16 | AL36: Works at A2: Standard work of the discipline | AM36: Varied and non-standard work; handles exceptions · in this role: XBRL domain | AN36: Works at B1: Domain specialist work | AO36: Works at A2: Chooses own approach within standards | AP36: Technical / QC / client calls on own work | AQ36: Works at B1: Technical / QC / client calls for the domain | AR36: Works at A2: Own deliverables · accuracy, TAT | AS36: A module / process, or work with client or regulatory consequences · KRA themes: Common themes in manager-set KRAs: resolve · defect · deliver · complete · modules · testing | AT36: Works at B1: A domain or a small team | AU36: Works at A2: contributes alone; guides others only informally | AV36: Helps peers and newer people informally · None · guides 1–3 juniors informally | AW36: Works at B1: IC: mentors and reviews · People: hands-on team lead of 3–5 | AX36: Works at A2: Own deliverables feed a team's output and turnaround | AY36: A process or client deliverable depends on this work | AZ36: Works at B1: Moves a module's, product area's or client account's results | BA36: Less than 2–4 yrs | BB36: 2–4 yrs · market 2–5 yrs | BC36: More than 2–4 yrs | BD36: Below: Graduate · or diploma with experience | BE36: Graduate; relevant certification preferred | BF36: Above: Graduate + relevant qualification or certification preferred
A37: R011 | B37: Taxonomy Design & Regulatory Consulting · IC | C37: Consulting & Professional Services | D37: IC | E37: level | F37: A2 | G37: Taxonomy Analyst | H37: 2 | AL37: Works at A1: Learning; follows worked examples | AM37: Standard work of the discipline · in this role: XBRL domain · XBRL specifications · analytical skills · Domain knowledge · XBRL · XBRl knowledge · Academic strength | AN37: Works at A3: Varied and non-standard work; handles exceptions | AO37: Works at A1: Needs approval / close guidance | AP37: Chooses own approach within standards | AQ37: Works at A3: Technical / QC / client calls on own work | AR37: Works at A1: Learning tasks | AS37: Own deliverables · accuracy, TAT · KRA themes: Common themes in manager-set KRAs: complete iris · resolve · cycle full · accuracy targets · maintained · logs document | AT37: Works at A3: A module / process, or work with client or regulatory consequences | AU37: Works at A1: contributes alone; guides others only informally | AV37: Helps peers and newer people informally · No direct reports | AW37: Works at A3: Not scored in Band A | AX37: Works at A1: Learning; little direct effect on business results yet | AY37: Own deliverables feed a team's output and turnaround | AZ37: Works at A3: A process or client deliverable depends on this work | BA37: Less than 0–2 yrs | BB37: 0–2 yrs · market 0–3 yrs | BC37: More than 0–2 yrs | BD37: Below: Pursuing or completed graduation / diploma | BE37: Graduate · or diploma with experience | BF37: Above: Graduate; relevant certification preferred
A38: R012 | B38: Taxonomy Design & Regulatory Consulting · Manager | C38: Consulting & Professional Services | D38: Manager | E38: ROLE | F38: B2 | G38: Band B · People Manager · Regulatory & domain consulting | H38: 2 | I38: H | J38: M | K38: M | L38: M | M38: L | N38: L | O38: L | P38: H | Q38: M | R38: M | S38: M | T38: L | U38: L | V38: L | AD38: =IF(W38<>"",W38,I38) -> H | AE38: =IF(X38<>"",X38,J38) -> M | AF38: =IF(Y38<>"",Y38,K38) -> M | AG38: =IF(Z38<>"",Z38,L38) -> M | AH38: =IF(AA38<>"",AA38,M38) -> L | AI38: =IF(AB38<>"",AB38,N38) -> L | AJ38: =IF(AC38<>"",AC38,O38) -> L | AK38: =COUNTA(W38:AC38) -> 0
A39: R012 | B39: Taxonomy Design & Regulatory Consulting · Manager | C39: Consulting & Professional Services | D39: Manager | E39: level | F39: B2 | G39: Senior Manager | H39: 2 | AL39: Works at B1: Domain specialist work | AM39: Hardest problems in the domain · in this role: XBRL Domain | AN39: Works at B3: Sets standards for a practice; cross-team problems | AO39: Works at B1: Technical / QC / client calls for the domain | AP39: Allocates people and sets team priorities | AQ39: Works at B3: Commercial / strategic calls for the unit | AR39: Works at B1: A domain or a small team | AS39: One team or a client portfolio · KRA themes: Common themes in manager-set KRAs: ifile business · analyst contribute · resolve · domain delivery · serve analyst · milestones on-time | AT39: Works at B3: Several teams or a practice | AU39: Works at B1: IC: mentors and reviews · People: hands-on team lead of 3–5 | AV39: IC: guides others in the domain · People: manages a team of 6+ | AW39: Works at B3: IC: leads a practice · People: team leads / managers report in | AX39: Works at B1: Moves a module's, product area's or client account's results | AY39: Visible effect on a team's or client portfolio's revenue, quality or compliance | AZ39: Works at B3: Shapes the results of a practice or several teams | BA39: Less than 6–8 yrs | BB39: 6–8 yrs · market 6–10 yrs | BC39: More than 6–8 yrs | BD39: Below: Graduate + relevant qualification or certification preferred | BE39: Graduate or postgraduate; professional qualification preferred | BF39: Above: Postgraduate or professional qualification preferred
A40: R013 | B40: XBRL Tagging, Conversion & Filing · IC | C40: Consulting & Professional Services | D40: IC | E40: ROLE | F40: A2 · A3 · B1 | G40: Band A · all tracks · Service delivery & data operations | H40: 52 | I40: H | J40: M | K40: M | L40: L | M40: L | N40: L | O40: L | P40: H | Q40: M | R40: M | S40: L | T40: L | U40: L | V40: L | AD40: =IF(W40<>"",W40,I40) -> H | AE40: =IF(X40<>"",X40,J40) -> M | AF40: =IF(Y40<>"",Y40,K40) -> M | AG40: =IF(Z40<>"",Z40,L40) -> L | AH40: =IF(AA40<>"",AA40,M40) -> L | AI40: =IF(AB40<>"",AB40,N40) -> L | AJ40: =IF(AC40<>"",AC40,O40) -> L | AK40: =COUNTA(W40:AC40) -> 0
...

Sheet 4. Market Benchmark
A1: Market Benchmark — Low / Medium / High, with the evidence behind each | M1: ◂ Start
A2: Sheet 4 · How much each parameter counts in published job-evaluation methods, by role group, turned into Low / Medium / High. Rule: a share of 30% or more of the points is High; 9% to under 30% is Medium; under 9% is Low. Each row shows the published numbers it rests on. Experience and Education: every method folds them into knowledge, so the market weights them Low on their own.
A3: IRIS · Job Architecture Model v2.0 · October 2026 · Internal — Confidential · HR and business leaders
A5: 1 · Weightage by role group and parameter
A6: Role group | B6: Parameter | C6: Market · L/M/H | D6: Korn Ferry Hay | E6: Mercer IPE | F6: Public plans · average of 5 | G6: Market average | H6: Why this rating | I6: References
A7: Band A · all tracks | B7: Complexity & Expertise | C7: H | D7: 81% | E7: 62% | F7: 63% | G7: 69% | H7: Average 69% of the points · at or above 30% → High · Complexity here includes knowledge and experience, as the methods publish it | I7: S46–S51 Korn Ferry Hay evaluations · S04, S52 Mercer IPE · S53–S57 NHS, UK NJC/PSC, GLPC, SJC, US OPM point-factor plans
A8: Band A · all tracks | B8: Autonomy & Decision | C8: M | D8: 11% | E8: 22% | F8: 15% | G8: 16% | H8: Average 16% of the points · below 30% and at or above 9% → Medium | I8: S46–S51 Korn Ferry Hay evaluations · S04, S52 Mercer IPE · S53–S57 NHS, UK NJC/PSC, GLPC, SJC, US OPM point-factor plans
A9: Band A · all tracks | B9: Accountability & Impact | C9: M | D9: 4% | E9: 8% | F9: 15% | G9: 9% | H9: Average 9% of the points · below 30% and at or above 9% → Medium | I9: S46–S51 Korn Ferry Hay evaluations · S04, S52 Mercer IPE · S53–S57 NHS, UK NJC/PSC, GLPC, SJC, US OPM point-factor plans
A10: Band A · all tracks | B10: Leadership & Strategy | C10: L | D10: 0% | E10: 0% | F10: 0% | G10: 0% | H10: Average 0% of the points · below 30% and below 9% → Low | I10: S46–S51 Korn Ferry Hay evaluations · S04, S52 Mercer IPE · S53–S57 NHS, UK NJC/PSC, GLPC, SJC, US OPM point-factor plans
A11: Band A · all tracks | B11: Business Impact | C11: L | D11: 4% | E11: 8% | F11: 7% | G11: 6% | H11: Average 6% of the points · below 30% and below 9% → Low | I11: S46–S51 Korn Ferry Hay evaluations · S04, S52 Mercer IPE · S53–S57 NHS, UK NJC/PSC, GLPC, SJC, US OPM point-factor plans
A12: Band A · all tracks | B12: Experience | C12: L | D12: in know-how | E12: in knowledge | F12: in knowledge / KTE | G12: not separate | H12: No published method weights it on its own: Hay know-how includes all knowledge and experience however acquired; Mercer IPE knowledge; NHS knowledge, training and experience. Skills-first evidence argues for a low weight. | I12: S05, S49 Hay · S04, S52 Mercer IPE · S53 NHS · S58 McKinsey · S59 Deloitte · S60 WEF · S61 EY India
A13: Band A · all tracks | B13: Education | C13: L | D13: in know-how | E13: in knowledge | F13: in knowledge / KTE | G13: not separate | H13: No published method weights it on its own: Hay know-how includes all knowledge and experience however acquired; Mercer IPE knowledge; NHS knowledge, training and experience. Skills-first evidence argues for a low weight. | I13: S05, S49 Hay · S04, S52 Mercer IPE · S53 NHS · S58 McKinsey · S59 Deloitte · S60 WEF · S61 EY India
A14: Band B · Specialist / POD Lead | B14: Complexity & Expertise | C14: H | D14: 64% | E14: 61% | F14: 58% | G14: 61% | H14: Average 61% of the points · at or above 30% → High · Complexity here includes knowledge and experience, as the methods publish it | I14: S46–S51 Korn Ferry Hay evaluations · S04, S52 Mercer IPE · S53–S57 NHS, UK NJC/PSC, GLPC, SJC, US OPM point-factor plans
A15: Band B · Specialist / POD Lead | B15: Autonomy & Decision | C15: M | D15: 19% | E15: 18% | F15: 15% | G15: 17% | H15: Average 17% of the points · below 30% and at or above 9% → Medium | I15: S46–S51 Korn Ferry Hay evaluations · S04, S52 Mercer IPE · S53–S57 NHS, UK NJC/PSC, GLPC, SJC, US OPM point-factor plans
A16: Band B · Specialist / POD Lead | B16: Accountability & Impact | C16: M | D16: 6% | E16: 8% | F16: 15% | G16: 10% | H16: Average 10% of the points · below 30% and at or above 9% → Medium | I16: S46–S51 Korn Ferry Hay evaluations · S04, S52 Mercer IPE · S53–S57 NHS, UK NJC/PSC, GLPC, SJC, US OPM point-factor plans
A17: Band B · Specialist / POD Lead | B17: Leadership & Strategy | C17: L | D17: 5% | E17: 5% | F17: 5% | G17: 5% | H17: Average 5% of the points · below 30% and below 9% → Low | I17: S46–S51 Korn Ferry Hay evaluations · S04, S52 Mercer IPE · S53–S57 NHS, UK NJC/PSC, GLPC, SJC, US OPM point-factor plans
... A62: Bands D–E · Leadership | B62: Education | C62: L | D62: in know-how | E62: in knowledge | F62: in knowledge / KTE | G62: not separate | H62: No published method weights it on its own: Hay know-how includes all knowledge and experience however acquired; Mercer IPE knowledge; NHS knowledge, training and experience. Skills-first evidence argues for a low weight. | I62: S05, S49 Hay · S04, S52 Mercer IPE · S53 NHS · S58 McKinsey · S59 Deloitte · S60 WEF · S61 EY India
